Workbook
Name Slicer_DATE: #N/A
Name Slicer_DATE1: #N/A
Name Slicer_DATE2: #N/A
Name Slicer_DATE3: #N/A
Name Slicer_MONTH: #N/A
Name Slicer_MONTH1: #N/A
Name Slicer_MONTH2: #N/A
Name Slicer_MONTH3: #N/A

Sheet EGA
A1: HOST LIVE | M1: EGA
A2: DATE | B2: DAY | C2: WEEK | D2: MONTH | E2: KODE KET | F2: KETERANGAN | G2: NAMA KARYAWAN | H2: SESI 1 | I2: SESI 2 | J2: SESI 3 | K2: VT
A3: 46025 | B3: =TEXT(A3,"DDD") -> Sat | C3: =WEEKNUM(A3) -> 1 | D3: =TEXT(A3,"mmmm") -> January | E3: j1 | F3: =IF(E3="J1",$O$3,IF(E3="J2",$O$4,IF(E3="J3",$O$5,IF(E3="J4",$O$6,IF(E3="J5",$O$7," "))))) -> Total hari kerja | G3: EGA SILVIA YUNIAR | H3: 12 | N3: J1 | O3: Total hari kerja
A4: 46026 | B4: =TEXT(A4,"DDD") -> Sun | C4: =WEEKNUM(A4) -> 2 | D4: =TEXT(A4,"mmmm") -> January | F4: =IF(E4="J1",$O$3,IF(E4="J2",$O$4,IF(E4="J3",$O$5,IF(E4="J4",$O$6,IF(E4="J5",$O$7," "))))) | G4: EGA SILVIA YUNIAR | N4: J2 | O4: Ijin/Sakit/Alfa
A5: 46027 | B5: =TEXT(A5,"DDD") -> Mon | C5: =WEEKNUM(A5) -> 2 | D5: =TEXT(A5,"mmmm") -> January | E5: j1 | F5: =IF(E5="J1",$O$3,IF(E5="J2",$O$4,IF(E5="J3",$O$5,IF(E5="J4",$O$6,IF(E5="J5",$O$7," "))))) -> Total hari kerja | G5: EGA SILVIA YUNIAR | H5: 8 | I5: 4 | N5: J3 | O5: MERAH
A6: 46028 | B6: =TEXT(A6,"DDD") -> Tue | C6: =WEEKNUM(A6) -> 2 | D6: =TEXT(A6,"mmmm") -> January | E6: j1 | F6: =IF(E6="J1",$O$3,IF(E6="J2",$O$4,IF(E6="J3",$O$5,IF(E6="J4",$O$6,IF(E6="J5",$O$7," "))))) -> Total hari kerja | G6: EGA SILVIA YUNIAR | H6: 1 | N6: J4 | O6: LEMBUR
A7: 46029 | B7: =TEXT(A7,"DDD") -> Wed | C7: =WEEKNUM(A7) -> 2 | D7: =TEXT(A7,"mmmm") -> January | E7: j1 | F7: =IF(E7="J1",$O$3,IF(E7="J2",$O$4,IF(E7="J3",$O$5,IF(E7="J4",$O$6,IF(E7="J5",$O$7," "))))) -> Total hari kerja | G7: EGA SILVIA YUNIAR | H7: 3 | I7: 4 | N7: J5 | O7: 1/2 HARI
A8: 46030 | B8: =TEXT(A8,"DDD") -> Thu | C8: =WEEKNUM(A8) -> 2 | D8: =TEXT(A8,"mmmm") -> January | E8: j1 | F8: =IF(E8="J1",$O$3,IF(E8="J2",$O$4,IF(E8="J3",$O$5,IF(E8="J4",$O$6,IF(E8="J5",$O$7," "))))) -> Total hari kerja | G8: EGA SILVIA YUNIAR | H8: 2 | I8: 1
A9: 46031 | B9: =TEXT(A9,"DDD") -> Fri | C9: =WEEKNUM(A9) -> 2 | D9: =TEXT(A9,"mmmm") -> January | E9: j1 | F9: =IF(E9="J1",$O$3,IF(E9="J2",$O$4,IF(E9="J3",$O$5,IF(E9="J4",$O$6,IF(E9="J5",$O$7," "))))) -> Total hari kerja | G9: EGA SILVIA YUNIAR | H9: 2
A10: 46032 | B10: =TEXT(A10,"DDD") -> Sat | C10: =WEEKNUM(A10) -> 2 | D10: =TEXT(A10,"mmmm") -> January | E10: j1 | F10: =IF(E10="J1",$O$3,IF(E10="J2",$O$4,IF(E10="J3",$O$5,IF(E10="J4",$O$6,IF(E10="J5",$O$7," "))))) -> Total hari kerja | G10: EGA SILVIA YUNIAR | H10: 7
A11: 46033 | B11: =TEXT(A11,"DDD") -> Sun | C11: =WEEKNUM(A11) -> 3 | D11: =TEXT(A11,"mmmm") -> January | F11: =IF(E11="J1",$O$3,IF(E11="J2",$O$4,IF(E11="J3",$O$5,IF(E11="J4",$O$6,IF(E11="J5",$O$7," "))))) | G11: EGA SILVIA YUNIAR
A12: 46034 | B12: =TEXT(A12,"DDD") -> Mon | C12: =WEEKNUM(A12) -> 3 | D12: =TEXT(A12,"mmmm") -> January | E12: j1 | F12: =IF(E12="J1",$O$3,IF(E12="J2",$O$4,IF(E12="J3",$O$5,IF(E12="J4",$O$6,IF(E12="J5",$O$7," "))))) -> Total hari kerja | G12: EGA SILVIA YUNIAR | H12: 2 | I12: 3
A13: 46035 | B13: =TEXT(A13,"DDD") -> Tue | C13: =WEEKNUM(A13) -> 3 | D13: =TEXT(A13,"mmmm") -> January | E13: j1 | F13: =IF(E13="J1",$O$3,IF(E13="J2",$O$4,IF(E13="J3",$O$5,IF(E13="J4",$O$6,IF(E13="J5",$O$7," "))))) -> Total hari kerja | G13: EGA SILVIA YUNIAR | H13: 1 | I13: 2
A14: 46036 | B14: =TEXT(A14,"DDD") -> Wed | C14: =WEEKNUM(A14) -> 3 | D14: =TEXT(A14,"mmmm") -> January | E14: j2 | F14: =IF(E14="J1",$O$3,IF(E14="J2",$O$4,IF(E14="J3",$O$5,IF(E14="J4",$O$6,IF(E14="J5",$O$7," "))))) -> Ijin/Sakit/Alfa | G14: EGA SILVIA YUNIAR
A15: 46037 | B15: =TEXT(A15,"DDD") -> Thu | C15: =WEEKNUM(A15) -> 3 | D15: =TEXT(A15,"mmmm") -> January | E15: j1 | F15: =IF(E15="J1",$O$3,IF(E15="J2",$O$4,IF(E15="J3",$O$5,IF(E15="J4",$O$6,IF(E15="J5",$O$7," "))))) -> Total hari kerja | G15: EGA SILVIA YUNIAR | H15: 6
A16: 46038 | B16: =TEXT(A16,"DDD") -> Fri | C16: =WEEKNUM(A16) -> 3 | D16: =TEXT(A16,"mmmm") -> January | E16: j3 | F16: =IF(E16="J1",$O$3,IF(E16="J2",$O$4,IF(E16="J3",$O$5,IF(E16="J4",$O$6,IF(E16="J5",$O$7," "))))) -> MERAH | G16: EGA SILVIA YUNIAR
A17: 46039 | B17: =TEXT(A17,"DDD") -> Sat | C17: =WEEKNUM(A17) -> 3 | D17: =TEXT(A17,"mmmm") -> January | E17: j1 | F17: =IF(E17="J1",$O$3,IF(E17="J2",$O$4,IF(E17="J3",$O$5,IF(E17="J4",$O$6,IF(E17="J5",$O$7," "))))) -> Total hari kerja | G17: EGA SILVIA YUNIAR | H17: 3
A18: 46040 | B18: =TEXT(A18,"DDD") -> Sun | C18: =WEEKNUM(A18) -> 4 | D18: =TEXT(A18,"mmmm") -> January | F18: =IF(E18="J1",$O$3,IF(E18="J2",$O$4,IF(E18="J3",$O$5,IF(E18="J4",$O$6,IF(E18="J5",$O$7," "))))) | G18: EGA SILVIA YUNIAR
A19: 46041 | B19: =TEXT(A19,"DDD") -> Mon | C19: =WEEKNUM(A19) -> 4 | D19: =TEXT(A19,"mmmm") -> January | E19: j1 | F19: =IF(E19="J1",$O$3,IF(E19="J2",$O$4,IF(E19="J3",$O$5,IF(E19="J4",$O$6,IF(E19="J5",$O$7," "))))) -> Total hari kerja | G19: EGA SILVIA YUNIAR | H19: 6
A20: 46042 | B20: =TEXT(A20,"DDD") -> Tue | C20: =WEEKNUM(A20) -> 4 | D20: =TEXT(A20,"mmmm") -> January | E20: j5 | F20: =IF(E20="J1",$O$3,IF(E20="J2",$O$4,IF(E20="J3",$O$5,IF(E20="J4",$O$6,IF(E20="J5",$O$7," "))))) -> 1/2 HARI | G20: EGA SILVIA YUNIAR | H20: 0
A21: 46043 | B21: =TEXT(A21,"DDD") -> Wed | C21: =WEEKNUM(A21) -> 4 | D21: =TEXT(A21,"mmmm") -> January | E21: J1 | F21: =IF(E21="J1",$O$3,IF(E21="J2",$O$4,IF(E21="J3",$O$5,IF(E21="J4",$O$6,IF(E21="J5",$O$7," "))))) -> Total hari kerja | G21: EGA SILVIA YUNIAR | H21: 7 | I21: 2 | J21: 2
A22: 46044 | B22: =TEXT(A22,"DDD") -> Thu | C22: =WEEKNUM(A22) -> 4 | D22: =TEXT(A22,"mmmm") -> January | E22: J1 | F22: =IF(E22="J1",$O$3,IF(E22="J2",$O$4,IF(E22="J3",$O$5,IF(E22="J4",$O$6,IF(E22="J5",$O$7," "))))) -> Total hari kerja | G22: EGA SILVIA YUNIAR | H22: 12 | I22: 1
A23: 46045 | B23: =TEXT(A23,"DDD") -> Fri | C23: =WEEKNUM(A23) -> 4 | D23: =TEXT(A23,"mmmm") -> January | E23: J1 | F23: =IF(E23="J1",$O$3,IF(E23="J2",$O$4,IF(E23="J3",$O$5,IF(E23="J4",$O$6,IF(E23="J5",$O$7," "))))) -> Total hari kerja | G23: EGA SILVIA YUNIAR | H23: 5 | I23: 8 | J23: 1
A24: 46046 | B24: =TEXT(A24,"DDD") -> Sat | C24: =WEEKNUM(A24) -> 4 | D24: =TEXT(A24,"mmmm") -> January | E24: J1 | F24: =IF(E24="J1",$O$3,IF(E24="J2",$O$4,IF(E24="J3",$O$5,IF(E24="J4",$O$6,IF(E24="J5",$O$7," "))))) -> Total hari kerja | G24: EGA SILVIA YUNIAR | H24: 8 | I24: 1
A25: 46047 | B25: =TEXT(A25,"DDD") -> Sun | C25: =WEEKNUM(A25) -> 5 | D25: =TEXT(A25,"mmmm") -> January | F25: =IF(E25="J1",$O$3,IF(E25="J2",$O$4,IF(E25="J3",$O$5,IF(E25="J4",$O$6,IF(E25="J5",$O$7," "))))) | G25: EGA SILVIA YUNIAR
A26: 46048 | B26: =TEXT(A26,"DDD") -> Mon | C26: =WEEKNUM(A26) -> 5 | D26: =TEXT(A26,"mmmm") -> January | E26: J1 | F26: =IF(E26="J1",$O$3,IF(E26="J2",$O$4,IF(E26="J3",$O$5,IF(E26="J4",$O$6,IF(E26="J5",$O$7," "))))) -> Total hari kerja | G26: EGA SILVIA YUNIAR | H26: 5 | I26: 2 | J26: 2
A27: 46049 | B27: =TEXT(A27,"DDD") -> Tue | C27: =WEEKNUM(A27) -> 5 | D27: =TEXT(A27,"mmmm") -> January | E27: J1 | F27: =IF(E27="J1",$O$3,IF(E27="J2",$O$4,IF(E27="J3",$O$5,IF(E27="J4",$O$6,IF(E27="J5",$O$7," "))))) -> Total hari kerja | G27: EGA SILVIA YUNIAR | H27: 1 | I27: 10 | J27: 1
A28: 46050 | B28: =TEXT(A28,"DDD") -> Wed | C28: =WEEKNUM(A28) -> 5 | D28: =TEXT(A28,"mmmm") -> January | E28: J1 | F28: =IF(E28="J1",$O$3,IF(E28="J2",$O$4,IF(E28="J3",$O$5,IF(E28="J4",$O$6,IF(E28="J5",$O$7," "))))) -> Total hari kerja | G28: EGA SILVIA YUNIAR | H28: 3 | I28: 2
A29: 46051 | B29: =TEXT(A29,"DDD") -> Thu | C29: =WEEKNUM(A29) -> 5 | D29: =TEXT(A29,"mmmm") -> January | E29: J1 | F29: =IF(E29="J1",$O$3,IF(E29="J2",$O$4,IF(E29="J3",$O$5,IF(E29="J4",$O$6,IF(E29="J5",$O$7," "))))) -> Total hari kerja | G29: EGA SILVIA YUNIAR | H29: 3 | I29: 1
A30: 46052 | B30: =TEXT(A30,"DDD") -> Fri | C30: =WEEKNUM(A30) -> 5 | D30: =TEXT(A30,"mmmm") -> January | E30: J1 | F30: =IF(E30="J1",$O$3,IF(E30="J2",$O$4,IF(E30="J3",$O$5,IF(E30="J4",$O$6,IF(E30="J5",$O$7," "))))) -> Total hari kerja | G30: EGA SILVIA YUNIAR | H30: 1 | I30: 4
A31: 46053 | B31: =TEXT(A31,"DDD") -> Sat | C31: =WEEKNUM(A31) -> 5 | D31: =TEXT(A31,"mmmm") -> January | E31: J1 | F31: =IF(E31="J1",$O$3,IF(E31="J2",$O$4,IF(E31="J3",$O$5,IF(E31="J4",$O$6,IF(E31="J5",$O$7," "))))) -> Total hari kerja | G31: EGA SILVIA YUNIAR
A32: 46054 | B32: =TEXT(A32,"DDD") -> Sun | C32: =WEEKNUM(A32) -> 6 | D32: =TEXT(A32,"mmmm") -> February | F32: =IF(E32="J1",$O$3,IF(E32="J2",$O$4,IF(E32="J3",$O$5,IF(E32="J4",$O$6,IF(E32="J5",$O$7," "))))) | G32: EGA SILVIA YUNIAR
A33: 46055 | B33: =TEXT(A33,"DDD") -> Mon | C33: =WEEKNUM(A33) -> 6 | D33: =TEXT(A33,"mmmm") -> February | E33: J1 | F33: =IF(E33="J1",$O$3,IF(E33="J2",$O$4,IF(E33="J3",$O$5,IF(E33="J4",$O$6,IF(E33="J5",$O$7," "))))) -> Total hari kerja | G33: EGA SILVIA YUNIAR | H33: 4 | I33: 1
A34: 46056 | B34: =TEXT(A34,"DDD") -> Tue | C34: =WEEKNUM(A34) -> 6 | D34: =TEXT(A34,"mmmm") -> February | E34: j2 | F34: =IF(E34="J1",$O$3,IF(E34="J2",$O$4,IF(E34="J3",$O$5,IF(E34="J4",$O$6,IF(E34="J5",$O$7," "))))) -> Ijin/Sakit/Alfa | G34: EGA SILVIA YUNIAR
A35: 46057 | B35: =TEXT(A35,"DDD") -> Wed | C35: =WEEKNUM(A35) -> 6 | D35: =TEXT(A35,"mmmm") -> February | E35: j2 | F35: =IF(E35="J1",$O$3,IF(E35="J2",$O$4,IF(E35="J3",$O$5,IF(E35="J4",$O$6,IF(E35="J5",$O$7," "))))) -> Ijin/Sakit/Alfa | G35: EGA SILVIA YUNIAR
A36: 46058 | B36: =TEXT(A36,"DDD") -> Thu | C36: =WEEKNUM(A36) -> 6 | D36: =TEXT(A36,"mmmm") -> February | E36: J1 | F36: =IF(E36="J1",$O$3,IF(E36="J2",$O$4,IF(E36="J3",$O$5,IF(E36="J4",$O$6,IF(E36="J5",$O$7," "))))) -> Total hari kerja | G36: EGA SILVIA YUNIAR | H36: 12 | I36: 3
A37: 46059 | B37: =TEXT(A37,"DDD") -> Fri | C37: =WEEKNUM(A37) -> 6 | D37: =TEXT(A37,"mmmm") -> February | E37: J1 | F37: =IF(E37="J1",$O$3,IF(E37="J2",$O$4,IF(E37="J3",$O$5,IF(E37="J4",$O$6,IF(E37="J5",$O$7," "))))) -> Total hari kerja | G37: EGA SILVIA YUNIAR | H37: 1 | I37: 3
A38: 46060 | B38: =TEXT(A38,"DDD") -> Sat | C38: =WEEKNUM(A38) -> 6 | D38: =TEXT(A38,"mmmm") -> February | E38: j2 | F38: =IF(E38="J1",$O$3,IF(E38="J2",$O$4,IF(E38="J3",$O$5,IF(E38="J4",$O$6,IF(E38="J5",$O$7," "))))) -> Ijin/Sakit/Alfa | G38: EGA SILVIA YUNIAR
A39: 46061 | B39: =TEXT(A39,"DDD") -> Sun | C39: =WEEKNUM(A39) -> 7 | D39: =TEXT(A39,"mmmm") -> February | F39: =IF(E39="J1",$O$3,IF(E39="J2",$O$4,IF(E39="J3",$O$5,IF(E39="J4",$O$6,IF(E39="J5",$O$7," "))))) | G39: EGA SILVIA YUNIAR
A40: 46062 | B40: =TEXT(A40,"DDD") -> Mon | C40: =WEEKNUM(A40) -> 7 | D40: =TEXT(A40,"mmmm") -> February | E40: j2 | F40: =IF(E40="J1",$O$3,IF(E40="J2",$O$4,IF(E40="J3",$O$5,IF(E40="J4",$O$6,IF(E40="J5",$O$7," "))))) -> Ijin/Sakit/Alfa | G40: EGA SILVIA YUNIAR
...

Sheet GEFIRA
A1: HOST LIVE | M1: GEFIRA
A2: DATE | B2: DAY | C2: WEEK | D2: MONTH | E2: KODE KET | F2: KETERANGAN | G2: NAMA KARYAWAN | H2: SESI 1 | I2: SESI 2 | J2: SESI 3 | K2: VT
A3: 46025 | B3: =TEXT(A3,"DDD") -> Sat | C3: =WEEKNUM(A3) -> 1 | D3: =TEXT(A3,"mmmm") -> January | E3: j1 | F3: =IF(E3="J1",$O$3,IF(E3="J2",$O$4,IF(E3="J3",$O$5,IF(E3="J4",$O$6,IF(E3="J5",$O$7," "))))) -> Total hari kerja | G3: REINA DWI MAHARANI | H3: 1 | N3: J1 | O3: Total hari kerja
A4: 46026 | B4: =TEXT(A4,"DDD") -> Sun | C4: =WEEKNUM(A4) -> 2 | D4: =TEXT(A4,"mmmm") -> January | F4: =IF(E4="J1",$O$3,IF(E4="J2",$O$4,IF(E4="J3",$O$5,IF(E4="J4",$O$6,IF(E4="J5",$O$7," "))))) | G4: REINA DWI MAHARANI | N4: J2 | O4: Ijin/Sakit/Alfa
A5: 46027 | B5: =TEXT(A5,"DDD") -> Mon | C5: =WEEKNUM(A5) -> 2 | D5: =TEXT(A5,"mmmm") -> January | E5: j1 | F5: =IF(E5="J1",$O$3,IF(E5="J2",$O$4,IF(E5="J3",$O$5,IF(E5="J4",$O$6,IF(E5="J5",$O$7," "))))) -> Total hari kerja | G5: REINA DWI MAHARANI | H5: 4 | I5: 4 | N5: J3 | O5: MERAH
A6: 46028 | B6: =TEXT(A6,"DDD") -> Tue | C6: =WEEKNUM(A6) -> 2 | D6: =TEXT(A6,"mmmm") -> January | E6: j1 | F6: =IF(E6="J1",$O$3,IF(E6="J2",$O$4,IF(E6="J3",$O$5,IF(E6="J4",$O$6,IF(E6="J5",$O$7," "))))) -> Total hari kerja | G6: REINA DWI MAHARANI | H6: 2 | I6: 4 | N6: J4 | O6: LEMBUR
A7: 46029 | B7: =TEXT(A7,"DDD") -> Wed | C7: =WEEKNUM(A7) -> 2 | D7: =TEXT(A7,"mmmm") -> January | E7: j1 | F7: =IF(E7="J1",$O$3,IF(E7="J2",$O$4,IF(E7="J3",$O$5,IF(E7="J4",$O$6,IF(E7="J5",$O$7," "))))) -> Total hari kerja | G7: REINA DWI MAHARANI | H7: 4 | I7: 2 | N7: J5 | O7: 1/2 HARI
A8: 46030 | B8: =TEXT(A8,"DDD") -> Thu | C8: =WEEKNUM(A8) -> 2 | D8: =TEXT(A8,"mmmm") -> January | E8: j1 | F8: =IF(E8="J1",$O$3,IF(E8="J2",$O$4,IF(E8="J3",$O$5,IF(E8="J4",$O$6,IF(E8="J5",$O$7," "))))) -> Total hari kerja | G8: REINA DWI MAHARANI | H8: 3 | I8: 1
A9: 46031 | B9: =TEXT(A9,"DDD") -> Fri | C9: =WEEKNUM(A9) -> 2 | D9: =TEXT(A9,"mmmm") -> January | E9: j2 | F9: =IF(E9="J1",$O$3,IF(E9="J2",$O$4,IF(E9="J3",$O$5,IF(E9="J4",$O$6,IF(E9="J5",$O$7," "))))) -> Ijin/Sakit/Alfa | G9: REINA DWI MAHARANI
A10: 46032 | B10: =TEXT(A10,"DDD") -> Sat | C10: =WEEKNUM(A10) -> 2 | D10: =TEXT(A10,"mmmm") -> January | E10: j1 | F10: =IF(E10="J1",$O$3,IF(E10="J2",$O$4,IF(E10="J3",$O$5,IF(E10="J4",$O$6,IF(E10="J5",$O$7," "))))) -> Total hari kerja | G10: REINA DWI MAHARANI | H10: 1
A11: 46033 | B11: =TEXT(A11,"DDD") -> Sun | C11: =WEEKNUM(A11) -> 3 | D11: =TEXT(A11,"mmmm") -> January | F11: =IF(E11="J1",$O$3,IF(E11="J2",$O$4,IF(E11="J3",$O$5,IF(E11="J4",$O$6,IF(E11="J5",$O$7," "))))) | G11: REINA DWI MAHARANI
A12: 46034 | B12: =TEXT(A12,"DDD") -> Mon | C12: =WEEKNUM(A12) -> 3 | D12: =TEXT(A12,"mmmm") -> January | E12: j1 | F12: =IF(E12="J1",$O$3,IF(E12="J2",$O$4,IF(E12="J3",$O$5,IF(E12="J4",$O$6,IF(E12="J5",$O$7," "))))) -> Total hari kerja | G12: REINA DWI MAHARANI | H12: 3
A13: 46035 | B13: =TEXT(A13,"DDD") -> Tue | C13: =WEEKNUM(A13) -> 3 | D13: =TEXT(A13,"mmmm") -> January | E13: j1 | F13: =IF(E13="J1",$O$3,IF(E13="J2",$O$4,IF(E13="J3",$O$5,IF(E13="J4",$O$6,IF(E13="J5",$O$7," "))))) -> Total hari kerja | G13: REINA DWI MAHARANI | H13: 1
A14: 46036 | B14: =TEXT(A14,"DDD") -> Wed | C14: =WEEKNUM(A14) -> 3 | D14: =TEXT(A14,"mmmm") -> January | E14: j1 | F14: =IF(E14="J1",$O$3,IF(E14="J2",$O$4,IF(E14="J3",$O$5,IF(E14="J4",$O$6,IF(E14="J5",$O$7," "))))) -> Total hari kerja | G14: REINA DWI MAHARANI | H14: 4 | I14: 1
A15: 46037 | B15: =TEXT(A15,"DDD") -> Thu | C15: =WEEKNUM(A15) -> 3 | D15: =TEXT(A15,"mmmm") -> January | E15: j1 | F15: =IF(E15="J1",$O$3,IF(E15="J2",$O$4,IF(E15="J3",$O$5,IF(E15="J4",$O$6,IF(E15="J5",$O$7," "))))) -> Total hari kerja | G15: REINA DWI MAHARANI | H15: 5 | I15: 1
A16: 46038 | B16: =TEXT(A16,"DDD") -> Fri | C16: =WEEKNUM(A16) -> 3 | D16: =TEXT(A16,"mmmm") -> January | E16: j1 | F16: =IF(E16="J1",$O$3,IF(E16="J2",$O$4,IF(E16="J3",$O$5,IF(E16="J4",$O$6,IF(E16="J5",$O$7," "))))) -> Total hari kerja | G16: REINA DWI MAHARANI | H16: 8
A17: 46039 | B17: =TEXT(A17,"DDD") -> Sat | C17: =WEEKNUM(A17) -> 3 | D17: =TEXT(A17,"mmmm") -> January | E17: j2 | F17: =IF(E17="J1",$O$3,IF(E17="J2",$O$4,IF(E17="J3",$O$5,IF(E17="J4",$O$6,IF(E17="J5",$O$7," "))))) -> Ijin/Sakit/Alfa | G17: REINA DWI MAHARANI | L17: GAJIHAN
A18: 46040 | B18: =TEXT(A18,"DDD") -> Sun | C18: =WEEKNUM(A18) -> 4 | D18: =TEXT(A18,"mmmm") -> January | F18: =IF(E18="J1",$O$3,IF(E18="J2",$O$4,IF(E18="J3",$O$5,IF(E18="J4",$O$6,IF(E18="J5",$O$7," "))))) | G18: REINA DWI MAHARANI
A19: 46041 | B19: =TEXT(A19,"DDD") -> Mon | C19: =WEEKNUM(A19) -> 4 | D19: =TEXT(A19,"mmmm") -> January | E19: j1 | F19: =IF(E19="J1",$O$3,IF(E19="J2",$O$4,IF(E19="J3",$O$5,IF(E19="J4",$O$6,IF(E19="J5",$O$7," "))))) -> Total hari kerja | G19: REINA DWI MAHARANI | H19: 3
A20: 46042 | B20: =TEXT(A20,"DDD") -> Tue | C20: =WEEKNUM(A20) -> 4 | D20: =TEXT(A20,"mmmm") -> January | E20: j1 | F20: =IF(E20="J1",$O$3,IF(E20="J2",$O$4,IF(E20="J3",$O$5,IF(E20="J4",$O$6,IF(E20="J5",$O$7," "))))) -> Total hari kerja | G20: REINA DWI MAHARANI | H20: 3
A21: 46043 | B21: =TEXT(A21,"DDD") -> Wed | C21: =WEEKNUM(A21) -> 4 | D21: =TEXT(A21,"mmmm") -> January | F21: =IF(E21="J1",$O$3,IF(E21="J2",$O$4,IF(E21="J3",$O$5,IF(E21="J4",$O$6,IF(E21="J5",$O$7," "))))) | G21: REINA DWI MAHARANI
A22: 46044 | B22: =TEXT(A22,"DDD") -> Thu | C22: =WEEKNUM(A22) -> 4 | D22: =TEXT(A22,"mmmm") -> January | F22: =IF(E22="J1",$O$3,IF(E22="J2",$O$4,IF(E22="J3",$O$5,IF(E22="J4",$O$6,IF(E22="J5",$O$7," "))))) | G22: REINA DWI MAHARANI
A23: 46045 | B23: =TEXT(A23,"DDD") -> Fri | C23: =WEEKNUM(A23) -> 4 | D23: =TEXT(A23,"mmmm") -> January | F23: =IF(E23="J1",$O$3,IF(E23="J2",$O$4,IF(E23="J3",$O$5,IF(E23="J4",$O$6,IF(E23="J5",$O$7," "))))) | G23: REINA DWI MAHARANI
A24: 46046 | B24: =TEXT(A24,"DDD") -> Sat | C24: =WEEKNUM(A24) -> 4 | D24: =TEXT(A24,"mmmm") -> January | F24: =IF(E24="J1",$O$3,IF(E24="J2",$O$4,IF(E24="J3",$O$5,IF(E24="J4",$O$6,IF(E24="J5",$O$7," "))))) | G24: REINA DWI MAHARANI
A25: 46047 | B25: =TEXT(A25,"DDD") -> Sun | C25: =WEEKNUM(A25) -> 5 | D25: =TEXT(A25,"mmmm") -> January | F25: =IF(E25="J1",$O$3,IF(E25="J2",$O$4,IF(E25="J3",$O$5,IF(E25="J4",$O$6,IF(E25="J5",$O$7," "))))) | G25: REINA DWI MAHARANI
A26: 46048 | B26: =TEXT(A26,"DDD") -> Mon | C26: =WEEKNUM(A26) -> 5 | D26: =TEXT(A26,"mmmm") -> January | E26: J1 | F26: =IF(E26="J1",$O$3,IF(E26="J2",$O$4,IF(E26="J3",$O$5,IF(E26="J4",$O$6,IF(E26="J5",$O$7," "))))) -> Total hari kerja | G26: GEFIRA SITI NURHALIJAH | H26: 3 | I26: 5 | J26: 1
A27: 46049 | B27: =TEXT(A27,"DDD") -> Tue | C27: =WEEKNUM(A27) -> 5 | D27: =TEXT(A27,"mmmm") -> January | E27: J1 | F27: =IF(E27="J1",$O$3,IF(E27="J2",$O$4,IF(E27="J3",$O$5,IF(E27="J4",$O$6,IF(E27="J5",$O$7," "))))) -> Total hari kerja | G27: GEFIRA SITI NURHALIJAH | H27: 1 | I27: 3 | J27: 4
A28: 46050 | B28: =TEXT(A28,"DDD") -> Wed | C28: =WEEKNUM(A28) -> 5 | D28: =TEXT(A28,"mmmm") -> January | E28: J1 | F28: =IF(E28="J1",$O$3,IF(E28="J2",$O$4,IF(E28="J3",$O$5,IF(E28="J4",$O$6,IF(E28="J5",$O$7," "))))) -> Total hari kerja | G28: GEFIRA SITI NURHALIJAH | H28: 1 | I28: 2
A29: 46051 | B29: =TEXT(A29,"DDD") -> Thu | C29: =WEEKNUM(A29) -> 5 | D29: =TEXT(A29,"mmmm") -> January | E29: J2 | F29: =IF(E29="J1",$O$3,IF(E29="J2",$O$4,IF(E29="J3",$O$5,IF(E29="J4",$O$6,IF(E29="J5",$O$7," "))))) -> Ijin/Sakit/Alfa | G29: GEFIRA SITI NURHALIJAH
A30: 46052 | B30: =TEXT(A30,"DDD") -> Fri | C30: =WEEKNUM(A30) -> 5 | D30: =TEXT(A30,"mmmm") -> January | E30: J1 | F30: =IF(E30="J1",$O$3,IF(E30="J2",$O$4,IF(E30="J3",$O$5,IF(E30="J4",$O$6,IF(E30="J5",$O$7," "))))) -> Total hari kerja | G30: GEFIRA SITI NURHALIJAH | H30: 3 | I30: 4 | J30: 2
A31: 46053 | B31: =TEXT(A31,"DDD") -> Sat | C31: =WEEKNUM(A31) -> 5 | D31: =TEXT(A31,"mmmm") -> January | E31: J1 | F31: =IF(E31="J1",$O$3,IF(E31="J2",$O$4,IF(E31="J3",$O$5,IF(E31="J4",$O$6,IF(E31="J5",$O$7," "))))) -> Total hari kerja | G31: GEFIRA SITI NURHALIJAH
A32: 46054 | B32: =TEXT(A32,"DDD") -> Sun | C32: =WEEKNUM(A32) -> 6 | D32: =TEXT(A32,"mmmm") -> February | F32: =IF(E32="J1",$O$3,IF(E32="J2",$O$4,IF(E32="J3",$O$5,IF(E32="J4",$O$6,IF(E32="J5",$O$7," "))))) | G32: GEFIRA SITI NURHALIJAH
A33: 46055 | B33: =TEXT(A33,"DDD") -> Mon | C33: =WEEKNUM(A33) -> 6 | D33: =TEXT(A33,"mmmm") -> February | E33: J1 | F33: =IF(E33="J1",$O$3,IF(E33="J2",$O$4,IF(E33="J3",$O$5,IF(E33="J4",$O$6,IF(E33="J5",$O$7," "))))) -> Total hari kerja | G33: GEFIRA SITI NURHALIJAH | H33: 2 | I33: 1 | J33: 3
A34: 46056 | B34: =TEXT(A34,"DDD") -> Tue | C34: =WEEKNUM(A34) -> 6 | D34: =TEXT(A34,"mmmm") -> February | E34: J1 | F34: =IF(E34="J1",$O$3,IF(E34="J2",$O$4,IF(E34="J3",$O$5,IF(E34="J4",$O$6,IF(E34="J5",$O$7," "))))) -> Total hari kerja | G34: GEFIRA SITI NURHALIJAH | H34: 3 | I34: 1
A35: 46057 | B35: =TEXT(A35,"DDD") -> Wed | C35: =WEEKNUM(A35) -> 6 | D35: =TEXT(A35,"mmmm") -> February | E35: J1 | F35: =IF(E35="J1",$O$3,IF(E35="J2",$O$4,IF(E35="J3",$O$5,IF(E35="J4",$O$6,IF(E35="J5",$O$7," "))))) -> Total hari kerja | G35: GEFIRA SITI NURHALIJAH | H35: 2 | I35: 4 | J35: 1
A36: 46058 | B36: =TEXT(A36,"DDD") -> Thu | C36: =WEEKNUM(A36) -> 6 | D36: =TEXT(A36,"mmmm") -> February | E36: J1 | F36: =IF(E36="J1",$O$3,IF(E36="J2",$O$4,IF(E36="J3",$O$5,IF(E36="J4",$O$6,IF(E36="J5",$O$7," "))))) -> Total hari kerja | G36: GEFIRA SITI NURHALIJAH | H36: 4
A37: 46059 | B37: =TEXT(A37,"DDD") -> Fri | C37: =WEEKNUM(A37) -> 6 | D37: =TEXT(A37,"mmmm") -> February | E37: J1 | F37: =IF(E37="J1",$O$3,IF(E37="J2",$O$4,IF(E37="J3",$O$5,IF(E37="J4",$O$6,IF(E37="J5",$O$7," "))))) -> Total hari kerja | G37: GEFIRA SITI NURHALIJAH | H37: 1
A38: 46060 | B38: =TEXT(A38,"DDD") -> Sat | C38: =WEEKNUM(A38) -> 6 | D38: =TEXT(A38,"mmmm") -> February | E38: J1 | F38: =IF(E38="J1",$O$3,IF(E38="J2",$O$4,IF(E38="J3",$O$5,IF(E38="J4",$O$6,IF(E38="J5",$O$7," "))))) -> Total hari kerja | G38: GEFIRA SITI NURHALIJAH | H38: 2 | I38: 1
A39: 46061 | B39: =TEXT(A39,"DDD") -> Sun | C39: =WEEKNUM(A39) -> 7 | D39: =TEXT(A39,"mmmm") -> February | F39: =IF(E39="J1",$O$3,IF(E39="J2",$O$4,IF(E39="J3",$O$5,IF(E39="J4",$O$6,IF(E39="J5",$O$7," "))))) | G39: GEFIRA SITI NURHALIJAH
A40: 46062 | B40: =TEXT(A40,"DDD") -> Mon | C40: =WEEKNUM(A40) -> 7 | D40: =TEXT(A40,"mmmm") -> February | E40: J1 | F40: =IF(E40="J1",$O$3,IF(E40="J2",$O$4,IF(E40="J3",$O$5,IF(E40="J4",$O$6,IF(E40="J5",$O$7," "))))) -> Total hari kerja | G40: GEFIRA SITI NURHALIJAH | H40: 1 | I40: 3
...

Sheet EKI
A1: GUDANG | J1: EKI
A2: DATE | B2: DAY | C2: WEEK | D2: MONTH | E2: KODE KET | F2: KETERANGAN | G2: NAMA KARYAWAN | H2: LEMBUR
A3: 46054 | B3: =TEXT(A3,"DDD") -> Sun | C3: =WEEKNUM(A3) -> 6 | D3: =TEXT(A3,"mmmm") -> February | F3: =IF(E3="J1",$L$3,IF(E3="J2",$L$4,IF(E3="J3",$L$5,IF(E3="J4",$L$6,IF(E3="J5",$L$7," "))))) | G3: REVKI FIRDAUS | K3: J1 | L3: Total hari kerja
A4: 46055 | B4: =TEXT(A4,"DDD") -> Mon | C4: =WEEKNUM(A4) -> 6 | D4: =TEXT(A4,"mmmm") -> February | E4: J1 | F4: =IF(E4="J1",$L$3,IF(E4="J2",$L$4,IF(E4="J3",$L$5,IF(E4="J4",$L$6,IF(E4="J5",$L$7," "))))) -> Total hari kerja | G4: REVKI FIRDAUS | K4: J2 | L4: Ijin/Sakit/Alfa
A5: 46056 | B5: =TEXT(A5,"DDD") -> Tue | C5: =WEEKNUM(A5) -> 6 | D5: =TEXT(A5,"mmmm") -> February | E5: J1 | F5: =IF(E5="J1",$L$3,IF(E5="J2",$L$4,IF(E5="J3",$L$5,IF(E5="J4",$L$6,IF(E5="J5",$L$7," "))))) -> Total hari kerja | G5: REVKI FIRDAUS | K5: J3 | L5: MERAH
A6: 46057 | B6: =TEXT(A6,"DDD") -> Wed | C6: =WEEKNUM(A6) -> 6 | D6: =TEXT(A6,"mmmm") -> February | E6: J1 | F6: =IF(E6="J1",$L$3,IF(E6="J2",$L$4,IF(E6="J3",$L$5,IF(E6="J4",$L$6,IF(E6="J5",$L$7," "))))) -> Total hari kerja | G6: REVKI FIRDAUS | K6: J4 | L6: LEMBUR
A7: 46058 | B7: =TEXT(A7,"DDD") -> Thu | C7: =WEEKNUM(A7) -> 6 | D7: =TEXT(A7,"mmmm") -> February | E7: J1 | F7: =IF(E7="J1",$L$3,IF(E7="J2",$L$4,IF(E7="J3",$L$5,IF(E7="J4",$L$6,IF(E7="J5",$L$7," "))))) -> Total hari kerja | G7: REVKI FIRDAUS | K7: J5 | L7: 1/2 HARI
A8: 46059 | B8: =TEXT(A8,"DDD") -> Fri | C8: =WEEKNUM(A8) -> 6 | D8: =TEXT(A8,"mmmm") -> February | E8: J1 | F8: =IF(E8="J1",$L$3,IF(E8="J2",$L$4,IF(E8="J3",$L$5,IF(E8="J4",$L$6,IF(E8="J5",$L$7," "))))) -> Total hari kerja | G8: REVKI FIRDAUS
A9: 46060 | B9: =TEXT(A9,"DDD") -> Sat | C9: =WEEKNUM(A9) -> 6 | D9: =TEXT(A9,"mmmm") -> February | E9: J1 | F9: =IF(E9="J1",$L$3,IF(E9="J2",$L$4,IF(E9="J3",$L$5,IF(E9="J4",$L$6,IF(E9="J5",$L$7," "))))) -> Total hari kerja | G9: REVKI FIRDAUS
A10: 46061 | B10: =TEXT(A10,"DDD") -> Sun | C10: =WEEKNUM(A10) -> 7 | D10: =TEXT(A10,"mmmm") -> February | F10: =IF(E10="J1",$L$3,IF(E10="J2",$L$4,IF(E10="J3",$L$5,IF(E10="J4",$L$6,IF(E10="J5",$L$7," "))))) | G10: REVKI FIRDAUS
A11: 46062 | B11: =TEXT(A11,"DDD") -> Mon | C11: =WEEKNUM(A11) -> 7 | D11: =TEXT(A11,"mmmm") -> February | E11: J1 | F11: =IF(E11="J1",$L$3,IF(E11="J2",$L$4,IF(E11="J3",$L$5,IF(E11="J4",$L$6,IF(E11="J5",$L$7," "))))) -> Total hari kerja | G11: REVKI FIRDAUS
A12: 46063 | B12: =TEXT(A12,"DDD") -> Tue | C12: =WEEKNUM(A12) -> 7 | D12: =TEXT(A12,"mmmm") -> February | E12: J1 | F12: =IF(E12="J1",$L$3,IF(E12="J2",$L$4,IF(E12="J3",$L$5,IF(E12="J4",$L$6,IF(E12="J5",$L$7," "))))) -> Total hari kerja | G12: REVKI FIRDAUS
A13: 46064 | B13: =TEXT(A13,"DDD") -> Wed | C13: =WEEKNUM(A13) -> 7 | D13: =TEXT(A13,"mmmm") -> February | E13: J1 | F13: =IF(E13="J1",$L$3,IF(E13="J2",$L$4,IF(E13="J3",$L$5,IF(E13="J4",$L$6,IF(E13="J5",$L$7," "))))) -> Total hari kerja | G13: REVKI FIRDAUS
A14: 46065 | B14: =TEXT(A14,"DDD") -> Thu | C14: =WEEKNUM(A14) -> 7 | D14: =TEXT(A14,"mmmm") -> February | E14: J1 | F14: =IF(E14="J1",$L$3,IF(E14="J2",$L$4,IF(E14="J3",$L$5,IF(E14="J4",$L$6,IF(E14="J5",$L$7," "))))) -> Total hari kerja | G14: REVKI FIRDAUS
A15: 46066 | B15: =TEXT(A15,"DDD") -> Fri | C15: =WEEKNUM(A15) -> 7 | D15: =TEXT(A15,"mmmm") -> February | E15: J1 | F15: =IF(E15="J1",$L$3,IF(E15="J2",$L$4,IF(E15="J3",$L$5,IF(E15="J4",$L$6,IF(E15="J5",$L$7," "))))) -> Total hari kerja | G15: REVKI FIRDAUS
A16: 46067 | B16: =TEXT(A16,"DDD") -> Sat | C16: =WEEKNUM(A16) -> 7 | D16: =TEXT(A16,"mmmm") -> February | E16: J1 | F16: =IF(E16="J1",$L$3,IF(E16="J2",$L$4,IF(E16="J3",$L$5,IF(E16="J4",$L$6,IF(E16="J5",$L$7," "))))) -> Total hari kerja | G16: REVKI FIRDAUS
A17: 46068 | B17: =TEXT(A17,"DDD") -> Sun | C17: =WEEKNUM(A17) -> 8 | D17: =TEXT(A17,"mmmm") -> February | F17: =IF(E17="J1",$L$3,IF(E17="J2",$L$4,IF(E17="J3",$L$5,IF(E17="J4",$L$6,IF(E17="J5",$L$7," "))))) | G17: REVKI FIRDAUS | I17: GAJIHAN
A18: 46069 | B18: =TEXT(A18,"DDD") -> Mon | C18: =WEEKNUM(A18) -> 8 | D18: =TEXT(A18,"mmmm") -> February | E18: J1 | F18: =IF(E18="J1",$L$3,IF(E18="J2",$L$4,IF(E18="J3",$L$5,IF(E18="J4",$L$6,IF(E18="J5",$L$7," "))))) -> Total hari kerja | G18: REVKI FIRDAUS
A19: 46070 | B19: =TEXT(A19,"DDD") -> Tue | C19: =WEEKNUM(A19) -> 8 | D19: =TEXT(A19,"mmmm") -> February | E19: J1 | F19: =IF(E19="J1",$L$3,IF(E19="J2",$L$4,IF(E19="J3",$L$5,IF(E19="J4",$L$6,IF(E19="J5",$L$7," "))))) -> Total hari kerja | G19: REVKI FIRDAUS
A20: 46071 | B20: =TEXT(A20,"DDD") -> Wed | C20: =WEEKNUM(A20) -> 8 | D20: =TEXT(A20,"mmmm") -> February | E20: J1 | F20: =IF(E20="J1",$L$3,IF(E20="J2",$L$4,IF(E20="J3",$L$5,IF(E20="J4",$L$6,IF(E20="J5",$L$7," "))))) -> Total hari kerja | G20: REVKI FIRDAUS
A21: 46072 | B21: =TEXT(A21,"DDD") -> Thu | C21: =WEEKNUM(A21) -> 8 | D21: =TEXT(A21,"mmmm") -> February | E21: J1 | F21: =IF(E21="J1",$L$3,IF(E21="J2",$L$4,IF(E21="J3",$L$5,IF(E21="J4",$L$6,IF(E21="J5",$L$7," "))))) -> Total hari kerja | G21: REVKI FIRDAUS
A22: 46073 | B22: =TEXT(A22,"DDD") -> Fri | C22: =WEEKNUM(A22) -> 8 | D22: =TEXT(A22,"mmmm") -> February | E22: J1 | F22: =IF(E22="J1",$L$3,IF(E22="J2",$L$4,IF(E22="J3",$L$5,IF(E22="J4",$L$6,IF(E22="J5",$L$7," "))))) -> Total hari kerja | G22: REVKI FIRDAUS
A23: 46074 | B23: =TEXT(A23,"DDD") -> Sat | C23: =WEEKNUM(A23) -> 8 | D23: =TEXT(A23,"mmmm") -> February | E23: J1 | F23: =IF(E23="J1",$L$3,IF(E23="J2",$L$4,IF(E23="J3",$L$5,IF(E23="J4",$L$6,IF(E23="J5",$L$7," "))))) -> Total hari kerja | G23: REVKI FIRDAUS
A24: 46075 | B24: =TEXT(A24,"DDD") -> Sun | C24: =WEEKNUM(A24) -> 9 | D24: =TEXT(A24,"mmmm") -> February | F24: =IF(E24="J1",$L$3,IF(E24="J2",$L$4,IF(E24="J3",$L$5,IF(E24="J4",$L$6,IF(E24="J5",$L$7," "))))) | G24: REVKI FIRDAUS
A25: 46076 | B25: =TEXT(A25,"DDD") -> Mon | C25: =WEEKNUM(A25) -> 9 | D25: =TEXT(A25,"mmmm") -> February | E25: J1 | F25: =IF(E25="J1",$L$3,IF(E25="J2",$L$4,IF(E25="J3",$L$5,IF(E25="J4",$L$6,IF(E25="J5",$L$7," "))))) -> Total hari kerja | G25: REVKI FIRDAUS
A26: 46077 | B26: =TEXT(A26,"DDD") -> Tue | C26: =WEEKNUM(A26) -> 9 | D26: =TEXT(A26,"mmmm") -> February | E26: J1 | F26: =IF(E26="J1",$L$3,IF(E26="J2",$L$4,IF(E26="J3",$L$5,IF(E26="J4",$L$6,IF(E26="J5",$L$7," "))))) -> Total hari kerja | G26: REVKI FIRDAUS
A27: 46078 | B27: =TEXT(A27,"DDD") -> Wed | C27: =WEEKNUM(A27) -> 9 | D27: =TEXT(A27,"mmmm") -> February | E27: J1 | F27: =IF(E27="J1",$L$3,IF(E27="J2",$L$4,IF(E27="J3",$L$5,IF(E27="J4",$L$6,IF(E27="J5",$L$7," "))))) -> Total hari kerja | G27: REVKI FIRDAUS
A28: 46079 | B28: =TEXT(A28,"DDD") -> Thu | C28: =WEEKNUM(A28) -> 9 | D28: =TEXT(A28,"mmmm") -> February | E28: J1 | F28: =IF(E28="J1",$L$3,IF(E28="J2",$L$4,IF(E28="J3",$L$5,IF(E28="J4",$L$6,IF(E28="J5",$L$7," "))))) -> Total hari kerja | G28: REVKI FIRDAUS
A29: 46080 | B29: =TEXT(A29,"DDD") -> Fri | C29: =WEEKNUM(A29) -> 9 | D29: =TEXT(A29,"mmmm") -> February | E29: J1 | F29: =IF(E29="J1",$L$3,IF(E29="J2",$L$4,IF(E29="J3",$L$5,IF(E29="J4",$L$6,IF(E29="J5",$L$7," "))))) -> Total hari kerja | G29: REVKI FIRDAUS
A30: 46081 | B30: =TEXT(A30,"DDD") -> Sat | C30: =WEEKNUM(A30) -> 9 | D30: =TEXT(A30,"mmmm") -> February | E30: J1 | F30: =IF(E30="J1",$L$3,IF(E30="J2",$L$4,IF(E30="J3",$L$5,IF(E30="J4",$L$6,IF(E30="J5",$L$7," "))))) -> Total hari kerja | G30: REVKI FIRDAUS
A31: 46082 | B31: =TEXT(A31,"DDD") -> Sun | C31: =WEEKNUM(A31) -> 10 | D31: =TEXT(A31,"mmmm") -> March | F31: =IF(E31="J1",$L$3,IF(E31="J2",$L$4,IF(E31="J3",$L$5,IF(E31="J4",$L$6,IF(E31="J5",$L$7," "))))) | G31: REVKI FIRDAUS
A32: 46083 | B32: =TEXT(A32,"DDD") -> Mon | C32: =WEEKNUM(A32) -> 10 | D32: =TEXT(A32,"mmmm") -> March | E32: J1 | F32: =IF(E32="J1",$L$3,IF(E32="J2",$L$4,IF(E32="J3",$L$5,IF(E32="J4",$L$6,IF(E32="J5",$L$7," "))))) -> Total hari kerja | G32: REVKI FIRDAUS
A33: 46084 | B33: =TEXT(A33,"DDD") -> Tue | C33: =WEEKNUM(A33) -> 10 | D33: =TEXT(A33,"mmmm") -> March | E33: J1 | F33: =IF(E33="J1",$L$3,IF(E33="J2",$L$4,IF(E33="J3",$L$5,IF(E33="J4",$L$6,IF(E33="J5",$L$7," "))))) -> Total hari kerja | G33: REVKI FIRDAUS
A34: 46085 | B34: =TEXT(A34,"DDD") -> Wed | C34: =WEEKNUM(A34) -> 10 | D34: =TEXT(A34,"mmmm") -> March | E34: J1 | F34: =IF(E34="J1",$L$3,IF(E34="J2",$L$4,IF(E34="J3",$L$5,IF(E34="J4",$L$6,IF(E34="J5",$L$7," "))))) -> Total hari kerja | G34: REVKI FIRDAUS
A35: 46086 | B35: =TEXT(A35,"DDD") -> Thu | C35: =WEEKNUM(A35) -> 10 | D35: =TEXT(A35,"mmmm") -> March | E35: J1 | F35: =IF(E35="J1",$L$3,IF(E35="J2",$L$4,IF(E35="J3",$L$5,IF(E35="J4",$L$6,IF(E35="J5",$L$7," "))))) -> Total hari kerja | G35: REVKI FIRDAUS
A36: 46087 | B36: =TEXT(A36,"DDD") -> Fri | C36: =WEEKNUM(A36) -> 10 | D36: =TEXT(A36,"mmmm") -> March | E36: J1 | F36: =IF(E36="J1",$L$3,IF(E36="J2",$L$4,IF(E36="J3",$L$5,IF(E36="J4",$L$6,IF(E36="J5",$L$7," "))))) -> Total hari kerja | G36: REVKI FIRDAUS | H36: 1 | I36: 1
A37: 46088 | B37: =TEXT(A37,"DDD") -> Sat | C37: =WEEKNUM(A37) -> 10 | D37: =TEXT(A37,"mmmm") -> March | E37: J1 | F37: =IF(E37="J1",$L$3,IF(E37="J2",$L$4,IF(E37="J3",$L$5,IF(E37="J4",$L$6,IF(E37="J5",$L$7," "))))) -> Total hari kerja | G37: REVKI FIRDAUS | H37: 1 | I37: 1
A38: 46089 | B38: =TEXT(A38,"DDD") -> Sun | C38: =WEEKNUM(A38) -> 11 | D38: =TEXT(A38,"mmmm") -> March | F38: =IF(E38="J1",$L$3,IF(E38="J2",$L$4,IF(E38="J3",$L$5,IF(E38="J4",$L$6,IF(E38="J5",$L$7," "))))) | G38: REVKI FIRDAUS
A39: 46090 | B39: =TEXT(A39,"DDD") -> Mon | C39: =WEEKNUM(A39) -> 11 | D39: =TEXT(A39,"mmmm") -> March | E39: J1 | F39: =IF(E39="J1",$L$3,IF(E39="J2",$L$4,IF(E39="J3",$L$5,IF(E39="J4",$L$6,IF(E39="J5",$L$7," "))))) -> Total hari kerja | G39: REVKI FIRDAUS | H39: 1 | I39: 1
A40: 46091 | B40: =TEXT(A40,"DDD") -> Tue | C40: =WEEKNUM(A40) -> 11 | D40: =TEXT(A40,"mmmm") -> March | E40: J1 | F40: =IF(E40="J1",$L$3,IF(E40="J2",$L$4,IF(E40="J3",$L$5,IF(E40="J4",$L$6,IF(E40="J5",$L$7," "))))) -> Total hari kerja | G40: REVKI FIRDAUS | H40: 1 | I40: 1
...

Sheet RADIT
A1: GUDANG | J1: RADIT
A2: DATE | B2: DAY | C2: WEEK | D2: MONTH | E2: KODE KET | F2: KETERANGAN | G2: NAMA KARYAWAN | H2: LEMBUR
A3: 46113 | B3: =TEXT(A3,"DDD") -> Wed | C3: =WEEKNUM(A3) -> 14 | D3: =TEXT(A3,"mmmm") -> April | E3: J1 | F3: =IF(E3="J1",$L$3,IF(E3="J2",$L$4,IF(E3="J3",$L$5,IF(E3="J4",$L$6,IF(E3="J5",$L$7," "))))) -> Total hari kerja | G3: RADIT | H3: 3 | K3: J1 | L3: Total hari kerja
A4: 46114 | B4: =TEXT(A4,"DDD") -> Thu | C4: =WEEKNUM(A4) -> 14 | D4: =TEXT(A4,"mmmm") -> April | E4: J1 | F4: =IF(E4="J1",$L$3,IF(E4="J2",$L$4,IF(E4="J3",$L$5,IF(E4="J4",$L$6,IF(E4="J5",$L$7," "))))) -> Total hari kerja | G4: RADIT | H4: 2 | K4: J2 | L4: Ijin/Sakit/Alfa
A5: 46115 | B5: =TEXT(A5,"DDD") -> Fri | C5: =WEEKNUM(A5) -> 14 | D5: =TEXT(A5,"mmmm") -> April | E5: J1 | F5: =IF(E5="J1",$L$3,IF(E5="J2",$L$4,IF(E5="J3",$L$5,IF(E5="J4",$L$6,IF(E5="J5",$L$7," "))))) -> Total hari kerja | G5: RADIT | H5: 5 | K5: J3 | L5: MERAH
A6: 46116 | B6: =TEXT(A6,"DDD") -> Sat | C6: =WEEKNUM(A6) -> 14 | D6: =TEXT(A6,"mmmm") -> April | E6: J1 | F6: =IF(E6="J1",$L$3,IF(E6="J2",$L$4,IF(E6="J3",$L$5,IF(E6="J4",$L$6,IF(E6="J5",$L$7," "))))) -> Total hari kerja | G6: RADIT | H6: 5 | K6: J4 | L6: LEMBUR
A7: 46117 | B7: =TEXT(A7,"DDD") -> Sun | C7: =WEEKNUM(A7) -> 15 | D7: =TEXT(A7,"mmmm") -> April | F7: =IF(E7="J1",$L$3,IF(E7="J2",$L$4,IF(E7="J3",$L$5,IF(E7="J4",$L$6,IF(E7="J5",$L$7," "))))) | G7: RADIT | K7: J5 | L7: 1/2 HARI
A8: 46118 | B8: =TEXT(A8,"DDD") -> Mon | C8: =WEEKNUM(A8) -> 15 | D8: =TEXT(A8,"mmmm") -> April | E8: J1 | F8: =IF(E8="J1",$L$3,IF(E8="J2",$L$4,IF(E8="J3",$L$5,IF(E8="J4",$L$6,IF(E8="J5",$L$7," "))))) -> Total hari kerja | G8: RADIT | H8: 5
A9: 46119 | B9: =TEXT(A9,"DDD") -> Tue | C9: =WEEKNUM(A9) -> 15 | D9: =TEXT(A9,"mmmm") -> April | E9: J1 | F9: =IF(E9="J1",$L$3,IF(E9="J2",$L$4,IF(E9="J3",$L$5,IF(E9="J4",$L$6,IF(E9="J5",$L$7," "))))) -> Total hari kerja | G9: RADIT | H9: 5
A10: 46120 | B10: =TEXT(A10,"DDD") -> Wed | C10: =WEEKNUM(A10) -> 15 | D10: =TEXT(A10,"mmmm") -> April | E10: J1 | F10: =IF(E10="J1",$L$3,IF(E10="J2",$L$4,IF(E10="J3",$L$5,IF(E10="J4",$L$6,IF(E10="J5",$L$7," "))))) -> Total hari kerja | G10: RADIT | H10: 5
A11: 46121 | B11: =TEXT(A11,"DDD") -> Thu | C11: =WEEKNUM(A11) -> 15 | D11: =TEXT(A11,"mmmm") -> April | E11: J1 | F11: =IF(E11="J1",$L$3,IF(E11="J2",$L$4,IF(E11="J3",$L$5,IF(E11="J4",$L$6,IF(E11="J5",$L$7," "))))) -> Total hari kerja | G11: RADIT | H11: 5
A12: 46122 | B12: =TEXT(A12,"DDD") -> Fri | C12: =WEEKNUM(A12) -> 15 | D12: =TEXT(A12,"mmmm") -> April | E12: J2 | F12: =IF(E12="J1",$L$3,IF(E12="J2",$L$4,IF(E12="J3",$L$5,IF(E12="J4",$L$6,IF(E12="J5",$L$7," "))))) -> Ijin/Sakit/Alfa | G12: RADIT
A13: 46123 | B13: =TEXT(A13,"DDD") -> Sat | C13: =WEEKNUM(A13) -> 15 | D13: =TEXT(A13,"mmmm") -> April | E13: J1 | F13: =IF(E13="J1",$L$3,IF(E13="J2",$L$4,IF(E13="J3",$L$5,IF(E13="J4",$L$6,IF(E13="J5",$L$7," "))))) -> Total hari kerja | G13: RADIT | H13: 4.5
A14: 46124 | B14: =TEXT(A14,"DDD") -> Sun | C14: =WEEKNUM(A14) -> 16 | D14: =TEXT(A14,"mmmm") -> April | F14: =IF(E14="J1",$L$3,IF(E14="J2",$L$4,IF(E14="J3",$L$5,IF(E14="J4",$L$6,IF(E14="J5",$L$7," "))))) | G14: RADIT
A15: 46125 | B15: =TEXT(A15,"DDD") -> Mon | C15: =WEEKNUM(A15) -> 16 | D15: =TEXT(A15,"mmmm") -> April | E15: J1 | F15: =IF(E15="J1",$L$3,IF(E15="J2",$L$4,IF(E15="J3",$L$5,IF(E15="J4",$L$6,IF(E15="J5",$L$7," "))))) -> Total hari kerja | G15: RADIT | H15: 5
A16: 46126 | B16: =TEXT(A16,"DDD") -> Tue | C16: =WEEKNUM(A16) -> 16 | D16: =TEXT(A16,"mmmm") -> April | E16: J1 | F16: =IF(E16="J1",$L$3,IF(E16="J2",$L$4,IF(E16="J3",$L$5,IF(E16="J4",$L$6,IF(E16="J5",$L$7," "))))) -> Total hari kerja | G16: RADIT | H16: 5
A17: 46127 | B17: =TEXT(A17,"DDD") -> Wed | C17: =WEEKNUM(A17) -> 16 | D17: =TEXT(A17,"mmmm") -> April | E17: J1 | F17: =IF(E17="J1",$L$3,IF(E17="J2",$L$4,IF(E17="J3",$L$5,IF(E17="J4",$L$6,IF(E17="J5",$L$7," "))))) -> Total hari kerja | G17: RADIT | H17: 5
A18: 46128 | B18: =TEXT(A18,"DDD") -> Thu | C18: =WEEKNUM(A18) -> 16 | D18: =TEXT(A18,"mmmm") -> April | E18: J1 | F18: =IF(E18="J1",$L$3,IF(E18="J2",$L$4,IF(E18="J3",$L$5,IF(E18="J4",$L$6,IF(E18="J5",$L$7," "))))) -> Total hari kerja | G18: RADIT | H18: 5
A19: 46129 | B19: =TEXT(A19,"DDD") -> Fri | C19: =WEEKNUM(A19) -> 16 | D19: =TEXT(A19,"mmmm") -> April | E19: J1 | F19: =IF(E19="J1",$L$3,IF(E19="J2",$L$4,IF(E19="J3",$L$5,IF(E19="J4",$L$6,IF(E19="J5",$L$7," "))))) -> Total hari kerja | G19: RADIT | H19: 4
A20: 46130 | B20: =TEXT(A20,"DDD") -> Sat | C20: =WEEKNUM(A20) -> 16 | D20: =TEXT(A20,"mmmm") -> April | E20: J1 | F20: =IF(E20="J1",$L$3,IF(E20="J2",$L$4,IF(E20="J3",$L$5,IF(E20="J4",$L$6,IF(E20="J5",$L$7," "))))) -> Total hari kerja | G20: RADIT | H20: 3
A21: 46131 | B21: =TEXT(A21,"DDD") -> Sun | C21: =WEEKNUM(A21) -> 17 | D21: =TEXT(A21,"mmmm") -> April | F21: =IF(E21="J1",$L$3,IF(E21="J2",$L$4,IF(E21="J3",$L$5,IF(E21="J4",$L$6,IF(E21="J5",$L$7," "))))) | G21: RADIT
A22: 46132 | B22: =TEXT(A22,"DDD") -> Mon | C22: =WEEKNUM(A22) -> 17 | D22: =TEXT(A22,"mmmm") -> April | E22: J1 | F22: =IF(E22="J1",$L$3,IF(E22="J2",$L$4,IF(E22="J3",$L$5,IF(E22="J4",$L$6,IF(E22="J5",$L$7," "))))) -> Total hari kerja | G22: RADIT | H22: 2.5
A23: 46133 | B23: =TEXT(A23,"DDD") -> Tue | C23: =WEEKNUM(A23) -> 17 | D23: =TEXT(A23,"mmmm") -> April | E23: J1 | F23: =IF(E23="J1",$L$3,IF(E23="J2",$L$4,IF(E23="J3",$L$5,IF(E23="J4",$L$6,IF(E23="J5",$L$7," "))))) -> Total hari kerja | G23: RADIT | H23: 2.5
A24: 46134 | B24: =TEXT(A24,"DDD") -> Wed | C24: =WEEKNUM(A24) -> 17 | D24: =TEXT(A24,"mmmm") -> April | E24: J1 | F24: =IF(E24="J1",$L$3,IF(E24="J2",$L$4,IF(E24="J3",$L$5,IF(E24="J4",$L$6,IF(E24="J5",$L$7," "))))) -> Total hari kerja | G24: RADIT | H24: 2.5
A25: 46135 | B25: =TEXT(A25,"DDD") -> Thu | C25: =WEEKNUM(A25) -> 17 | D25: =TEXT(A25,"mmmm") -> April | E25: J1 | F25: =IF(E25="J1",$L$3,IF(E25="J2",$L$4,IF(E25="J3",$L$5,IF(E25="J4",$L$6,IF(E25="J5",$L$7," "))))) -> Total hari kerja | G25: RADIT | H25: 2.5
A26: 46136 | B26: =TEXT(A26,"DDD") -> Fri | C26: =WEEKNUM(A26) -> 17 | D26: =TEXT(A26,"mmmm") -> April | E26: J1 | F26: =IF(E26="J1",$L$3,IF(E26="J2",$L$4,IF(E26="J3",$L$5,IF(E26="J4",$L$6,IF(E26="J5",$L$7," "))))) -> Total hari kerja | G26: RADIT | H26: 3
A27: 46137 | B27: =TEXT(A27,"DDD") -> Sat | C27: =WEEKNUM(A27) -> 17 | D27: =TEXT(A27,"mmmm") -> April | E27: J1 | F27: =IF(E27="J1",$L$3,IF(E27="J2",$L$4,IF(E27="J3",$L$5,IF(E27="J4",$L$6,IF(E27="J5",$L$7," "))))) -> Total hari kerja | G27: RADIT | H27: 1.5
A28: 46138 | B28: =TEXT(A28,"DDD") -> Sun | C28: =WEEKNUM(A28) -> 18 | D28: =TEXT(A28,"mmmm") -> April | F28: =IF(E28="J1",$L$3,IF(E28="J2",$L$4,IF(E28="J3",$L$5,IF(E28="J4",$L$6,IF(E28="J5",$L$7," "))))) | G28: RADIT
A29: 46139 | B29: =TEXT(A29,"DDD") -> Mon | C29: =WEEKNUM(A29) -> 18 | D29: =TEXT(A29,"mmmm") -> April | E29: J1 | F29: =IF(E29="J1",$L$3,IF(E29="J2",$L$4,IF(E29="J3",$L$5,IF(E29="J4",$L$6,IF(E29="J5",$L$7," "))))) -> Total hari kerja | G29: RADIT | H29: 0.5
A30: 46140 | B30: =TEXT(A30,"DDD") -> Tue | C30: =WEEKNUM(A30) -> 18 | D30: =TEXT(A30,"mmmm") -> April | E30: J1 | F30: =IF(E30="J1",$L$3,IF(E30="J2",$L$4,IF(E30="J3",$L$5,IF(E30="J4",$L$6,IF(E30="J5",$L$7," "))))) -> Total hari kerja | G30: RADIT | H30: 1
A31: 46141 | B31: =TEXT(A31,"DDD") -> Wed | C31: =WEEKNUM(A31) -> 18 | D31: =TEXT(A31,"mmmm") -> April | E31: J1 | F31: =IF(E31="J1",$L$3,IF(E31="J2",$L$4,IF(E31="J3",$L$5,IF(E31="J4",$L$6,IF(E31="J5",$L$7," "))))) -> Total hari kerja | G31: RADIT | H31: 1
A32: 46142 | B32: =TEXT(A32,"DDD") -> Thu | C32: =WEEKNUM(A32) -> 18 | D32: =TEXT(A32,"mmmm") -> April | E32: J1 | F32: =IF(E32="J1",$L$3,IF(E32="J2",$L$4,IF(E32="J3",$L$5,IF(E32="J4",$L$6,IF(E32="J5",$L$7," "))))) -> Total hari kerja | G32: RADIT | H32: 2.5
A33: 46143 | B33: =TEXT(A33,"DDD") -> Fri | C33: =WEEKNUM(A33) -> 18 | D33: =TEXT(A33,"mmmm") -> May | E33: J1 | F33: =IF(E33="J1",$L$3,IF(E33="J2",$L$4,IF(E33="J3",$L$5,IF(E33="J4",$L$6,IF(E33="J5",$L$7," "))))) -> Total hari kerja | G33: RADIT | H33: 2
A34: 46144 | B34: =TEXT(A34,"DDD") -> Sat | C34: =WEEKNUM(A34) -> 18 | D34: =TEXT(A34,"mmmm") -> May | E34: J1 | F34: =IF(E34="J1",$L$3,IF(E34="J2",$L$4,IF(E34="J3",$L$5,IF(E34="J4",$L$6,IF(E34="J5",$L$7," "))))) -> Total hari kerja | G34: RADIT | H34: 2.5
A35: 46145 | B35: =TEXT(A35,"DDD") -> Sun | C35: =WEEKNUM(A35) -> 19 | D35: =TEXT(A35,"mmmm") -> May | F35: =IF(E35="J1",$L$3,IF(E35="J2",$L$4,IF(E35="J3",$L$5,IF(E35="J4",$L$6,IF(E35="J5",$L$7," "))))) | G35: RADIT
A36: 46146 | B36: =TEXT(A36,"DDD") -> Mon | C36: =WEEKNUM(A36) -> 19 | D36: =TEXT(A36,"mmmm") -> May | E36: J1 | F36: =IF(E36="J1",$L$3,IF(E36="J2",$L$4,IF(E36="J3",$L$5,IF(E36="J4",$L$6,IF(E36="J5",$L$7," "))))) -> Total hari kerja | G36: RADIT | H36: 3
A37: 46147 | B37: =TEXT(A37,"DDD") -> Tue | C37: =WEEKNUM(A37) -> 19 | D37: =TEXT(A37,"mmmm") -> May | E37: J1 | F37: =IF(E37="J1",$L$3,IF(E37="J2",$L$4,IF(E37="J3",$L$5,IF(E37="J4",$L$6,IF(E37="J5",$L$7," "))))) -> Total hari kerja | G37: RADIT | H37: 3.5
A38: 46148 | B38: =TEXT(A38,"DDD") -> Wed | C38: =WEEKNUM(A38) -> 19 | D38: =TEXT(A38,"mmmm") -> May | E38: J1 | F38: =IF(E38="J1",$L$3,IF(E38="J2",$L$4,IF(E38="J3",$L$5,IF(E38="J4",$L$6,IF(E38="J5",$L$7," "))))) -> Total hari kerja | G38: RADIT | H38: 2
A39: 46149 | B39: =TEXT(A39,"DDD") -> Thu | C39: =WEEKNUM(A39) -> 19 | D39: =TEXT(A39,"mmmm") -> May | E39: J1 | F39: =IF(E39="J1",$L$3,IF(E39="J2",$L$4,IF(E39="J3",$L$5,IF(E39="J4",$L$6,IF(E39="J5",$L$7," "))))) -> Total hari kerja | G39: RADIT | H39: 2
A40: 46150 | B40: =TEXT(A40,"DDD") -> Fri | C40: =WEEKNUM(A40) -> 19 | D40: =TEXT(A40,"mmmm") -> May | E40: J1 | F40: =IF(E40="J1",$L$3,IF(E40="J2",$L$4,IF(E40="J3",$L$5,IF(E40="J4",$L$6,IF(E40="J5",$L$7," "))))) -> Total hari kerja | G40: RADIT | H40: 1
...

Sheet rumus
U1: Total hari kerja | V1: =IFERROR(VLOOKUP(U1,$R$2:$S$8,2,0),"0") -> 25
B2: TOTALAN PEMBAYARAN UPAH KINI GROUP | G2: Periode : | H2: 46266 | I2: s/d | J2: 46295 | P2: NAMA KARYAWAN | Q2: KODE KET | R2: KETERANGAN | S2: Count of DATE | U2: Ijin/Sakit/Alfa | V2: =IFERROR(VLOOKUP(U2,$R$2:$S$8,2,0),"0") -> 1
B3: (HOST LIVE) | P3: EGA SILVIA YUNIAR | Q3: (blank) | S3: 4 | U3: MERAH | V3: =IFERROR(VLOOKUP(U3,$R$2:$S$8,2,0),"0") -> 0
Q4: j1 | R4: Total hari kerja | S4: 25 | U4: LEMBUR | V4: =IFERROR(VLOOKUP(U4,$R$2:$S$8,2,0),"0") -> 0
B5: NAMA : | C5: =P3 -> EGA SILVIA YUNIAR | G5: Gajih Pokok: | H5: 1500000 | I5: 25 | J5: (Hari kerja) | Q5: j2 | R5: Ijin/Sakit/Alfa | S5: 1 | U5: 1/2 HARI | V5: =IFERROR(VLOOKUP(U5,$R$2:$S$8,2,0),"0") -> 0
B6: 45689 | G6: Tunjangan transport | H6: 100000
G7: Tunjangan makan | H7: 250000
G8: Bruto | H8: =H5+H7+H6 -> 1850000 | I8: / | J8: =H8/I5 -> 74000 | K8: /Hari
B12: Total hari kerja | D12: =V1 -> 25 | E12: = | F12: =IF(B12="Total hari kerja",D12*J8,0) -> 1850000 | H12: Lembur jam | I12: =
B13: Ijin/Sakit/Alfa | D13: =V2 -> 1 | E13: = | F13: =IF(B13="IJIN/SAKIT/ALFA",D13*0,0) -> 0 | H13: Bonus | I13: =
B14: 1/2 hari | D14: =V5 -> 0 | E14: = | F14: =IF(B14="1/2 hari",D14*35000,0) -> 0 | I14: =
B15: Total Pembayaran | F15: =F12+F14+J12+J14+J13 -> 1850000 | J15: =J13+J14 -> 0
B16: Notes:
B17: 1. Gajih merupakan bayaran harian di 25 Hari kerja.
B18: 2. Jika berhalangan hadir (ijin/sakit) akan di potong sesuai upah harian.
B19: 3. Lembur di hitung sesuai dengan upah harian/per jam.
B20: 4. Thr mengikuti Gapok.
P24: NAMA KARYAWAN | Q24: KODE KET | R24: KETERANGAN | S24: Count of DATE | U24: Total hari kerja | V24: =IFERROR(VLOOKUP(U24,$R$25:$S$30,2,0),"0") -> 26
P25: GEFIRA SITI NURHALIJAH | Q25: (blank) | S25: 4 | U25: Ijin/Sakit/Alfa | V25: =IFERROR(VLOOKUP(U25,$R$26:$S$30,2,0),"0") -> 0
B26: HITUNGAN THR LAMA KERJA / 12 BULAN X GAJIH POKOK | Q26: j1 | R26: Total hari kerja | S26: 26 | U26: MERAH | V26: =IFERROR(VLOOKUP(U26,$R$26:$S$30,2,0),"0") -> 0
U27: LEMBUR | V27: =IFERROR(VLOOKUP(U27,$R$26:$S$30,2,0),"0") -> 0
U28: 1/2 HARI | V28: =IFERROR(VLOOKUP(U28,$R$26:$S$30,2,0),"0") -> 0
V29: =IFERROR(VLOOKUP(U29,$R$26:$S$30,2,0),"0") -> 0
C30: =4/12*1500000 -> 500000
B35: TOTALAN PEMBAYARAN UPAH KINI GROUP | G35: Periode : | H35: 46266 | I35: s/d | J35: 46295
B36: (HOST LIVE)
H37: (M)
B38: NAMA : | C38: =P25 -> GEFIRA SITI NURHALIJAH | G38: Gajih Pokok: | H38: 1350000 | I38: 25 | J38: (Hari kerja)
B39: 46023 | G39: Tunjangan makan | H39: 150000
G40: Bruto | H40: =H38+H39 -> 1500000 | I40: / | J40: =H40/I38 -> 60000 | K40: /Hari
B44: Total hari kerja | D44: =V24 -> 26 | E44: = | F44: =IF(B44="Total hari kerja",D44*J40,0) -> 1560000 | H44: Lembur jam | I44: =
B45: Ijin/Sakit/Alfa | D45: =V25 -> 0 | E45: = | F45: =IF(B45="IJIN/SAKIT/ALFA",D45*0,0) -> 0 | H45: Bonus | I45: =
B46: 1/2 hari | D46: =V28 -> 0 | E46: = | F46: =IF(B46="1/2 hari",D46*32000,0) -> 0 | I46: =
B47: Total Pembayaran | F47: =F44+F46+J44+J46 -> 1560000
B48: Notes:
B49: 1. Gajih merupakan bayaran harian di 25 Hari kerja.
B50: 2. Jika berhalangan hadir (ijin/sakit) akan di potong sesuai upah harian.
B51: 3. Lembur di hitung sesuai dengan upah harian/per jam.
B52: 4. Thr mengikuti Gapok.
P61: NAMA KARYAWAN | Q61: KODE KET | R61: KETERANGAN | S61: Count of DATE | T61: Sum of LEMBUR | U61: Total hari kerja | V61: =IFERROR(VLOOKUP(U61,$R$62:$S$67,2,0),"0") -> 26
...

Sheet RULES
A1: BIAYA OPERASIONAL | I1: april | J1: total
A2: AIR + KEAMANAN | B2: 150000 | I2: ='PERHITNGAN BONUS'!G6 -> 1952 | J2: ='PERHITNGAN BONUS'!G6*5000 -> 9760000
A3: LISTRIK | B3: 200000 | I3: ='PERHITNGAN BONUS'!B6 -> 2000 | J3: =I3*5000 -> 10000000
A4: MAKAN & MINUM | B4: =15000*25 -> 375000 | J4: =J2-J3 -> -240000 | K4: KOTOR
A5: GAJIH | B5: =1600000*2 -> 3200000 | J5: =J2*3.8% -> 370880 | K5: bonus
A6: SAMPLE | B6: 1000000 | J6: =J4-J5 -> -610880 | K6: BERSIH
A7: IKLAN | B7: =35000*30 -> 1050000
A8: TOTALAN | B8: =SUM(B2:B7) -> 5975000 | D8: TARGET 6 BULAN
A9: KEUNTUNGAN 25% | B9: =B8+C9 -> 7468750 | C9: =B8*25% -> 1493750 | D9: =C9*6 -> 8962500
A12: KOMISI AFFILATE | B12: 5000 | C12: TOTAL TARGET
A13: TOTALAN PCS (1 BULAN) | B13: =B9/B12 -> 1493.75 | C13: =B13/2 -> 746.875 | D13: /ORG
A14: TOTALAN PCS (1 HARI) | B14: =B13/25 -> 59.75 | C14: =B14/2 -> 29.875 | D14: /ORG

Sheet PERHITNGAN BONUS
M1: NAMA KARYAWAN | N1: MONTH | O1: Sum of SESI 1 | P1: Sum of SESI 2 | Q1: Sum of SESI 3 | R1: Sum of VT | S1: TOTAL
A2: TARGET BULANAN | B2: TARGET | C2: =M2 -> EGA SILVIA YUNIAR | D2: % | E2: =M17 -> GEFIRA SITI NURHALIJAH | F2: % | G2: GRAND TOTAL | H2: GRAND % | I2: - TARGET | J2: -% | M2: EGA SILVIA YUNIAR | N2: January | O2: 98 | P2: 45 | Q2: 6 | S2: =SUM(O2:R2) -> 149
A3: JANUARY | B3: 2000 | C3: =S2 -> 149 | D3: =(C3-$B$3)/$B$3+100% -> 0.0745 | E3: =S17 -> 29 | F3: =(E3-$B$3)/$B$3+100% -> 0.0145 | G3: =C3+E3 -> 178 | H3: =D3+F3 -> 0.089 | I3: =G3-B3 -> -1822 | J3: =H3-100% -> -0.911 | N3: February | O3: 81 | P3: 36 | Q3: 14 | S3: =SUM(O3:R3) -> 131
A4: FEBRUARY | B4: 2000 | C4: =S3 -> 131 | D4: =(C4-$B$4)/$B$4+100% -> 0.0655 | E4: =S18 -> 134 | F4: =(E4-$B$4)/$B$4+100% -> 0.067 | G4: =C4+E4 -> 265 | H4: =D4+F4 -> 0.1325 | I4: =G4-B4 -> -1735 | J4: =H4-100% -> -0.8675 | N4: March | O4: 147 | P4: 56 | Q4: 6 | S4: =SUM(O4:R4) -> 209
A5: MARCH | B5: 2000 | C5: =S4 -> 209 | D5: =(C5-$B$4)/$B$4+100% -> 0.1045 | E5: =S19 -> 193 | F5: =(E5-$B$4)/$B$4+100% -> 0.0965 | G5: =C5+E5 -> 402 | H5: =D5+F5 -> 0.201 | I5: =G5-B5 -> -1598 | J5: =H5-100% -> -0.799 | N5: April | O5: 900 | P5: 258 | S5: =SUM(O5:R5) -> 1158
A6: APRIL | B6: 2000 | C6: =S5 -> 1158 | D6: =(C6-$B$4)/$B$4+100% -> 0.579 | E6: =S20 -> 794 | F6: =(E6-$B$4)/$B$4+100% -> 0.397 | G6: =C6+E6 -> 1952 | H6: =D6+F6 -> 0.976 | I6: =G6-B6 -> -48 | J6: =H6-100% -> -0.024 | N6: May | O6: 422 | P6: 153 | Q6: 13 | S6: =SUM(O6:R6) -> 588
A7: MAY | B7: 2000 | C7: =S6 -> 588 | D7: =(C7-$B$4)/$B$4+100% -> 0.294 | E7: =S21 -> 449 | F7: =(E7-$B$4)/$B$4+100% -> 0.2245 | G7: =C7+E7 -> 1037 | H7: =D7+F7 -> 0.5185 | I7: =G7-B7 -> -963 | J7: =H7-100% -> -0.4815 | N7: June | O7: 204 | P7: 125 | Q7: 13 | S7: =SUM(O7:R7) -> 342
A8: JUNE | B8: 2000 | C8: =S7 -> 342 | D8: =(C8-$B$4)/$B$4+100% -> 0.171 | E8: =S22 -> 258 | F8: =(E8-$B$4)/$B$4+100% -> 0.129 | G8: =C8+E8 -> 600 | H8: =D8+F8 -> 0.3 | I8: =G8-B8 -> -1400 | J8: =H8-100% -> -0.7 | N8: July | O8: 424 | P8: 158 | S8: =SUM(O8:R8) -> 582
A9: JULY | B9: 2000 | C9: =S8 -> 582 | D9: =(C9-$B$4)/$B$4+100% -> 0.291 | E9: =S23 -> 349 | F9: =(E9-$B$4)/$B$4+100% -> 0.1745 | G9: =C9+E9 -> 931 | H9: =D9+F9 -> 0.4655 | I9: =G9-B9 -> -1069 | J9: =H9-100% -> -0.5345 | N9: August | O9: 365 | P9: 112 | Q9: 7 | S9: =SUM(O9:R9) -> 484
A10: AUGUST | B10: 2000 | C10: =S9 -> 484 | D10: =(C10-$B$4)/$B$4+100% -> 0.242 | E10: =S24 -> 200 | F10: =(E10-$B$4)/$B$4+100% -> 0.1 | G10: =C10+E10 -> 684 | H10: =D10+F10 -> 0.342 | I10: =G10-B10 -> -1316 | J10: =H10-100% -> -0.658 | N10: September | O10: 279 | P10: 71 | S10: =SUM(O10:R10) -> 350
A11: SEPTEMBER | B11: 2000 | C11: =S10 -> 350 | D11: =(C11-$B$4)/$B$4+100% -> 0.175 | E11: =S25 -> 188 | F11: =(E11-$B$4)/$B$4+100% -> 0.094 | G11: =C11+E11 -> 538 | H11: =D11+F11 -> 0.269 | I11: =G11-B11 -> -1462 | J11: =H11-100% -> -0.731 | N11: October | S11: =SUM(O11:R11) -> 0
A12: OCTOBER | B12: 2000 | C12: =S11 -> 0 | D12: =(C12-$B$4)/$B$4+100% -> 0 | E12: =S26 -> 0 | F12: =(E12-$B$4)/$B$4+100% -> 0 | G12: =C12+E12 -> 0 | H12: =D12+F12 -> 0 | I12: =G12-B12 -> -2000 | J12: =H12-100% -> -1 | N12: November | S12: =SUM(O12:R12) -> 0
A13: NOVEMBER | B13: 2000 | C13: =S12 -> 0 | D13: =(C13-$B$4)/$B$4+100% -> 0 | E13: =S27 -> 0 | F13: =(E13-$B$4)/$B$4+100% -> 0 | G13: =C13+E13 -> 0 | H13: =D13+F13 -> 0 | I13: =G13-B13 -> -2000 | J13: =H13-100% -> -1 | N13: December | S13: =SUM(O13:R13) -> 0
A14: DECEMBER | B14: 2000 | C14: =S13 -> 0 | D14: =(C14-$B$4)/$B$4+100% -> 0 | E14: =S28 -> 0 | F14: =(E14-$B$4)/$B$4+100% -> 0 | G14: =C14+E14 -> 0 | H14: =D14+F14 -> 0 | I14: =G14-B14 -> -2000 | J14: =H14-100% -> -1
A15: TOTAL | B15: =SUM(B3:B14) -> 24000 | C15: =SUM(C3:C14) -> 3993 | D15: =SUM(D3:D14) -> 1.9965 | E15: =SUM(E3:E14) -> 2594 | F15: =SUM(F3:F14) -> 1.297 | G15: =SUM(G3:G14) -> 6587 | H15: =SUM(H3:H14) -> 3.2935 | I15: =SUM(I3:I14) -> -17413 | J15: =SUM(J3:J14) -> -8.7065
M16: NAMA KARYAWAN | N16: MONTH | O16: Sum of SESI 1 | P16: Sum of SESI 2 | Q16: Sum of SESI 3 | R16: Sum of VT | S16: TOTAL
A17: TARGET / HARI | B17: 60 PCS | M17: GEFIRA SITI NURHALIJAH | N17: January | O17: 8 | P17: 14 | Q17: 7 | S17: =SUM(O17:R17) -> 29
B18: 30PCS | C18: /ORG | N18: February | O18: 60 | P18: 45 | Q18: 29 | S18: =SUM(O18:R18) -> 134
N19: March | O19: 68 | P19: 39 | Q19: 86 | S19: =SUM(O19:R19) -> 193
N20: April | O20: 483 | P20: 185 | Q20: 126 | S20: =SUM(O20:R20) -> 794
A21: PERHITUNGAN BONUS | N21: May | O21: 312 | P21: 133 | Q21: 4 | S21: =SUM(O21:R21) -> 449
A22: 1133 X 6 BULAN | B22: =B14*6 -> 12000 | C22: PCS | N22: June | O22: 128 | P22: 130 | S22: =SUM(O22:R22) -> 258
A23: KOMISI AFFILIATE | B23: 5000 | N23: July | O23: 165 | P23: 169 | Q23: 15 | S23: =SUM(O23:R23) -> 349
A24: TOTAL | B24: =B22*B23 -> 60000000 | C24: =6*RULES!B8 -> 35850000 | D24: =B24-C24 -> 24150000 | E24: (KEUNTUNGAN) | N24: August | O24: 82 | P24: 109 | Q24: 9 | S24: =SUM(O24:R24) -> 200
A25: BONUS 2% | B25: =B24*2% -> 1200000 | D25: =B25*2 -> 2400000 | N25: September | O25: 98 | P25: 72 | Q25: 18 | S25: =SUM(O25:R25) -> 188
D26: =D24-D25 -> 21750000 | E26: (GRAND KEUNTUNGAN) | N26: October | S26: =SUM(O26:R26) -> 0
N27: November | S27: =SUM(O27:R27) -> 0
S28: =SUM(O28:R28) -> 0
A30: CONTOH KASUS | E30: KHUSUS BULAN APARIL MEI JUNI (3 BULAN)
A31: SEMISAL DALAM 6 BULAN TERJUAL | C31: =B14*6 -> 12000 | D31: PCS | E31: =B13*3 -> 6000 | F31: 3500
A32: KOMISI AFFILIATE (5000) | C32: =C31*5000 -> 60000000 | E32: =E31*5000 -> 30000000 | F32: =F31*5000 -> 17500000
A33: BONUS 1% | C33: =C32*1% -> 600000 | E33: =E32*1% -> 300000
A34: BONUS 1,5% | G34: =F32*1.5% -> 262500
A37: BONUS AKHIR TAHUN (BAT)
A38: TARGET 1 TAHUN | C38: =B14*12 -> 24000 | D38: PCS
A39: KOMISI AFFILIATE (5000) | C39: =C38*5000 -> 120000000
A40: BONUS 1% | C40: =C39*1% -> 1200000
C41: =C40-C33 -> 600000

Sheet Sheet1
A1: TARGET | B1: LEVEL UP TARGET | C1: PENCAPAIAN | D1: TOTAL CASH IN | E1: KOMISI | F1: EGA | H1: REINA
A2: 1375 | B2: =(A2*35%)+A2 -> 1856.25 | C2: ='PERHITNGAN BONUS'!G6 -> 1952 | D2: =C2*5000 -> 9760000 | E2: =D2*1.5% -> 146400 | F2: ='PERHITNGAN BONUS'!D6 -> 0.579 | G2: =$E$2*(F2) -> 84765.6 | H2: ='PERHITNGAN BONUS'!F6 -> 0.397 | I2: =$E$2*(H2) -> 58120.8
A3: 1375 | B3: =(A3*35%)+A3 -> 1856.25 | C3: ='PERHITNGAN BONUS'!G7 -> 1037 | F3: ='PERHITNGAN BONUS'!D7 -> 0.294 | H3: ='PERHITNGAN BONUS'!F7 -> 0.2245
A4: 1375 | B4: =(A4*35%)+A4 -> 1856.25 | C4: ='PERHITNGAN BONUS'!G8 -> 600 | F4: ='PERHITNGAN BONUS'!D8 -> 0.171 | H4: ='PERHITNGAN BONUS'!F8 -> 0.129
A5: =SUM(A2:A4) -> 4125 | B5: =SUM(B2:B4) -> 5568.75

Sheet BONUS APRL,MEI,JUN
A1: TUJUAN KINI HOME
A2: KRITERIA | B2: JUMLAH | C2: SELAMA 1 BULAN | H2: target
A3: TARGET PENJUALAN | B3: =1375*5000 -> 6875000 | C3: =B3*2 -> 13750000 | G3: april | H3: =IF(B11<=$B$3,B11*$B$5,IF(B11>$B$3,B11*$C$6)) -> 322080
A4: TARGET PCS | B4: 2000 | C4: =B4*2 -> 4000 | G4: mei | H4: =IF(B17<=$B$3,B17*$B$5,IF(B17>$B$3,B17*$C$5)) -> 103700
A5: BONUS | B5: 0.02 | C5: 0.08 | G5: juni | H5: =IF(B23<=$B$3,B23*$B$5,IF(B23>$B$3,B23*$C$5)) -> 60000
A6: pencapaian 1/2 dari target | C6: 0.033
A7: KALKULASI BONUS DENGAN KETENTUAN
A8: STAF NAME | B8: TOTAL PENJUALAN | C8: TARGET PRODUK | D8: % | E8: BONUS | G8: UP TARGET | H8: =C4 -> 4000
A9: EGA | B9: =C9*5000 -> 5790000 | C9: =SUM('PERHITNGAN BONUS'!C6) -> 1158 | D9: =(B9-$C$3)/$C$3+100% -> 0.42109091 | E9: =IF(AND($B$11<=$C$3,$C$11<=$C$4,B9*$C$5),B9*$C$6) -> 191070 | G9: TARGET | H9: =B4*3 -> 6000
A10: GEFIRA | B10: =C10*5000 -> 3970000 | C10: =SUM('PERHITNGAN BONUS'!E6) -> 794 | D10: =(B10-$C$3)/$C$3+100% -> 0.28872727 | E10: =IF(AND($B$11<=$C$3,$C$11<=$C$4,B10*$C$5),B10*$C$6) -> 131010 | G10: PENCAPAIAN | H10: =C11+C17+C23 -> 3589 | I10: =H10-H9 -> -2411
A11: TOTAL | B11: =SUM(B9:B10) -> 9760000 | C11: =SUM(C9:C10) -> 1952 | D11: =SUM(D9:D10) -> 0.70981818 | E11: =IF(AND($B$11<=$C$3,$C$11<=$C$4,B11*$C$5),B11*$C$6) -> 322080 | H11: =H10*5000 -> 17945000
H12: =IF(H10<=H9,H11*$B$5,IF(H10<=H8,H11*$C$6)) -> 358900
A13: KALKULASI BONUS DENGAN KETENTUAN | B13: MEI | H13: =H12/2 -> 179450
A14: STAF NAME | B14: TOTAL PENJUALAN | C14: TARGET PRODUK | D14: % | E14: BONUS
A15: EGA | B15: ='PERHITNGAN BONUS'!C7*5000 -> 2940000 | C15: ='PERHITNGAN BONUS'!C7 -> 588 | D15: =(B15-$B$3)/$B$3+100% -> 0.42763636 | E15: =IF(B15>=$B$3,C15>=$B$4,B15*$B$5) -> 58800
A16: REINA | B16: ='PERHITNGAN BONUS'!E7*5000 -> 2245000 | C16: ='PERHITNGAN BONUS'!E7 -> 449 | D16: =(B16-$B$3)/$B$3+100% -> 0.32654545 | E16: =IF(B16>=$B$3,C16>=$B$4,B16*$B$5) -> 44900
A17: TOTAL | B17: =SUM(B15:B16) -> 5185000 | C17: =SUM(C15:C16) -> 1037 | D17: =SUM(D15:D16) -> 0.75418182 | E17: =SUM(E15:E16) -> 103700
A19: KALKULASI BONUS DENGAN KETENTUAN | B19: JUNI
A20: STAF NAME | B20: TOTAL PENJUALAN | C20: TARGET PRODUK | D20: % | E20: BONUS
A21: EGA | B21: ='PERHITNGAN BONUS'!C8*5000 -> 1710000 | C21: ='PERHITNGAN BONUS'!C8 -> 342 | D21: =(B21-$B$3)/$B$3+100% -> 0.24872727 | E21: =IF(B21>=$B$3,C21>=$B$4,B21*$B$5) -> 34200
A22: REINA | B22: ='PERHITNGAN BONUS'!E8*5000 -> 1290000 | C22: ='PERHITNGAN BONUS'!E8 -> 258 | D22: =(B22-$B$3)/$B$3+100% -> 0.18763636 | E22: =IF(B22>=$B$3,C22>=$B$4,B22*$B$5) -> 25800
A23: TOTAL | B23: =SUM(B21:B22) -> 3000000 | C23: =SUM(C21:C22) -> 600 | D23: =SUM(D21:D22) -> 0.43636364 | E23: =SUM(E21:E22) -> 60000

Sheet BONUS JULI,AUG,SEPT
A1: TUJUAN KINI HOME
A2: KRITERIA | B2: JUMLAH | C2: SELAMA 3 BULAN | F2: Basil | G2: target | H2: uptarget
A3: TARGET PENJUALAN | B3: =1494*5000 -> 7470000 | C3: =B3*3 -> 22410000 | E3: =B7 -> JULY | F3: =IF(B11<$B$3,B11*B5) -> 93100 | G3: =IF(B11=$B$3,B11*$C$5,"tidak capai target") -> tidak capai target | H3: =IF(B11>=$B$3,B11*5%,"tidak up target") -> tidak up target
A4: TARGET PCS | B4: 1494 | C4: =B4*3+1000 -> 5482 | E4: =B13 -> AUGUST | F4: =IF(B17<=$B$3,B17*$B$5,IF(B17>$B$3,B17*$C$5)) -> 68400 | G4: =IF(B17=$B$3,B12*$C$5,"tidak capai target") -> tidak capai target | H4: =IF(B17>=$B$3,B12*5%,"tidak uptarget") -> tidak uptarget
A5: BONUS | B5: 0.02 | C5: 0.03 | E5: =B19 -> SEPTEMBER | F5: =IF(B23<=$B$3,B23*$B$5,IF(B23>$B$3,B23*$C$5)) -> 53800 | G5: =IF(B23=$B$3,B13*$C$5,"tidak capai target") -> tidak capai target | H5: =IF(B23>=$B$3,B13*5%,"tidak up target") -> tidak up target
A7: KALKULASI BONUS DENGAN KETENTUAN | B7: ='PERHITNGAN BONUS'!A9 -> JULY | H7: UP TARGET | I7: =C4 -> 5482
A8: STAF NAME | B8: TOTAL PENJUALAN | C8: TARGET PRODUK | D8: % | E8: BONUS | H8: TARGET | I8: =B4*3 -> 4482
A9: EGA | B9: ='PERHITNGAN BONUS'!C9*5000 -> 2910000 | C9: ='PERHITNGAN BONUS'!C9 -> 582 | D9: =(B9-$B$3)/$B$3+100% -> 0.38955823 | E9: =IF(B9>=$B$3,C9>=$B$4,B9*$B$5) -> 58200 | H9: PENCAPAIAN | I9: =C11+C17+C23 -> 2153 | J9: =I9-I8 -> -2329
A10: REINA | B10: ='PERHITNGAN BONUS'!E9*5000 -> 1745000 | C10: ='PERHITNGAN BONUS'!E9 -> 349 | D10: =(B10-$B$3)/$B$3+100% -> 0.23360107 | E10: =IF(B10>=$B$3,C10>=$B$4,B10*$B$5) -> 34900
A11: TOTAL | B11: =SUM(B9:B10) -> 4655000 | C11: =SUM(C9:C10) -> 931 | D11: =SUM(D9:D10) -> 0.6231593 | E11: =IF(B11>=$B$3,C11>=$B$4,B11*$B$5) -> 93100 | H11: TIDAK CAPAI TARGET
A13: KALKULASI BONUS DENGAN KETENTUAN | B13: ='PERHITNGAN BONUS'!A10 -> AUGUST
A14: STAF NAME | B14: TOTAL PENJUALAN | C14: TARGET PRODUK | D14: % | E14: BONUS
A15: EGA | B15: ='PERHITNGAN BONUS'!C10*5000 -> 2420000 | C15: ='PERHITNGAN BONUS'!C10 -> 484 | D15: =(B15-$B$3)/$B$3+100% -> 0.32396252 | E15: =IF(B15>=$B$3,C15>=$B$4,B15*$B$5) -> 48400
A16: REINA | B16: ='PERHITNGAN BONUS'!E10*5000 -> 1000000 | C16: ='PERHITNGAN BONUS'!E10 -> 200 | D16: =(B16-$B$3)/$B$3+100% -> 0.13386881 | E16: =IF(B16>=$B$3,C16>=$B$4,B16*$B$5) -> 20000
A17: TOTAL | B17: =SUM(B15:B16) -> 3420000 | C17: =SUM(C15:C16) -> 684 | D17: =SUM(D15:D16) -> 0.45783133 | E17: =SUM(E15:E16) -> 68400
A19: KALKULASI BONUS DENGAN KETENTUAN | B19: ='PERHITNGAN BONUS'!A11 -> SEPTEMBER
A20: STAF NAME | B20: TOTAL PENJUALAN | C20: TARGET PRODUK | D20: % | E20: BONUS
A21: EGA | B21: ='PERHITNGAN BONUS'!C11*5000 -> 1750000 | C21: ='PERHITNGAN BONUS'!C11 -> 350 | D21: =(B21-$B$3)/$B$3+100% -> 0.23427041 | E21: =IF(B21>=$B$3,C21>=$B$4,B21*$B$5) -> 35000
A22: REINA | B22: ='PERHITNGAN BONUS'!E11*5000 -> 940000 | C22: ='PERHITNGAN BONUS'!E11 -> 188 | D22: =(B22-$B$3)/$B$3+100% -> 0.12583668 | E22: =IF(B22>=$B$3,C22>=$B$4,B22*$B$5) -> 18800
A23: TOTAL | B23: =SUM(B21:B22) -> 2690000 | C23: =SUM(C21:C22) -> 538 | D23: =SUM(D21:D22) -> 0.3601071 | E23: =SUM(E21:E22) -> 53800

Sheet BONUS OKT,NOV,DES
A1: TUJUAN KINI HOME
A2: KRITERIA | B2: JUMLAH | C2: SELAMA 3 BULAN | F2: target
A3: TARGET PENJUALAN | B3: =1494*5000 -> 7470000 | C3: =B3*3 -> 22410000 | E3: =B7 -> OCTOBER | F3: =IF(B11<=$B$3,B11*$B$5,IF(B11>$B$3,B11*$C$5)) -> 0
A4: TARGET PCS | B4: 1494 | C4: =B4*3+1000 -> 5482 | E4: =B13 -> NOVEMBER | F4: =IF(B17<=$B$3,B17*$B$5,IF(B17>$B$3,B17*$C$5)) -> 0
A5: BONUS | B5: 0.02 | C5: 0.03 | E5: =B19 -> DECEMBER | F5: =IF(B23<=$B$3,B23*$B$5,IF(B23>$B$3,B23*$C$5)) -> 0
A7: KALKULASI BONUS DENGAN KETENTUAN | B7: ='PERHITNGAN BONUS'!A12 -> OCTOBER | C7: UP TARGET JADI 3% | H7: UP TARGET | I7: =C4 -> 5482
A8: STAF NAME | B8: TOTAL PENJUALAN | C8: TARGET PRODUK | D8: % | E8: BONUS | H8: TARGET | I8: =B4*3 -> 4482
A9: EGA | B9: ='PERHITNGAN BONUS'!C12*5000 -> 0 | C9: ='PERHITNGAN BONUS'!C12 -> 0 | D9: =(B9-$B$3)/$B$3+100% -> 0 | E9: =IF(B9>=$B$3,C9>=$B$4,B9*$B$5) -> 0 | H9: PENCAPAIAN | I9: =C11+C17+C23 -> 0 | J9: =I9-I8 -> -4482
A10: REINA | B10: ='PERHITNGAN BONUS'!E12*5000 -> 0 | C10: ='PERHITNGAN BONUS'!E12 -> 0 | D10: =(B10-$B$3)/$B$3+100% -> 0 | E10: =IF(B10>=$B$3,C10>=$B$4,B10*$B$5) -> 0
A11: TOTAL | B11: =SUM(B9:B10) -> 0 | C11: =SUM(C9:C10) -> 0 | D11: =SUM(D9:D10) -> 0 | E11: =IF(B11>=$B$3,C11>=$B$4,B11*$B$5) -> 0 | H11: TIDAK CAPAI TARGET
A13: KALKULASI BONUS DENGAN KETENTUAN | B13: ='PERHITNGAN BONUS'!A13 -> NOVEMBER
A14: STAF NAME | B14: TOTAL PENJUALAN | C14: TARGET PRODUK | D14: % | E14: BONUS
A15: EGA | B15: ='PERHITNGAN BONUS'!C13*5000 -> 0 | C15: ='PERHITNGAN BONUS'!C13 -> 0 | D15: =(B15-$B$3)/$B$3+100% -> 0 | E15: =IF(B15>=$B$3,C15>=$B$4,B15*$B$5) -> 0
A16: REINA | B16: ='PERHITNGAN BONUS'!E13*5000 -> 0 | C16: ='PERHITNGAN BONUS'!E13 -> 0 | D16: =(B16-$B$3)/$B$3+100% -> 0 | E16: =IF(B16>=$B$3,C16>=$B$4,B16*$B$5) -> 0
A17: TOTAL | B17: =SUM(B15:B16) -> 0 | C17: =SUM(C15:C16) -> 0 | D17: =SUM(D15:D16) -> 0 | E17: =SUM(E15:E16) -> 0
A19: KALKULASI BONUS DENGAN KETENTUAN | B19: ='PERHITNGAN BONUS'!A14 -> DECEMBER
A20: STAF NAME | B20: TOTAL PENJUALAN | C20: TARGET PRODUK | D20: % | E20: BONUS
A21: EGA | B21: ='PERHITNGAN BONUS'!C14*5000 -> 0 | C21: ='PERHITNGAN BONUS'!C14 -> 0 | D21: =(B21-$B$3)/$B$3+100% -> 0 | E21: =IF(B21>=$B$3,C21>=$B$4,B21*$B$5) -> 0
A22: REINA | B22: ='PERHITNGAN BONUS'!E14*5000 -> 0 | C22: ='PERHITNGAN BONUS'!E14 -> 0 | D22: =(B22-$B$3)/$B$3+100% -> 0 | E22: =IF(B22>=$B$3,C22>=$B$4,B22*$B$5) -> 0
A23: TOTAL | B23: =SUM(B21:B22) -> 0 | C23: =SUM(C21:C22) -> 0 | D23: =SUM(D21:D22) -> 0 | E23: =SUM(E21:E22) -> 0

Sheet YANG INI UNTUK BONUS
A1: TUJUAN KINI HOME
A2: KRITERIA | B2: JUMLAH | C2: SELAMA 3 BULAN | F2: target
A3: TARGET PENJUALAN | B3: =1375*5000 -> 6875000 | C3: =B3*3 -> 20625000 | E3: april | F3: =IF(B11<=$B$3,B11*$B$5,IF(B11>$B$3,B11*$C$5)) -> 292800
