Workbook

Sheet DATA
A1: MAHOGANY | B1: GOTIK | C1: JIMAT/FERRY | D1: ACIL | E1: MIMIH | F1: BROKAT
A2: BURGUNDY | B2: SLAYER | C2: JIMAT/EKI | D2: KANE | E2: BI NUR | F2: TILLE
A3: DENIM | B3: KUTUBARU | C3: JIMAT/RANGGA | D3: THE YANI | F3: FUKORO
A4: COKSU | B4: JANGGAN PENDEK | C4: FERRY/RANGGA | D4: MAMAH FAHMI | F4: PURING
A5: NAVY | B5: JANGGAN PANJANG | C5: JIMAT/GILANG | D5: BU NANANG | F5: ROK BATIK
A6: HITAM | B6: ROK DUYUNG | C6: RANGGA/GILANG | D6: BU KARLAN
A7: DUSTY | B7: ROK PLISKET | D7: BU ENUNG
A8: BABYBLUE | D8: MAMAH
A9: MAROON | D9: KARLINA
A10: GOLD | D10: KIKI
A11: SAGE | D11: SITI
A12: EMERALD GREEN
A13: FUCIA
A14: SILVER
A15: EMERALD BLUE
A16: BROKEN WHITE
A17: MILO
A18: BUTTER YELLOW
A19: ROSEGOLD
A20: DUSTY HITAM

Sheet BAHAN
A1: TANGGAL | B1: TEAM CUTTING | C1: BAHAN | D1: VARIAN WARNA | E1: ROLL | F1: ROLL | G1: JUMLAH | J1: STOCK | Q1: INCOMING
B2: JIMAT/FERRY | C2: BROKAT | D2: DENIM | E2: 4 | G2: =E2+F2 -> 4
C3: BROKAT | D3: BURGUNDY | E3: 2 | G3: =E3+F3 -> 2 | J3: WARNA | K3: BROKAT | L3: TILLE | M3: FUKORO | N3: PURING | O3: ROK BATIK | S3: NO | T3: TANGGAL | U3: BAHAN | V3: WARNA | W3: ROLL
G4: =E4+F4 -> 0 | J4: MAHOGANY | K4: =-SUMIFS($G:$G,$C:$C,"BROKAT",$D:$D,"MAHOGANY")+SUMIFS($W:$W,$U:$U,"BROKAT",$V:$V,"MAHOGANY")+K35 -> 3 | L4: =-SUMIFS($G:$G,$C:$C,"TILLE",$D:$D,"MAHOGANY")+SUMIFS($W:$W,$U:$U,"TILLE",$V:$V,"MAHOGANY")+L35 -> 3 | M4: =-SUMIFS($G:$G,$C:$C,"FUKORO",$D:$D,"MAHOGANY")+SUMIFS($W:$W,$U:$U,"FUKORO",$V:$V,"MAHOGANY")+M35 -> 3 | N4: =-SUMIFS($G:$G,$C:$C,"PURING",$D:$D,"MAHOGANY")+SUMIFS($W:$W,$U:$U,"PURING",$V:$V,"MAHOGANY")+N35 -> 3 | O4: =-SUMIFS($G:$G,$C:$C,"ROK BATIK",$D:$D,"MAHOGANY")+SUMIFS($W:$W,$U:$U,"ROK BATIK",$V:$V,"MAHOGANY")+O35 -> 3 | U4: BROKAT | V4: DENIM | W4: 5
G5: =E5+F5 -> 0 | J5: BURGUNDY | K5: =-SUMIFS($G:$G,$C:$C,"BROKAT",$D:$D,"BURGUNDY")+SUMIFS($W:$W,$U:$U,"BROKAT",$V:$V,"BURGUNDY")+K36 -> 1 | L5: =-SUMIFS($G:$G,$C:$C,"TILLE",$D:$D,"BURGUNDY")+SUMIFS($W:$W,$U:$U,"TILLE",$V:$V,"BURGUNDY")+L36 -> 3 | M5: =-SUMIFS($G:$G,$C:$C,"FUKORO",$D:$D,"BURGUNDY")+SUMIFS($W:$W,$U:$U,"FUKORO",$V:$V,"BURGUNDY")+M36 -> 3 | N5: =-SUMIFS($G:$G,$C:$C,"PURING",$D:$D,"BURGUNDY")+SUMIFS($W:$W,$U:$U,"PURING",$V:$V,"BURGUNDY")+N36 -> 3 | O5: =-SUMIFS($G:$G,$C:$C,"ROK BATIK",$D:$D,"BURGUNDY")+SUMIFS($W:$W,$U:$U,"ROK BATIK",$V:$V,"BURGUNDY")+O36 -> 3
G6: =E6+F6 -> 0 | J6: DENIM | K6: =-SUMIFS($G:$G,$C:$C,"BROKAT",$D:$D,"DENIM")+SUMIFS($W:$W,$U:$U,"BROKAT",$V:$V,"DENIM")+K37 -> 4 | L6: =-SUMIFS($G:$G,$C:$C,"TILLE",$D:$D,"DENIM")+SUMIFS($W:$W,$U:$U,"TILLE",$V:$V,"DENIM")+L37 -> 3 | M6: =-SUMIFS($G:$G,$C:$C,"FUKORO",$D:$D,"DENIM")+SUMIFS($W:$W,$U:$U,"FUKORO",$V:$V,"DENIM")+M37 -> 3 | N6: =-SUMIFS($G:$G,$C:$C,"PURING",$D:$D,"DENIM")+SUMIFS($W:$W,$U:$U,"PURING",$V:$V,"DENIM")+N37 -> 3 | O6: =-SUMIFS($G:$G,$C:$C,"ROK BATIK",$D:$D,"DENIM")+SUMIFS($W:$W,$U:$U,"ROK BATIK",$V:$V,"DENIM")+O37 -> 3
G7: =E7+F7 -> 0 | J7: COKSU | K7: =-SUMIFS($G:$G,$C:$C,"BROKAT",$D:$D,"COKSU")+SUMIFS($W:$W,$U:$U,"BROKAT",$V:$V,"COKSU")+K38 -> 3 | L7: =-SUMIFS($G:$G,$C:$C,"TILLE",$D:$D,"COKSU")+SUMIFS($W:$W,$U:$U,"TILLE",$V:$V,"COKSU")+L38 -> 3 | M7: =-SUMIFS($G:$G,$C:$C,"FUKORO",$D:$D,"COKSU")+SUMIFS($W:$W,$U:$U,"FUKORO",$V:$V,"COKSU")+M38 -> 3 | N7: =-SUMIFS($G:$G,$C:$C,"PURING",$D:$D,"COKSU")+SUMIFS($W:$W,$U:$U,"PURING",$V:$V,"COKSU")+N38 -> 3 | O7: =-SUMIFS($G:$G,$C:$C,"ROK BATIK",$D:$D,"COKSU")+SUMIFS($W:$W,$U:$U,"ROK BATIK",$V:$V,"COKSU")+O38 -> 3
G8: =E8+F8 -> 0 | J8: NAVY | K8: =-SUMIFS($G:$G,$C:$C,"BROKAT",$D:$D,"NAVY")+SUMIFS($W:$W,$U:$U,"BROKAT",$V:$V,"NAVY")+K39 -> 3 | L8: =-SUMIFS($G:$G,$C:$C,"TILLE",$D:$D,"NAVY")+SUMIFS($W:$W,$U:$U,"TILLE",$V:$V,"NAVY")+L39 -> 3 | M8: =-SUMIFS($G:$G,$C:$C,"FUKORO",$D:$D,"NAVY")+SUMIFS($W:$W,$U:$U,"FUKORO",$V:$V,"NAVY")+M39 -> 3 | N8: =-SUMIFS($G:$G,$C:$C,"PURING",$D:$D,"NAVY")+SUMIFS($W:$W,$U:$U,"PURING",$V:$V,"NAVY")+N39 -> 3 | O8: =-SUMIFS($G:$G,$C:$C,"ROK BATIK",$D:$D,"NAVY")+SUMIFS($W:$W,$U:$U,"ROK BATIK",$V:$V,"NAVY")+O39 -> 3
G9: =E9+F9 -> 0 | J9: HITAM | K9: =-SUMIFS($G:$G,$C:$C,"BROKAT",$D:$D,"HITAM")+SUMIFS($W:$W,$U:$U,"BROKAT",$V:$V,"HITAM")+K40 -> 3 | L9: =-SUMIFS($G:$G,$C:$C,"TILLE",$D:$D,"HITAM")+SUMIFS($W:$W,$U:$U,"TILLE",$V:$V,"HITAM")+L40 -> 3 | M9: =-SUMIFS($G:$G,$C:$C,"FUKORO",$D:$D,"HITAM")+SUMIFS($W:$W,$U:$U,"FUKORO",$V:$V,"HITAM")+M40 -> 3 | N9: =-SUMIFS($G:$G,$C:$C,"PURING",$D:$D,"HITAM")+SUMIFS($W:$W,$U:$U,"PURING",$V:$V,"HITAM")+N40 -> 3 | O9: =-SUMIFS($G:$G,$C:$C,"ROK BATIK",$D:$D,"HITAM")+SUMIFS($W:$W,$U:$U,"ROK BATIK",$V:$V,"HITAM")+O40 -> 3
G10: =E10+F10 -> 0 | J10: DUSTY | K10: =-SUMIFS($G:$G,$C:$C,"BROKAT",$D:$D,"DUSTY")+SUMIFS($W:$W,$U:$U,"BROKAT",$V:$V,"DUSTY")+K41 -> 3 | L10: =-SUMIFS($G:$G,$C:$C,"TILLE",$D:$D,"DUSTY")+SUMIFS($W:$W,$U:$U,"TILLE",$V:$V,"DUSTY")+L41 -> 3 | M10: =-SUMIFS($G:$G,$C:$C,"FUKORO",$D:$D,"DUSTY")+SUMIFS($W:$W,$U:$U,"FUKORO",$V:$V,"DUSTY")+M41 -> 3 | N10: =-SUMIFS($G:$G,$C:$C,"PURING",$D:$D,"DUSTY")+SUMIFS($W:$W,$U:$U,"PURING",$V:$V,"DUSTY")+N41 -> 3 | O10: =-SUMIFS($G:$G,$C:$C,"ROK BATIK",$D:$D,"DUSTY")+SUMIFS($W:$W,$U:$U,"ROK BATIK",$V:$V,"DUSTY")+O41 -> 3
G11: =E11+F11 -> 0 | J11: BABYBLUE | K11: =-SUMIFS($G:$G,$C:$C,"BROKAT",$D:$D,"BABYBLUE")+SUMIFS($W:$W,$U:$U,"BROKAT",$V:$V,"BABYBLUE")+K42 -> 3 | L11: =-SUMIFS($G:$G,$C:$C,"TILLE",$D:$D,"BABYBLUE")+SUMIFS($W:$W,$U:$U,"TILLE",$V:$V,"BABYBLUE")+L42 -> 3 | M11: =-SUMIFS($G:$G,$C:$C,"FUKORO",$D:$D,"BABYBLUE")+SUMIFS($W:$W,$U:$U,"FUKORO",$V:$V,"BABYBLUE")+M42 -> 3 | N11: =-SUMIFS($G:$G,$C:$C,"PURING",$D:$D,"BABYBLUE")+SUMIFS($W:$W,$U:$U,"PURING",$V:$V,"BABYBLUE")+N42 -> 3 | O11: =-SUMIFS($G:$G,$C:$C,"ROK BATIK",$D:$D,"BABYBLUE")+SUMIFS($W:$W,$U:$U,"ROK BATIK",$V:$V,"BABYBLUE")+O42 -> 3
G12: =E12+F12 -> 0 | J12: MAROON | K12: =-SUMIFS($G:$G,$C:$C,"BROKAT",$D:$D,"MAROON")+SUMIFS($W:$W,$U:$U,"BROKAT",$V:$V,"MAROON")+K43 -> 3 | L12: =-SUMIFS($G:$G,$C:$C,"TILLE",$D:$D,"MAROON")+SUMIFS($W:$W,$U:$U,"TILLE",$V:$V,"MAROON")+L43 -> 3 | M12: =-SUMIFS($G:$G,$C:$C,"FUKORO",$D:$D,"MAROON")+SUMIFS($W:$W,$U:$U,"FUKORO",$V:$V,"MAROON")+M43 -> 3 | N12: =-SUMIFS($G:$G,$C:$C,"PURING",$D:$D,"MAROON")+SUMIFS($W:$W,$U:$U,"PURING",$V:$V,"MAROON")+N43 -> 3 | O12: =-SUMIFS($G:$G,$C:$C,"ROK BATIK",$D:$D,"MAROON")+SUMIFS($W:$W,$U:$U,"ROK BATIK",$V:$V,"MAROON")+O43 -> 3
G13: =E13+F13 -> 0 | J13: GOLD | K13: =-SUMIFS($G:$G,$C:$C,"BROKAT",$D:$D,"GOLD")+SUMIFS($W:$W,$U:$U,"BROKAT",$V:$V,"GOLD")+K44 -> 3 | L13: =-SUMIFS($G:$G,$C:$C,"TILLE",$D:$D,"GOLD")+SUMIFS($W:$W,$U:$U,"TILLE",$V:$V,"GOLD")+L44 -> 3 | M13: =-SUMIFS($G:$G,$C:$C,"FUKORO",$D:$D,"GOLD")+SUMIFS($W:$W,$U:$U,"FUKORO",$V:$V,"GOLD")+M44 -> 3 | N13: =-SUMIFS($G:$G,$C:$C,"PURING",$D:$D,"GOLD")+SUMIFS($W:$W,$U:$U,"PURING",$V:$V,"GOLD")+N44 -> 3 | O13: =-SUMIFS($G:$G,$C:$C,"ROK BATIK",$D:$D,"GOLD")+SUMIFS($W:$W,$U:$U,"ROK BATIK",$V:$V,"GOLD")+O44 -> 3
G14: =E14+F14 -> 0 | J14: SAGE | K14: =-SUMIFS($G:$G,$C:$C,"BROKAT",$D:$D,"SAGE")+SUMIFS($W:$W,$U:$U,"BROKAT",$V:$V,"SAGE")+K45 -> 3 | L14: =-SUMIFS($G:$G,$C:$C,"TILLE",$D:$D,"SAGE")+SUMIFS($W:$W,$U:$U,"TILLE",$V:$V,"SAGE")+L45 -> 3 | M14: =-SUMIFS($G:$G,$C:$C,"FUKORO",$D:$D,"SAGE")+SUMIFS($W:$W,$U:$U,"FUKORO",$V:$V,"SAGE")+M45 -> 3 | N14: =-SUMIFS($G:$G,$C:$C,"PURING",$D:$D,"SAGE")+SUMIFS($W:$W,$U:$U,"PURING",$V:$V,"SAGE")+N45 -> 3 | O14: =-SUMIFS($G:$G,$C:$C,"ROK BATIK",$D:$D,"SAGE")+SUMIFS($W:$W,$U:$U,"ROK BATIK",$V:$V,"SAGE")+O45 -> 3
G15: =E15+F15 -> 0 | J15: EMERALD GREEN | K15: =-SUMIFS($G:$G,$C:$C,"BROKAT",$D:$D,"EMERALD GREEN")+SUMIFS($W:$W,$U:$U,"BROKAT",$V:$V,"EMERALD GREEN")+K46 -> 3 | L15: =-SUMIFS($G:$G,$C:$C,"TILLE",$D:$D,"EMERALD GREEN")+SUMIFS($W:$W,$U:$U,"TILLE",$V:$V,"EMERALD GREEN")+L46 -> 3 | M15: =-SUMIFS($G:$G,$C:$C,"FUKORO",$D:$D,"EMERALD GREEN")+SUMIFS($W:$W,$U:$U,"FUKORO",$V:$V,"EMERALD GREEN")+M46 -> 3 | N15: =-SUMIFS($G:$G,$C:$C,"PURING",$D:$D,"EMERALD GREEN")+SUMIFS($W:$W,$U:$U,"PURING",$V:$V,"EMERALD GREEN")+N46 -> 3 | O15: =-SUMIFS($G:$G,$C:$C,"ROK BATIK",$D:$D,"EMERALD GREEN")+SUMIFS($W:$W,$U:$U,"ROK BATIK",$V:$V,"EMERALD GREEN")+O46 -> 3
G16: =E16+F16 -> 0 | J16: FUCIA | K16: =-SUMIFS($G:$G,$C:$C,"BROKAT",$D:$D,"FUCIA")+SUMIFS($W:$W,$U:$U,"BROKAT",$V:$V,"FUCIA")+K47 -> 3 | L16: =-SUMIFS($G:$G,$C:$C,"TILLE",$D:$D,"FUCIA")+SUMIFS($W:$W,$U:$U,"TILLE",$V:$V,"FUCIA")+L47 -> 3 | M16: =-SUMIFS($G:$G,$C:$C,"FUKORO",$D:$D,"FUCIA")+SUMIFS($W:$W,$U:$U,"FUKORO",$V:$V,"FUCIA")+M47 -> 3 | N16: =-SUMIFS($G:$G,$C:$C,"PURING",$D:$D,"FUCIA")+SUMIFS($W:$W,$U:$U,"PURING",$V:$V,"FUCIA")+N47 -> 3 | O16: =-SUMIFS($G:$G,$C:$C,"ROK BATIK",$D:$D,"FUCIA")+SUMIFS($W:$W,$U:$U,"ROK BATIK",$V:$V,"FUCIA")+O47 -> 3
G17: =E17+F17 -> 0 | J17: SILVER | K17: =-SUMIFS($G:$G,$C:$C,"BROKAT",$D:$D,"SILVER")+SUMIFS($W:$W,$U:$U,"BROKAT",$V:$V,"SILVER")+K48 -> 3 | L17: =-SUMIFS($G:$G,$C:$C,"TILLE",$D:$D,"SILVER")+SUMIFS($W:$W,$U:$U,"TILLE",$V:$V,"SILVER")+L48 -> 3 | M17: =-SUMIFS($G:$G,$C:$C,"FUKORO",$D:$D,"SILVER")+SUMIFS($W:$W,$U:$U,"FUKORO",$V:$V,"SILVER")+M48 -> 3 | N17: =-SUMIFS($G:$G,$C:$C,"PURING",$D:$D,"SILVER")+SUMIFS($W:$W,$U:$U,"PURING",$V:$V,"SILVER")+N48 -> 3 | O17: =-SUMIFS($G:$G,$C:$C,"ROK BATIK",$D:$D,"SILVER")+SUMIFS($W:$W,$U:$U,"ROK BATIK",$V:$V,"SILVER")+O48 -> 3
G18: =E18+F18 -> 0 | J18: EMERALD BLUE | K18: =-SUMIFS($G:$G,$C:$C,"BROKAT",$D:$D,"EMERALD BLUE")+SUMIFS($W:$W,$U:$U,"BROKAT",$V:$V,"EMERALD BLUE")+K49 -> 3 | L18: =-SUMIFS($G:$G,$C:$C,"TILLE",$D:$D,"EMERALD BLUE")+SUMIFS($W:$W,$U:$U,"TILLE",$V:$V,"EMERALD BLUE")+L49 -> 3 | M18: =-SUMIFS($G:$G,$C:$C,"FUKORO",$D:$D,"EMERALD BLUE")+SUMIFS($W:$W,$U:$U,"FUKORO",$V:$V,"EMERALD BLUE")+M49 -> 3 | N18: =-SUMIFS($G:$G,$C:$C,"PURING",$D:$D,"EMERALD BLUE")+SUMIFS($W:$W,$U:$U,"PURING",$V:$V,"EMERALD BLUE")+N49 -> 3 | O18: =-SUMIFS($G:$G,$C:$C,"ROK BATIK",$D:$D,"EMERALD BLUE")+SUMIFS($W:$W,$U:$U,"ROK BATIK",$V:$V,"EMERALD BLUE")+O49 -> 3
G19: =E19+F19 -> 0 | J19: BROKEN WHITE | K19: =-SUMIFS($G:$G,$C:$C,"BROKAT",$D:$D,"BROKEN WHITE")+SUMIFS($W:$W,$U:$U,"BROKAT",$V:$V,"BROKEN WHITE")+K50 -> 3 | L19: =-SUMIFS($G:$G,$C:$C,"TILLE",$D:$D,"BROKEN WHITE")+SUMIFS($W:$W,$U:$U,"TILLE",$V:$V,"BROKEN WHITE")+L50 -> 3 | M19: =-SUMIFS($G:$G,$C:$C,"FUKORO",$D:$D,"BROKEN WHITE")+SUMIFS($W:$W,$U:$U,"FUKORO",$V:$V,"BROKEN WHITE")+M50 -> 3 | N19: =-SUMIFS($G:$G,$C:$C,"PURING",$D:$D,"BROKEN WHITE")+SUMIFS($W:$W,$U:$U,"PURING",$V:$V,"BROKEN WHITE")+N50 -> 3 | O19: =-SUMIFS($G:$G,$C:$C,"ROK BATIK",$D:$D,"BROKEN WHITE")+SUMIFS($W:$W,$U:$U,"ROK BATIK",$V:$V,"BROKEN WHITE")+O50 -> 3
G20: =E20+F20 -> 0 | J20: MILO | K20: =-SUMIFS($G:$G,$C:$C,"BROKAT",$D:$D,"MILO")+SUMIFS($W:$W,$U:$U,"BROKAT",$V:$V,"MILO")+K51 -> 3 | L20: =-SUMIFS($G:$G,$C:$C,"TILLE",$D:$D,"MILO")+SUMIFS($W:$W,$U:$U,"TILLE",$V:$V,"MILO")+L51 -> 3 | M20: =-SUMIFS($G:$G,$C:$C,"FUKORO",$D:$D,"MILO")+SUMIFS($W:$W,$U:$U,"FUKORO",$V:$V,"MILO")+M51 -> 3 | N20: =-SUMIFS($G:$G,$C:$C,"PURING",$D:$D,"MILO")+SUMIFS($W:$W,$U:$U,"PURING",$V:$V,"MILO")+N51 -> 3 | O20: =-SUMIFS($G:$G,$C:$C,"ROK BATIK",$D:$D,"MILO")+SUMIFS($W:$W,$U:$U,"ROK BATIK",$V:$V,"MILO")+O51 -> 3
G21: =E21+F21 -> 0 | J21: BUTTER YELLOW | K21: =-SUMIFS($G:$G,$C:$C,"BROKAT",$D:$D,"BUTTER YELLOW")+SUMIFS($W:$W,$U:$U,"BROKAT",$V:$V,"BUTTER YELLOW")+K52 -> 3 | L21: =-SUMIFS($G:$G,$C:$C,"TILLE",$D:$D,"BUTTER YELLOW")+SUMIFS($W:$W,$U:$U,"TILLE",$V:$V,"BUTTER YELLOW")+L52 -> 3 | M21: =-SUMIFS($G:$G,$C:$C,"FUKORO",$D:$D,"BUTTER YELLOW")+SUMIFS($W:$W,$U:$U,"FUKORO",$V:$V,"BUTTER YELLOW")+M52 -> 3 | N21: =-SUMIFS($G:$G,$C:$C,"PURING",$D:$D,"BUTTER YELLOW")+SUMIFS($W:$W,$U:$U,"PURING",$V:$V,"BUTTER YELLOW")+N52 -> 3 | O21: =-SUMIFS($G:$G,$C:$C,"ROK BATIK",$D:$D,"BUTTER YELLOW")+SUMIFS($W:$W,$U:$U,"ROK BATIK",$V:$V,"BUTTER YELLOW")+O52 -> 3
G22: =E22+F22 -> 0 | J22: ROSEGOLD | K22: =-SUMIFS($G:$G,$C:$C,"BROKAT",$D:$D,"ROSEGOLD")+SUMIFS($W:$W,$U:$U,"BROKAT",$V:$V,"ROSEGOLD")+K53 -> 3 | L22: =-SUMIFS($G:$G,$C:$C,"TILLE",$D:$D,"ROSEGOLD")+SUMIFS($W:$W,$U:$U,"TILLE",$V:$V,"ROSEGOLD")+L53 -> 3 | M22: =-SUMIFS($G:$G,$C:$C,"FUKORO",$D:$D,"ROSEGOLD")+SUMIFS($W:$W,$U:$U,"FUKORO",$V:$V,"ROSEGOLD")+M53 -> 3 | N22: =-SUMIFS($G:$G,$C:$C,"PURING",$D:$D,"ROSEGOLD")+SUMIFS($W:$W,$U:$U,"PURING",$V:$V,"ROSEGOLD")+N53 -> 3 | O22: =-SUMIFS($G:$G,$C:$C,"ROK BATIK",$D:$D,"ROSEGOLD")+SUMIFS($W:$W,$U:$U,"ROK BATIK",$V:$V,"ROSEGOLD")+O53 -> 3
G23: =E23+F23 -> 0 | J23: DUSTY HITAM | K23: =-SUMIFS($G:$G,$C:$C,"BROKAT",$D:$D,"DUSTY HITAM")+SUMIFS($W:$W,$U:$U,"BROKAT",$V:$V,"DUSTY HITAM")+K54 -> 3 | L23: =-SUMIFS($G:$G,$C:$C,"TILLE",$D:$D,"DUSTY HITAM")+SUMIFS($W:$W,$U:$U,"TILLE",$V:$V,"DUSTY HITAM")+L54 -> 3 | M23: =-SUMIFS($G:$G,$C:$C,"FUKORO",$D:$D,"DUSTY HITAM")+SUMIFS($W:$W,$U:$U,"FUKORO",$V:$V,"DUSTY HITAM")+M54 -> 3 | N23: =-SUMIFS($G:$G,$C:$C,"PURING",$D:$D,"DUSTY HITAM")+SUMIFS($W:$W,$U:$U,"PURING",$V:$V,"DUSTY HITAM")+N54 -> 3 | O23: =-SUMIFS($G:$G,$C:$C,"ROK BATIK",$D:$D,"DUSTY HITAM")+SUMIFS($W:$W,$U:$U,"ROK BATIK",$V:$V,"DUSTY HITAM")+O54 -> 3
G24: =E24+F24 -> 0
G25: =E25+F25 -> 0
G26: =E26+F26 -> 0
G27: =E27+F27 -> 0
G28: =E28+F28 -> 0
G29: =E29+F29 -> 0
G30: =E30+F30 -> 0
G31: =E31+F31 -> 0 | K31: STOCK OPNAME
G32: =E32+F32 -> 0
G33: =E33+F33 -> 0
G34: =E34+F34 -> 0 | J34: WARNA | K34: BROKAT | L34: TILLE | M34: FUKORO | N34: PURING | O34: ROK BATIK
G35: =E35+F35 -> 0 | J35: MAHOGANY | K35: 3 | L35: 3 | M35: 3 | N35: 3 | O35: 3
G36: =E36+F36 -> 0 | J36: BURGUNDY | K36: 3 | L36: 3 | M36: 3 | N36: 3 | O36: 3
G37: =E37+F37 -> 0 | J37: DENIM | K37: 3 | L37: 3 | M37: 3 | N37: 3 | O37: 3
G38: =E38+F38 -> 0 | J38: COKSU | K38: 3 | L38: 3 | M38: 3 | N38: 3 | O38: 3
G39: =E39+F39 -> 0 | J39: NAVY | K39: 3 | L39: 3 | M39: 3 | N39: 3 | O39: 3
G40: =E40+F40 -> 0 | J40: HITAM | K40: 3 | L40: 3 | M40: 3 | N40: 3 | O40: 3
...

Sheet CUTTING NEW
A1: TANGGAL | B1: TEAM CUTTING | C1: MODEL | D1: VARIAN WARNA | E1: ROLL | F1: Lebih size S | G1: 4/S | H1: 6/M | I1: 8/L | J1: 10/XL | K1: 12 | L1: 14 | M1: JUMLAH
M2: =SUM(F2:L2) -> 0
M3: =SUM(F3:L3) -> 0
M4: =SUM(F4:L4) -> 0
M5: =SUM(F5:L5) -> 0
M6: =SUM(F6:L6) -> 0
M7: =SUM(F7:L7) -> 0
M8: =SUM(F8:L8) -> 0
M9: =SUM(F9:L9) -> 0
M10: =SUM(F10:L10) -> 0
M11: =SUM(F11:L11) -> 0
M12: =SUM(F12:L12) -> 0
M13: =SUM(F13:L13) -> 0
... M369: =SUM(F369:L369) -> 0

Sheet PENJAHIT
A1: TANGGAL | B1: MODEL | C1: VARIAN WARNA | D1: Lebih size S | E1: 4/S | F1: 6/M | G1: 8/L | H1: 10/XL | I1: 12 | J1: 14 | K1: JUMLAH | L1: No Surat Jalan | M1: PENJAHIT | N1: TGL SETOR | O1: -/+ | P1: TOTAL | Q1: PENYELESAIAN | R1: KANCING | S1: TGL SETOR | T1: -/+ | U1: TOTAL | V1: PENYELESAIAN | AA1: SEARCH
B2: KUTUBARU | C2: MAHOGANY | E2: 30 | F2: 30 | G2: 30 | H2: 30 | K2: =SUM(D2:J2) -> 120 | M2: ACIL | N2: 46235 | O2: 100 | P2: =O2-K2 -> -20 | Q2: BELUM SELESAI | R2: BI NUR | U2: =T2-O2 -> -100 | AA2: TANGGAL | AB2: MODEL | AC2: VARIAN WARNA | AD2: Lebih size S | AE2: 4/S | AF2: 6/M | AG2: 8/L | AH2: 10/XL | AI2: 12 | AJ2: 14 | AK2: JUMLAH | AL2: No Surat Jalan | AM2: PENJAHIT | AN2: TGL SETOR | AO2: -/+ | AP2: TOTAL | AQ2: PENYELESAIAN | AR2: KANCING | AS2: TGL SETOR | AT2: -/+ | AU2: TOTAL | AV2: PENYELESAIAN
K3: =SUM(D3:J3) -> 0 | M3: KANE | P3: =O3-K3 -> 0 | U3: =T3-O3 -> 0 | AA3: {=_xlfn._xlws.FILTER(A2:V369,ISNUMBER(SEARCH(AB1,A2:A369&B2:B369&C2:C369&D2:D369&E2:E369&F2:F369&G2:G369&H2:H369&I2:I369&J2:J369&K2:K369&L2:L369&M2:M369&N2:N369&O2:O369&P2:P369&Q2:Q369&R2:R369&S2:S369&T2:T369&U2:U369&V2:V369)),"")} -> 0 | AB3: KUTUBARU | AC3: MAHOGANY | AD3: 0 | AE3: 30 | AF3: 30 | AG3: 30 | AH3: 30 | AI3: 0 | AJ3: 0 | AK3: 120 | AL3: 0 | AM3: ACIL | AN3: 46235 | AO3: 100 | AP3: -20 | AQ3: BELUM SELESAI | AR3: BI NUR | AS3: 0 | AT3: 0 | AU3: -100 | AV3: 0
K4: =SUM(D4:J4) -> 0 | P4: =O4-K4 -> 0 | U4: =T4-O4 -> 0 | AA4: 0 | AB4: 0 | AC4: 0 | AD4: 0 | AE4: 0 | AF4: 0 | AG4: 0 | AH4: 0 | AI4: 0 | AJ4: 0 | AK4: 0 | AL4: 0 | AM4: KANE | AN4: 0 | AO4: 0 | AP4: 0 | AQ4: 0 | AR4: 0 | AS4: 0 | AT4: 0 | AU4: 0 | AV4: 0
K5: =SUM(D5:J5) -> 0 | P5: =O5-K5 -> 0 | U5: =T5-O5 -> 0 | AA5: 0 | AB5: 0 | AC5: 0 | AD5: 0 | AE5: 0 | AF5: 0 | AG5: 0 | AH5: 0 | AI5: 0 | AJ5: 0 | AK5: 0 | AL5: 0 | AM5: 0 | AN5: 0 | AO5: 0 | AP5: 0 | AQ5: 0 | AR5: 0 | AS5: 0 | AT5: 0 | AU5: 0 | AV5: 0
K6: =SUM(D6:J6) -> 0 | P6: =O6-K6 -> 0 | U6: =T6-O6 -> 0 | AA6: 0 | AB6: 0 | AC6: 0 | AD6: 0 | AE6: 0 | AF6: 0 | AG6: 0 | AH6: 0 | AI6: 0 | AJ6: 0 | AK6: 0 | AL6: 0 | AM6: 0 | AN6: 0 | AO6: 0 | AP6: 0 | AQ6: 0 | AR6: 0 | AS6: 0 | AT6: 0 | AU6: 0 | AV6: 0
K7: =SUM(D7:J7) -> 0 | P7: =O7-K7 -> 0 | U7: =T7-O7 -> 0 | AA7: 0 | AB7: 0 | AC7: 0 | AD7: 0 | AE7: 0 | AF7: 0 | AG7: 0 | AH7: 0 | AI7: 0 | AJ7: 0 | AK7: 0 | AL7: 0 | AM7: 0 | AN7: 0 | AO7: 0 | AP7: 0 | AQ7: 0 | AR7: 0 | AS7: 0 | AT7: 0 | AU7: 0 | AV7: 0
K8: =SUM(D8:J8) -> 0 | P8: =O8-K8 -> 0 | U8: =T8-O8 -> 0 | AA8: 0 | AB8: 0 | AC8: 0 | AD8: 0 | AE8: 0 | AF8: 0 | AG8: 0 | AH8: 0 | AI8: 0 | AJ8: 0 | AK8: 0 | AL8: 0 | AM8: 0 | AN8: 0 | AO8: 0 | AP8: 0 | AQ8: 0 | AR8: 0 | AS8: 0 | AT8: 0 | AU8: 0 | AV8: 0
K9: =SUM(D9:J9) -> 0 | P9: =O9-K9 -> 0 | U9: =T9-O9 -> 0 | AA9: 0 | AB9: 0 | AC9: 0 | AD9: 0 | AE9: 0 | AF9: 0 | AG9: 0 | AH9: 0 | AI9: 0 | AJ9: 0 | AK9: 0 | AL9: 0 | AM9: 0 | AN9: 0 | AO9: 0 | AP9: 0 | AQ9: 0 | AR9: 0 | AS9: 0 | AT9: 0 | AU9: 0 | AV9: 0
K10: =SUM(D10:J10) -> 0 | P10: =O10-K10 -> 0 | U10: =T10-O10 -> 0 | AA10: 0 | AB10: 0 | AC10: 0 | AD10: 0 | AE10: 0 | AF10: 0 | AG10: 0 | AH10: 0 | AI10: 0 | AJ10: 0 | AK10: 0 | AL10: 0 | AM10: 0 | AN10: 0 | AO10: 0 | AP10: 0 | AQ10: 0 | AR10: 0 | AS10: 0 | AT10: 0 | AU10: 0 | AV10: 0
K11: =SUM(D11:J11) -> 0 | P11: =O11-K11 -> 0 | U11: =T11-O11 -> 0 | AA11: 0 | AB11: 0 | AC11: 0 | AD11: 0 | AE11: 0 | AF11: 0 | AG11: 0 | AH11: 0 | AI11: 0 | AJ11: 0 | AK11: 0 | AL11: 0 | AM11: 0 | AN11: 0 | AO11: 0 | AP11: 0 | AQ11: 0 | AR11: 0 | AS11: 0 | AT11: 0 | AU11: 0 | AV11: 0
K12: =SUM(D12:J12) -> 0 | P12: =O12-K12 -> 0 | U12: =T12-O12 -> 0 | AA12: 0 | AB12: 0 | AC12: 0 | AD12: 0 | AE12: 0 | AF12: 0 | AG12: 0 | AH12: 0 | AI12: 0 | AJ12: 0 | AK12: 0 | AL12: 0 | AM12: 0 | AN12: 0 | AO12: 0 | AP12: 0 | AQ12: 0 | AR12: 0 | AS12: 0 | AT12: 0 | AU12: 0 | AV12: 0
K13: =SUM(D13:J13) -> 0 | P13: =O13-K13 -> 0 | U13: =T13-O13 -> 0 | AA13: 0 | AB13: 0 | AC13: 0 | AD13: 0 | AE13: 0 | AF13: 0 | AG13: 0 | AH13: 0 | AI13: 0 | AJ13: 0 | AK13: 0 | AL13: 0 | AM13: 0 | AN13: 0 | AO13: 0 | AP13: 0 | AQ13: 0 | AR13: 0 | AS13: 0 | AT13: 0 | AU13: 0 | AV13: 0
K14: =SUM(D14:J14) -> 0 | P14: =O14-K14 -> 0 | U14: =T14-O14 -> 0 | AA14: 0 | AB14: 0 | AC14: 0 | AD14: 0 | AE14: 0 | AF14: 0 | AG14: 0 | AH14: 0 | AI14: 0 | AJ14: 0 | AK14: 0 | AL14: 0 | AM14: 0 | AN14: 0 | AO14: 0 | AP14: 0 | AQ14: 0 | AR14: 0 | AS14: 0 | AT14: 0 | AU14: 0 | AV14: 0
K15: =SUM(D15:J15) -> 0 | P15: =O15-K15 -> 0 | U15: =T15-O15 -> 0 | AA15: 0 | AB15: 0 | AC15: 0 | AD15: 0 | AE15: 0 | AF15: 0 | AG15: 0 | AH15: 0 | AI15: 0 | AJ15: 0 | AK15: 0 | AL15: 0 | AM15: 0 | AN15: 0 | AO15: 0 | AP15: 0 | AQ15: 0 | AR15: 0 | AS15: 0 | AT15: 0 | AU15: 0 | AV15: 0
K16: =SUM(D16:J16) -> 0 | P16: =O16-K16 -> 0 | U16: =T16-O16 -> 0 | AA16: 0 | AB16: 0 | AC16: 0 | AD16: 0 | AE16: 0 | AF16: 0 | AG16: 0 | AH16: 0 | AI16: 0 | AJ16: 0 | AK16: 0 | AL16: 0 | AM16: 0 | AN16: 0 | AO16: 0 | AP16: 0 | AQ16: 0 | AR16: 0 | AS16: 0 | AT16: 0 | AU16: 0 | AV16: 0
... K19: =SUM(D19:J19) -> 0 | P19: =O19-K19 -> 0 | U19: =T19-O19 -> 0 | AA19: 0 | AB19: 0 | AC19: 0 | AD19: 0 | AE19: 0 | AF19: 0 | AG19: 0 | AH19: 0 | AI19: 0 | AJ19: 0 | AK19: 0 | AL19: 0 | AM19: 0 | AN19: 0 | AO19: 0 | AP19: 0 | AQ19: 0 | AR19: 0 | AS19: 0 | AT19: 0 | AU19: 0 | AV19: 0
K20: =SUM(D369:J369) -> 0 | P20: =O369-K369 -> 0 | U20: =T369-O369 -> 0 | AA20: 0 | AB20: 0 | AC20: 0 | AD20: 0 | AE20: 0 | AF20: 0 | AG20: 0 | AH20: 0 | AI20: 0 | AJ20: 0 | AK20: 0 | AL20: 0 | AM20: 0 | AN20: 0 | AO20: 0 | AP20: 0 | AQ20: 0 | AR20: 0 | AS20: 0 | AT20: 0 | AU20: 0 | AV20: 0
K21: =SUM(D21:J21) -> 0 | P21: =O21-K21 -> 0 | U21: =T21-O21 -> 0 | AA21: 0 | AB21: 0 | AC21: 0 | AD21: 0 | AE21: 0 | AF21: 0 | AG21: 0 | AH21: 0 | AI21: 0 | AJ21: 0 | AK21: 0 | AL21: 0 | AM21: 0 | AN21: 0 | AO21: 0 | AP21: 0 | AQ21: 0 | AR21: 0 | AS21: 0 | AT21: 0 | AU21: 0 | AV21: 0
K22: =SUM(D22:J22) -> 0 | P22: =O22-K22 -> 0 | U22: =T22-O22 -> 0 | AA22: 0 | AB22: 0 | AC22: 0 | AD22: 0 | AE22: 0 | AF22: 0 | AG22: 0 | AH22: 0 | AI22: 0 | AJ22: 0 | AK22: 0 | AL22: 0 | AM22: 0 | AN22: 0 | AO22: 0 | AP22: 0 | AQ22: 0 | AR22: 0 | AS22: 0 | AT22: 0 | AU22: 0 | AV22: 0
K23: =SUM(D23:J23) -> 0 | P23: =O23-K23 -> 0 | U23: =T23-O23 -> 0 | AA23: 0 | AB23: 0 | AC23: 0 | AD23: 0 | AE23: 0 | AF23: 0 | AG23: 0 | AH23: 0 | AI23: 0 | AJ23: 0 | AK23: 0 | AL23: 0 | AM23: 0 | AN23: 0 | AO23: 0 | AP23: 0 | AQ23: 0 | AR23: 0 | AS23: 0 | AT23: 0 | AU23: 0 | AV23: 0
K24: =SUM(D24:J24) -> 0 | P24: =O24-K24 -> 0 | U24: =T24-O24 -> 0 | AA24: 0 | AB24: 0 | AC24: 0 | AD24: 0 | AE24: 0 | AF24: 0 | AG24: 0 | AH24: 0 | AI24: 0 | AJ24: 0 | AK24: 0 | AL24: 0 | AM24: 0 | AN24: 0 | AO24: 0 | AP24: 0 | AQ24: 0 | AR24: 0 | AS24: 0 | AT24: 0 | AU24: 0 | AV24: 0
K25: =SUM(D25:J25) -> 0 | P25: =O25-K25 -> 0 | U25: =T25-O25 -> 0 | AA25: 0 | AB25: 0 | AC25: 0 | AD25: 0 | AE25: 0 | AF25: 0 | AG25: 0 | AH25: 0 | AI25: 0 | AJ25: 0 | AK25: 0 | AL25: 0 | AM25: 0 | AN25: 0 | AO25: 0 | AP25: 0 | AQ25: 0 | AR25: 0 | AS25: 0 | AT25: 0 | AU25: 0 | AV25: 0
K26: =SUM(D26:J26) -> 0 | P26: =O26-K26 -> 0 | U26: =T26-O26 -> 0 | AA26: 0 | AB26: 0 | AC26: 0 | AD26: 0 | AE26: 0 | AF26: 0 | AG26: 0 | AH26: 0 | AI26: 0 | AJ26: 0 | AK26: 0 | AL26: 0 | AM26: 0 | AN26: 0 | AO26: 0 | AP26: 0 | AQ26: 0 | AR26: 0 | AS26: 0 | AT26: 0 | AU26: 0 | AV26: 0
K27: =SUM(D27:J27) -> 0 | P27: =O27-K27 -> 0 | U27: =T27-O27 -> 0 | AA27: 0 | AB27: 0 | AC27: 0 | AD27: 0 | AE27: 0 | AF27: 0 | AG27: 0 | AH27: 0 | AI27: 0 | AJ27: 0 | AK27: 0 | AL27: 0 | AM27: 0 | AN27: 0 | AO27: 0 | AP27: 0 | AQ27: 0 | AR27: 0 | AS27: 0 | AT27: 0 | AU27: 0 | AV27: 0
K28: =SUM(D28:J28) -> 0 | P28: =O28-K28 -> 0 | U28: =T28-O28 -> 0 | AA28: 0 | AB28: 0 | AC28: 0 | AD28: 0 | AE28: 0 | AF28: 0 | AG28: 0 | AH28: 0 | AI28: 0 | AJ28: 0 | AK28: 0 | AL28: 0 | AM28: 0 | AN28: 0 | AO28: 0 | AP28: 0 | AQ28: 0 | AR28: 0 | AS28: 0 | AT28: 0 | AU28: 0 | AV28: 0
K29: =SUM(D29:J29) -> 0 | P29: =O29-K29 -> 0 | U29: =T29-O29 -> 0 | AA29: 0 | AB29: 0 | AC29: 0 | AD29: 0 | AE29: 0 | AF29: 0 | AG29: 0 | AH29: 0 | AI29: 0 | AJ29: 0 | AK29: 0 | AL29: 0 | AM29: 0 | AN29: 0 | AO29: 0 | AP29: 0 | AQ29: 0 | AR29: 0 | AS29: 0 | AT29: 0 | AU29: 0 | AV29: 0
K30: =SUM(D30:J30) -> 0 | P30: =O30-K30 -> 0 | U30: =T30-O30 -> 0 | AA30: 0 | AB30: 0 | AC30: 0 | AD30: 0 | AE30: 0 | AF30: 0 | AG30: 0 | AH30: 0 | AI30: 0 | AJ30: 0 | AK30: 0 | AL30: 0 | AM30: 0 | AN30: 0 | AO30: 0 | AP30: 0 | AQ30: 0 | AR30: 0 | AS30: 0 | AT30: 0 | AU30: 0 | AV30: 0
K31: =SUM(D31:J31) -> 0 | P31: =O31-K31 -> 0 | U31: =T31-O31 -> 0 | AA31: 0 | AB31: 0 | AC31: 0 | AD31: 0 | AE31: 0 | AF31: 0 | AG31: 0 | AH31: 0 | AI31: 0 | AJ31: 0 | AK31: 0 | AL31: 0 | AM31: 0 | AN31: 0 | AO31: 0 | AP31: 0 | AQ31: 0 | AR31: 0 | AS31: 0 | AT31: 0 | AU31: 0 | AV31: 0
K32: =SUM(D32:J32) -> 0 | P32: =O32-K32 -> 0 | U32: =T32-O32 -> 0 | AA32: 0 | AB32: 0 | AC32: 0 | AD32: 0 | AE32: 0 | AF32: 0 | AG32: 0 | AH32: 0 | AI32: 0 | AJ32: 0 | AK32: 0 | AL32: 0 | AM32: 0 | AN32: 0 | AO32: 0 | AP32: 0 | AQ32: 0 | AR32: 0 | AS32: 0 | AT32: 0 | AU32: 0 | AV32: 0
... K119: =SUM(D119:J119) -> 0 | P119: =O119-K119 -> 0 | U119: =T119-O119 -> 0 | AA119: 0 | AB119: 0 | AC119: 0 | AD119: 0 | AE119: 0 | AF119: 0 | AG119: 0 | AH119: 0 | AI119: 0 | AJ119: 0 | AK119: 0 | AL119: 0 | AM119: 0 | AN119: 0 | AO119: 0 | AP119: 0 | AQ119: 0 | AR119: 0 | AS119: 0 | AT119: 0 | AU119: 0 | AV119: 0
K120: =SUM(D1369:J1369) -> 0 | P120: =O1369-K1369 -> 0 | U120: =T1369-O1369 -> 0 | AA120: 0 | AB120: 0 | AC120: 0 | AD120: 0 | AE120: 0 | AF120: 0 | AG120: 0 | AH120: 0 | AI120: 0 | AJ120: 0 | AK120: 0 | AL120: 0 | AM120: 0 | AN120: 0 | AO120: 0 | AP120: 0 | AQ120: 0 | AR120: 0 | AS120: 0 | AT120: 0 | AU120: 0 | AV120: 0
K121: =SUM(D121:J121) -> 0 | P121: =O121-K121 -> 0 | U121: =T121-O121 -> 0 | AA121: 0 | AB121: 0 | AC121: 0 | AD121: 0 | AE121: 0 | AF121: 0 | AG121: 0 | AH121: 0 | AI121: 0 | AJ121: 0 | AK121: 0 | AL121: 0 | AM121: 0 | AN121: 0 | AO121: 0 | AP121: 0 | AQ121: 0 | AR121: 0 | AS121: 0 | AT121: 0 | AU121: 0 | AV121: 0
K122: =SUM(D122:J122) -> 0 | P122: =O122-K122 -> 0 | U122: =T122-O122 -> 0 | AA122: 0 | AB122: 0 | AC122: 0 | AD122: 0 | AE122: 0 | AF122: 0 | AG122: 0 | AH122: 0 | AI122: 0 | AJ122: 0 | AK122: 0 | AL122: 0 | AM122: 0 | AN122: 0 | AO122: 0 | AP122: 0 | AQ122: 0 | AR122: 0 | AS122: 0 | AT122: 0 | AU122: 0 | AV122: 0
K123: =SUM(D123:J123) -> 0 | P123: =O123-K123 -> 0 | U123: =T123-O123 -> 0 | AA123: 0 | AB123: 0 | AC123: 0 | AD123: 0 | AE123: 0 | AF123: 0 | AG123: 0 | AH123: 0 | AI123: 0 | AJ123: 0 | AK123: 0 | AL123: 0 | AM123: 0 | AN123: 0 | AO123: 0 | AP123: 0 | AQ123: 0 | AR123: 0 | AS123: 0 | AT123: 0 | AU123: 0 | AV123: 0
K124: =SUM(D124:J124) -> 0 | P124: =O124-K124 -> 0 | U124: =T124-O124 -> 0 | AA124: 0 | AB124: 0 | AC124: 0 | AD124: 0 | AE124: 0 | AF124: 0 | AG124: 0 | AH124: 0 | AI124: 0 | AJ124: 0 | AK124: 0 | AL124: 0 | AM124: 0 | AN124: 0 | AO124: 0 | AP124: 0 | AQ124: 0 | AR124: 0 | AS124: 0 | AT124: 0 | AU124: 0 | AV124: 0
K125: =SUM(D125:J125) -> 0 | P125: =O125-K125 -> 0 | U125: =T125-O125 -> 0 | AA125: 0 | AB125: 0 | AC125: 0 | AD125: 0 | AE125: 0 | AF125: 0 | AG125: 0 | AH125: 0 | AI125: 0 | AJ125: 0 | AK125: 0 | AL125: 0 | AM125: 0 | AN125: 0 | AO125: 0 | AP125: 0 | AQ125: 0 | AR125: 0 | AS125: 0 | AT125: 0 | AU125: 0 | AV125: 0
K126: =SUM(D126:J126) -> 0 | P126: =O126-K126 -> 0 | U126: =T126-O126 -> 0 | AA126: 0 | AB126: 0 | AC126: 0 | AD126: 0 | AE126: 0 | AF126: 0 | AG126: 0 | AH126: 0 | AI126: 0 | AJ126: 0 | AK126: 0 | AL126: 0 | AM126: 0 | AN126: 0 | AO126: 0 | AP126: 0 | AQ126: 0 | AR126: 0 | AS126: 0 | AT126: 0 | AU126: 0 | AV126: 0
K127: =SUM(D127:J127) -> 0 | P127: =O127-K127 -> 0 | U127: =T127-O127 -> 0 | AA127: 0 | AB127: 0 | AC127: 0 | AD127: 0 | AE127: 0 | AF127: 0 | AG127: 0 | AH127: 0 | AI127: 0 | AJ127: 0 | AK127: 0 | AL127: 0 | AM127: 0 | AN127: 0 | AO127: 0 | AP127: 0 | AQ127: 0 | AR127: 0 | AS127: 0 | AT127: 0 | AU127: 0 | AV127: 0
K128: =SUM(D128:J128) -> 0 | P128: =O128-K128 -> 0 | U128: =T128-O128 -> 0 | AA128: 0 | AB128: 0 | AC128: 0 | AD128: 0 | AE128: 0 | AF128: 0 | AG128: 0 | AH128: 0 | AI128: 0 | AJ128: 0 | AK128: 0 | AL128: 0 | AM128: 0 | AN128: 0 | AO128: 0 | AP128: 0 | AQ128: 0 | AR128: 0 | AS128: 0 | AT128: 0 | AU128: 0 | AV128: 0
...

Sheet CUTTING
A1: TANGGAL | B1: TEAM CUTTING | C1: MODEL | D1: VARIAN WARNA | E1: ROLL | F1: Lebih size S | G1: 4/S | H1: 6/M | I1: 8/L | J1: 10/XL | K1: 12 | L1: 14 | M1: JUMLAH | N1: No Surat Jalan | O1: PENJAHIT | P1: TGL SETOR | Q1: -/+ | R1: TOTAL | S1: PENYELESAIAN | T1: KANCING | U1: TGL SETOR | V1: -/+ | W1: TOTAL | X1: PENYELESAIAN
L2: 20 | M2: =SUM(F2:L2) -> 20 | Q2: 18 | R2: =Q2-M2 -> -2 | V2: 18 | W2: =V2-Q2 -> 0
M3: =SUM(F3:L3) -> 0 | R3: =Q3-M3 -> 0 | W3: =V3-Q3 -> 0
M4: =SUM(F4:L4) -> 0 | R4: =Q4-M4 -> 0 | W4: =V4-Q4 -> 0
M5: =SUM(F5:L5) -> 0 | R5: =Q5-M5 -> 0 | W5: =V5-Q5 -> 0
M6: =SUM(F6:L6) -> 0 | R6: =Q6-M6 -> 0 | W6: =V6-Q6 -> 0
M7: =SUM(F7:L7) -> 0 | R7: =Q7-M7 -> 0 | W7: =V7-Q7 -> 0
M8: =SUM(F8:L8) -> 0 | R8: =Q8-M8 -> 0 | W8: =V8-Q8 -> 0
M9: =SUM(F9:L9) -> 0 | R9: =Q9-M9 -> 0 | W9: =V9-Q9 -> 0
M10: =SUM(F10:L10) -> 0 | R10: =Q10-M10 -> 0 | W10: =V10-Q10 -> 0
M11: =SUM(F11:L11) -> 0 | R11: =Q11-M11 -> 0 | W11: =V11-Q11 -> 0
M12: =SUM(F12:L12) -> 0 | R12: =Q12-M12 -> 0 | W12: =V12-Q12 -> 0
M13: =SUM(F13:L13) -> 0 | R13: =Q13-M13 -> 0 | W13: =V13-Q13 -> 0
M14: =SUM(F14:L14) -> 0 | R14: =Q14-M14 -> 0 | W14: =V14-Q14 -> 0
... M369: =SUM(F369:L369) -> 0 | R369: =Q369-M369 -> 0 | W369: =V369-Q369 -> 0

Sheet SO
A1: KUTUBARU | F1: TOTAL | I1: GOTIK | P1: TOTAL
A2: WARNA | B2: S | C2: M | D2: L | E2: XL | I2: WARNA | J2: 4 | K2: 6 | L2: 8 | M2: 10 | N2: 12 | O2: 14
A3: MAHOGANY | F3: =SUM(B3:E3) -> 0 | I3: MAHOGANY | P3: =SUM(K3:M3) -> 0
A4: BURGUNDY | F4: =SUM(B4:E4) -> 0 | I4: BERGUNDI | P4: =SUM(K4:M4) -> 0
A5: DENIM | F5: =SUM(B5:E5) -> 0 | I5: DENIM | P5: =SUM(K5:M5) -> 0
A6: COKSU | F6: =SUM(B6:E6) -> 0 | I6: COKSU | P6: =SUM(K6:M6) -> 0
A7: NAVY | F7: =SUM(B7:E7) -> 0 | I7: NAVY | P7: =SUM(K7:M7) -> 0
A8: HITAM | F8: =SUM(B8:E8) -> 0 | I8: HITAM | P8: =SUM(K8:M8) -> 0
A9: DUSTY | F9: =SUM(B9:E9) -> 0 | I9: DUSTY | P9: =SUM(K9:M9) -> 0
A10: BABYBLUE | F10: =SUM(B10:E10) -> 0 | I10: BABYBLUE | P10: =SUM(K10:M10) -> 0
A11: MAROON | F11: =SUM(B11:E11) -> 0 | I11: MARON | P11: =SUM(K11:M11) -> 0
A12: GOLD | F12: =SUM(B12:E12) -> 0 | I12: GOLD | P12: =SUM(K12:M12) -> 0
A13: SAGE | F13: =SUM(B13:E13) -> 0 | I13: SAGE | P13: =SUM(K13:M13) -> 0
A14: EMERALD GREEN | F14: =SUM(B14:E14) -> 0 | I14: EMERALD BLUE | P14: =SUM(K14:M14) -> 0
... A16: SILVER | F16: =SUM(B16:E16) -> 0 | I16: BUTTER YELLOW | P16: =SUM(K16:M16) -> 0
A17: BUTTER YELLOW | F17: =SUM(B17:E17) -> 0 | P17: =SUM(K17:M17) -> 0
F18: =SUM(B18:E18) -> 0 | P18: =SUM(K18:M18) -> 0
F19: =SUM(B19:E19) -> 0 | P19: =SUM(K19:M19) -> 0
E20: JUMLAH | F20: =SUBTOTAL(9,F3:F19) -> 0 | O20: JUMLAH | P20: =SUBTOTAL(9,P3:P19) -> 0
I23: SLAYER | P23: TOTAL
I24: WARNA | J24: 4 | K24: 6 | L24: 8 | M24: 10 | N24: 12 | O24: 14
A25: JANGGAN PENDEK | F25: TOTAL | I25: MAHOGANY | P25: =SUM(K25:M25) -> 0
A26: WARNA | B26: S | C26: M | D26: L | I26: BURGUNDY | P26: =SUM(K26:M26) -> 0
A27: MAHOGANY | F27: =SUM(B27:E27) -> 0 | I27: DENIM | P27: =SUM(K27:M27) -> 0
A28: BURGUNDY | F28: =SUM(B28:E28) -> 0 | I28: NAVY | P28: =SUM(K28:M28) -> 0
A29: BABYBLUE | F29: =SUM(B29:E29) -> 0 | I29: HITAM | P29: =SUM(K29:M29) -> 0
A30: COKSU | F30: =SUM(B30:E30) -> 0 | I30: DUSTY | P30: =SUM(K30:M30) -> 0
A31: NAVY | F31: =SUM(B31:E31) -> 0 | I31: BABYBLUE | P31: =SUM(K31:M31) -> 0
A32: HITAM | F32: =SUM(B32:E32) -> 0 | I32: MARON | P32: =SUM(K32:M32) -> 0
A33: DUSTY | F33: =SUM(B33:E33) -> 0 | I33: ROSEGOLD | P33: =SUM(K33:M33) -> 0
A34: ROSEGOLD | F34: =SUM(B34:E34) -> 0 | I34: SAGE | P34: =SUM(K34:M34) -> 0
A35: SAGE | F35: =SUM(B35:E35) -> 0 | I35: EMERALD GREEN | P35: =SUM(K35:M35) -> 0
A36: EMERALD GREEN | F36: =SUM(B36:E36) -> 0 | I36: SILVER | P36: =SUM(K36:M36) -> 0
A37: MILO | F37: =SUM(B37:E37) -> 0 | P37: =SUM(K37:M37) -> 0
A38: BROKEN WHITE | F38: =SUM(B38:E38) -> 0 | P38: =SUM(K38:M38) -> 0
A39: BUTTER YELLOW | F39: =SUM(B39:E39) -> 0 | P39: =SUM(K39:M39) -> 0
A40: EMERALD BLUE | F40: =SUM(B40:E40) -> 0 | P40: =SUM(K40:M40) -> 0
F41: =SUM(B41:E41) -> 0 | P41: =SUM(K41:M41) -> 0
F42: =SUM(B42:E42) -> 0 | O42: JUMLAH | P42: =SUBTOTAL(9,P25:P41) -> 0
F43: =SUM(B43:E43) -> 0
...

Sheet STOK
A1: KUTUBARU | F1: TOTAL | I1: GOTIK | P1: TOTAL
A2: WARNA | B2: S | C2: M | D2: L | E2: XL | I2: WARNA | J2: 4 | K2: 6 | L2: 8 | M2: 10 | N2: 12 | O2: 14
A3: MAHOGANY | B3: =-SUMIFS(KELUAR!$E:$E,KELUAR!$B:$B,"KUTUBARU",KELUAR!$C:$C,"MAHOGANY",KELUAR!$D:$D,"S")+SUMIFS(MASUK!$E:$E,MASUK!$B:$B,"KUTUBARU",MASUK!$C:$C,"MAHOGANY",MASUK!$D:$D,"S")+SO!B3 -> 0 | C3: =-SUMIFS(KELUAR!$E:$E,KELUAR!$B:$B,"KUTUBARU",KELUAR!$C:$C,"MAHOGANY",KELUAR!$D:$D,"M")+SUMIFS(MASUK!$E:$E,MASUK!$B:$B,"KUTUBARU",MASUK!$C:$C,"MAHOGANY",MASUK!$D:$D,"M")+SO!C3 -> 0 | D3: =-SUMIFS(KELUAR!$E:$E,KELUAR!$B:$B,"KUTUBARU",KELUAR!$C:$C,"MAHOGANY",KELUAR!$D:$D,"L")+SUMIFS(MASUK!$E:$E,MASUK!$B:$B,"KUTUBARU",MASUK!$C:$C,"MAHOGANY",MASUK!$D:$D,"L")+SO!D3 -> 0 | E3: =-SUMIFS(KELUAR!$E:$E,KELUAR!$B:$B,"KUTUBARU",KELUAR!$C:$C,"MAHOGANY",KELUAR!$D:$D,"XL")+SUMIFS(MASUK!$E:$E,MASUK!$B:$B,"KUTUBARU",MASUK!$C:$C,"MAHOGANY",MASUK!$D:$D,"XL")+SO!E3 -> 0 | F3: =SUM(B3:E3) -> 0 | I3: MAHOGANY | J3: =-SUMIFS(KELUAR!$E:$E,KELUAR!$B:$B,"GOTIK",KELUAR!$C:$C,"MAHOGANY",KELUAR!$D:$D,"4")+SUMIFS(MASUK!$E:$E,MASUK!$B:$B,"GOTIK",MASUK!$C:$C,"MAHOGANY",MASUK!$D:$D,"4")+SO!J3 -> 0 | K3: =-SUMIFS(KELUAR!$E:$E,KELUAR!$B:$B,"GOTIK",KELUAR!$C:$C,"MAHOGANY",KELUAR!$D:$D,"6")+SUMIFS(MASUK!$E:$E,MASUK!$B:$B,"GOTIK",MASUK!$C:$C,"MAHOGANY",MASUK!$D:$D,"6")+SO!K3 -> 0 | L3: =-SUMIFS(KELUAR!$E:$E,KELUAR!$B:$B,"GOTIK",KELUAR!$C:$C,"MAHOGANY",KELUAR!$D:$D,"8")+SUMIFS(MASUK!$E:$E,MASUK!$B:$B,"GOTIK",MASUK!$C:$C,"MAHOGANY",MASUK!$D:$D,"8")+SO!L3 -> 0 | M3: =-SUMIFS(KELUAR!$E:$E,KELUAR!$B:$B,"GOTIK",KELUAR!$C:$C,"MAHOGANY",KELUAR!$D:$D,"10")+SUMIFS(MASUK!$E:$E,MASUK!$B:$B,"GOTIK",MASUK!$C:$C,"MAHOGANY",MASUK!$D:$D,"10")+SO!M3 -> 0 | N3: =-SUMIFS(KELUAR!$E:$E,KELUAR!$B:$B,"GOTIK",KELUAR!$C:$C,"MAHOGANY",KELUAR!$D:$D,"12")+SUMIFS(MASUK!$E:$E,MASUK!$B:$B,"GOTIK",MASUK!$C:$C,"MAHOGANY",MASUK!$D:$D,"12")+SO!N3 -> 0 | O3: =-SUMIFS(KELUAR!$E:$E,KELUAR!$B:$B,"GOTIK",KELUAR!$C:$C,"MAHOGANY",KELUAR!$D:$D,"14")+SUMIFS(MASUK!$E:$E,MASUK!$B:$B,"GOTIK",MASUK!$C:$C,"MAHOGANY",MASUK!$D:$D,"14")+SO!O3 -> 0 | P3: =SUM(J3:O3) -> 0
A4: BURGUNDY | B4: =-SUMIFS(KELUAR!$E:$E,KELUAR!$B:$B,"KUTUBARU",KELUAR!$C:$C,"BURGUNDY",KELUAR!$D:$D,"S")+SUMIFS(MASUK!$E:$E,MASUK!$B:$B,"KUTUBARU",MASUK!$C:$C,"BURGUNDY",MASUK!$D:$D,"S")+SO!B4 -> 0 | C4: =-SUMIFS(KELUAR!$E:$E,KELUAR!$B:$B,"KUTUBARU",KELUAR!$C:$C,"BURGUNDY",KELUAR!$D:$D,"M")+SUMIFS(MASUK!$E:$E,MASUK!$B:$B,"KUTUBARU",MASUK!$C:$C,"BURGUNDY",MASUK!$D:$D,"M")+SO!C4 -> 0 | D4: =-SUMIFS(KELUAR!$E:$E,KELUAR!$B:$B,"KUTUBARU",KELUAR!$C:$C,"BURGUNDY",KELUAR!$D:$D,"L")+SUMIFS(MASUK!$E:$E,MASUK!$B:$B,"KUTUBARU",MASUK!$C:$C,"BURGUNDY",MASUK!$D:$D,"L")+SO!D4 -> 0 | E4: =-SUMIFS(KELUAR!$E:$E,KELUAR!$B:$B,"KUTUBARU",KELUAR!$C:$C,"BURGUNDY",KELUAR!$D:$D,"XL")+SUMIFS(MASUK!$E:$E,MASUK!$B:$B,"KUTUBARU",MASUK!$C:$C,"BURGUNDY",MASUK!$D:$D,"XL")+SO!E4 -> 0 | F4: =SUM(B4:E4) -> 0 | I4: BURGUNDY | J4: =-SUMIFS(KELUAR!$E:$E,KELUAR!$B:$B,"GOTIK",KELUAR!$C:$C,"BURGUNDY",KELUAR!$D:$D,"4")+SUMIFS(MASUK!$E:$E,MASUK!$B:$B,"GOTIK",MASUK!$C:$C,"BURGUNDY",MASUK!$D:$D,"4")+SO!J4 -> 0 | K4: =-SUMIFS(KELUAR!$E:$E,KELUAR!$B:$B,"GOTIK",KELUAR!$C:$C,"BURGUNDY",KELUAR!$D:$D,"6")+SUMIFS(MASUK!$E:$E,MASUK!$B:$B,"GOTIK",MASUK!$C:$C,"BURGUNDY",MASUK!$D:$D,"6")+SO!K4 -> 0 | L4: =-SUMIFS(KELUAR!$E:$E,KELUAR!$B:$B,"GOTIK",KELUAR!$C:$C,"BURGUNDY",KELUAR!$D:$D,"8")+SUMIFS(MASUK!$E:$E,MASUK!$B:$B,"GOTIK",MASUK!$C:$C,"BURGUNDY",MASUK!$D:$D,"8")+SO!L4 -> 0 | M4: =-SUMIFS(KELUAR!$E:$E,KELUAR!$B:$B,"GOTIK",KELUAR!$C:$C,"BURGUNDY",KELUAR!$D:$D,"10")+SUMIFS(MASUK!$E:$E,MASUK!$B:$B,"GOTIK",MASUK!$C:$C,"BURGUNDY",MASUK!$D:$D,"10")+SO!M4 -> 0 | N4: =-SUMIFS(KELUAR!$E:$E,KELUAR!$B:$B,"GOTIK",KELUAR!$C:$C,"BURGUNDY",KELUAR!$D:$D,"12")+SUMIFS(MASUK!$E:$E,MASUK!$B:$B,"GOTIK",MASUK!$C:$C,"BURGUNDY",MASUK!$D:$D,"12")+SO!N4 -> 0 | O4: =-SUMIFS(KELUAR!$E:$E,KELUAR!$B:$B,"GOTIK",KELUAR!$C:$C,"BURGUNDY",KELUAR!$D:$D,"14")+SUMIFS(MASUK!$E:$E,MASUK!$B:$B,"GOTIK",MASUK!$C:$C,"BURGUNDY",MASUK!$D:$D,"14")+SO!O4 -> 0 | P4: =SUM(J4:O4) -> 0
A5: DENIM | B5: =-SUMIFS(KELUAR!$E:$E,KELUAR!$B:$B,"KUTUBARU",KELUAR!$C:$C,"DENIM",KELUAR!$D:$D,"S")+SUMIFS(MASUK!$E:$E,MASUK!$B:$B,"KUTUBARU",MASUK!$C:$C,"DENIM",MASUK!$D:$D,"S")++SO!B5 -> 0 | C5: =-SUMIFS(KELUAR!$E:$E,KELUAR!$B:$B,"KUTUBARU",KELUAR!$C:$C,"DENIM",KELUAR!$D:$D,"M")+SUMIFS(MASUK!$E:$E,MASUK!$B:$B,"KUTUBARU",MASUK!$C:$C,"DENIM",MASUK!$D:$D,"M")+SO!C5 -> 0 | D5: =-SUMIFS(KELUAR!$E:$E,KELUAR!$B:$B,"KUTUBARU",KELUAR!$C:$C,"DENIM",KELUAR!$D:$D,"L")+SUMIFS(MASUK!$E:$E,MASUK!$B:$B,"KUTUBARU",MASUK!$C:$C,"DENIM",MASUK!$D:$D,"L")+SO!D5 -> 0 | E5: =-SUMIFS(KELUAR!$E:$E,KELUAR!$B:$B,"KUTUBARU",KELUAR!$C:$C,"DENIM",KELUAR!$D:$D,"XL")+SUMIFS(MASUK!$E:$E,MASUK!$B:$B,"KUTUBARU",MASUK!$C:$C,"DENIM",MASUK!$D:$D,"XL")+SO!E5 -> 0 | F5: =SUM(B5:E5) -> 0 | I5: DENIM | J5: =-SUMIFS(KELUAR!$E:$E,KELUAR!$B:$B,"GOTIK",KELUAR!$C:$C,"DENIM",KELUAR!$D:$D,"4")+SUMIFS(MASUK!$E:$E,MASUK!$B:$B,"GOTIK",MASUK!$C:$C,"DENIM",MASUK!$D:$D,"4")+SO!J5 -> 0 | K5: =-SUMIFS(KELUAR!$E:$E,KELUAR!$B:$B,"GOTIK",KELUAR!$C:$C,"DENIM",KELUAR!$D:$D,"6")+SUMIFS(MASUK!$E:$E,MASUK!$B:$B,"GOTIK",MASUK!$C:$C,"DENIM",MASUK!$D:$D,"6")+SO!K5 -> 0 | L5: =-SUMIFS(KELUAR!$E:$E,KELUAR!$B:$B,"GOTIK",KELUAR!$C:$C,"DENIM",KELUAR!$D:$D,"8")+SUMIFS(MASUK!$E:$E,MASUK!$B:$B,"GOTIK",MASUK!$C:$C,"DENIM",MASUK!$D:$D,"8")+SO!L5 -> 0 | M5: =-SUMIFS(KELUAR!$E:$E,KELUAR!$B:$B,"GOTIK",KELUAR!$C:$C,"DENIM",KELUAR!$D:$D,"10")+SUMIFS(MASUK!$E:$E,MASUK!$B:$B,"GOTIK",MASUK!$C:$C,"DENIM",MASUK!$D:$D,"10")+SO!M5 -> 0 | N5: =-SUMIFS(KELUAR!$E:$E,KELUAR!$B:$B,"GOTIK",KELUAR!$C:$C,"DENIM",KELUAR!$D:$D,"12")+SUMIFS(MASUK!$E:$E,MASUK!$B:$B,"GOTIK",MASUK!$C:$C,"DENIM",MASUK!$D:$D,"12")+SO!N5 -> 0 | O5: =-SUMIFS(KELUAR!$E:$E,KELUAR!$B:$B,"GOTIK",KELUAR!$C:$C,"DENIM",KELUAR!$D:$D,"14")+SUMIFS(MASUK!$E:$E,MASUK!$B:$B,"GOTIK",MASUK!$C:$C,"DENIM",MASUK!$D:$D,"14")+SO!O5 -> 0 | P5: =SUM(J5:O5) -> 0
A6: COKSU | B6: =-SUMIFS(KELUAR!$E:$E,KELUAR!$B:$B,"KUTUBARU",KELUAR!$C:$C,"COKSU",KELUAR!$D:$D,"S")+SUMIFS(MASUK!$E:$E,MASUK!$B:$B,"KUTUBARU",MASUK!$C:$C,"COKSU",MASUK!$D:$D,"S")++SO!B6 -> 0 | C6: =-SUMIFS(KELUAR!$E:$E,KELUAR!$B:$B,"KUTUBARU",KELUAR!$C:$C,"COKSU",KELUAR!$D:$D,"M")+SUMIFS(MASUK!$E:$E,MASUK!$B:$B,"KUTUBARU",MASUK!$C:$C,"COKSU",MASUK!$D:$D,"M")+SO!C6 -> 0 | D6: =-SUMIFS(KELUAR!$E:$E,KELUAR!$B:$B,"KUTUBARU",KELUAR!$C:$C,"COKSU",KELUAR!$D:$D,"L")+SUMIFS(MASUK!$E:$E,MASUK!$B:$B,"KUTUBARU",MASUK!$C:$C,"COKSU",MASUK!$D:$D,"L")+SO!D6 -> 0 | E6: =-SUMIFS(KELUAR!$E:$E,KELUAR!$B:$B,"KUTUBARU",KELUAR!$C:$C,"COKSU",KELUAR!$D:$D,"XL")+SUMIFS(MASUK!$E:$E,MASUK!$B:$B,"KUTUBARU",MASUK!$C:$C,"COKSU",MASUK!$D:$D,"XL")+SO!E6 -> 0 | F6: =SUM(B6:E6) -> 0 | I6: COKSU | J6: =-SUMIFS(KELUAR!$E:$E,KELUAR!$B:$B,"GOTIK",KELUAR!$C:$C,"COKSU",KELUAR!$D:$D,"4")+SUMIFS(MASUK!$E:$E,MASUK!$B:$B,"GOTIK",MASUK!$C:$C,"COKSU",MASUK!$D:$D,"4")+SO!J6 -> 0 | K6: =-SUMIFS(KELUAR!$E:$E,KELUAR!$B:$B,"GOTIK",KELUAR!$C:$C,"COKSU",KELUAR!$D:$D,"6")+SUMIFS(MASUK!$E:$E,MASUK!$B:$B,"GOTIK",MASUK!$C:$C,"COKSU",MASUK!$D:$D,"6")+SO!K6 -> 0 | L6: =-SUMIFS(KELUAR!$E:$E,KELUAR!$B:$B,"GOTIK",KELUAR!$C:$C,"COKSU",KELUAR!$D:$D,"8")+SUMIFS(MASUK!$E:$E,MASUK!$B:$B,"GOTIK",MASUK!$C:$C,"COKSU",MASUK!$D:$D,"8")+SO!L6 -> 0 | M6: =-SUMIFS(KELUAR!$E:$E,KELUAR!$B:$B,"GOTIK",KELUAR!$C:$C,"COKSU",KELUAR!$D:$D,"10")+SUMIFS(MASUK!$E:$E,MASUK!$B:$B,"GOTIK",MASUK!$C:$C,"COKSU",MASUK!$D:$D,"10")+SO!M6 -> 0 | N6: =-SUMIFS(KELUAR!$E:$E,KELUAR!$B:$B,"GOTIK",KELUAR!$C:$C,"COKSU",KELUAR!$D:$D,"12")+SUMIFS(MASUK!$E:$E,MASUK!$B:$B,"GOTIK",MASUK!$C:$C,"COKSU",MASUK!$D:$D,"12")+SO!N6 -> 0 | O6: =-SUMIFS(KELUAR!$E:$E,KELUAR!$B:$B,"GOTIK",KELUAR!$C:$C,"COKSU",KELUAR!$D:$D,"14")+SUMIFS(MASUK!$E:$E,MASUK!$B:$B,"GOTIK",MASUK!$C:$C,"COKSU",MASUK!$D:$D,"14")+SO!O6 -> 0 | P6: =SUM(J6:O6) -> 0
A7: NAVY | B7: =-SUMIFS(KELUAR!$E:$E,KELUAR!$B:$B,"KUTUBARU",KELUAR!$C:$C,"NAVY",KELUAR!$D:$D,"S")+SUMIFS(MASUK!$E:$E,MASUK!$B:$B,"KUTUBARU",MASUK!$C:$C,"NAVY",MASUK!$D:$D,"S")+SO!B7 -> 0 | C7: =-SUMIFS(KELUAR!$E:$E,KELUAR!$B:$B,"KUTUBARU",KELUAR!$C:$C,"NAVY",KELUAR!$D:$D,"M")+SUMIFS(MASUK!$E:$E,MASUK!$B:$B,"KUTUBARU",MASUK!$C:$C,"NAVY",MASUK!$D:$D,"M")+SO!C7 -> 0 | D7: =-SUMIFS(KELUAR!$E:$E,KELUAR!$B:$B,"KUTUBARU",KELUAR!$C:$C,"NAVY",KELUAR!$D:$D,"L")+SUMIFS(MASUK!$E:$E,MASUK!$B:$B,"KUTUBARU",MASUK!$C:$C,"NAVY",MASUK!$D:$D,"L")+SO!D7 -> 0 | E7: =-SUMIFS(KELUAR!$E:$E,KELUAR!$B:$B,"KUTUBARU",KELUAR!$C:$C,"NAVY",KELUAR!$D:$D,"XL")+SUMIFS(MASUK!$E:$E,MASUK!$B:$B,"KUTUBARU",MASUK!$C:$C,"NAVY",MASUK!$D:$D,"XL")+SO!E7 -> 0 | F7: =SUM(B7:E7) -> 0 | I7: NAVY | J7: =-SUMIFS(KELUAR!$E:$E,KELUAR!$B:$B,"GOTIK",KELUAR!$C:$C,"NAVY",KELUAR!$D:$D,"4")+SUMIFS(MASUK!$E:$E,MASUK!$B:$B,"GOTIK",MASUK!$C:$C,"NAVY",MASUK!$D:$D,"4")+SO!J7 -> 0 | K7: =-SUMIFS(KELUAR!$E:$E,KELUAR!$B:$B,"GOTIK",KELUAR!$C:$C,"NAVY",KELUAR!$D:$D,"6")+SUMIFS(MASUK!$E:$E,MASUK!$B:$B,"GOTIK",MASUK!$C:$C,"NAVY",MASUK!$D:$D,"6")+SO!K7 -> 0 | L7: =-SUMIFS(KELUAR!$E:$E,KELUAR!$B:$B,"GOTIK",KELUAR!$C:$C,"NAVY",KELUAR!$D:$D,"8")+SUMIFS(MASUK!$E:$E,MASUK!$B:$B,"GOTIK",MASUK!$C:$C,"NAVY",MASUK!$D:$D,"8")+SO!L7 -> 0 | M7: =-SUMIFS(KELUAR!$E:$E,KELUAR!$B:$B,"GOTIK",KELUAR!$C:$C,"NAVY",KELUAR!$D:$D,"10")+SUMIFS(MASUK!$E:$E,MASUK!$B:$B,"GOTIK",MASUK!$C:$C,"NAVY",MASUK!$D:$D,"10")+SO!M7 -> 0 | N7: =-SUMIFS(KELUAR!$E:$E,KELUAR!$B:$B,"GOTIK",KELUAR!$C:$C,"NAVY",KELUAR!$D:$D,"12")+SUMIFS(MASUK!$E:$E,MASUK!$B:$B,"GOTIK",MASUK!$C:$C,"NAVY",MASUK!$D:$D,"12")+SO!N7 -> 0 | O7: =-SUMIFS(KELUAR!$E:$E,KELUAR!$B:$B,"GOTIK",KELUAR!$C:$C,"NAVY",KELUAR!$D:$D,"14")+SUMIFS(MASUK!$E:$E,MASUK!$B:$B,"GOTIK",MASUK!$C:$C,"NAVY",MASUK!$D:$D,"14")+SO!O7 -> 0 | P7: =SUM(J7:O7) -> 0
A8: HITAM | B8: =-SUMIFS(KELUAR!$E:$E,KELUAR!$B:$B,"KUTUBARU",KELUAR!$C:$C,"HITAM",KELUAR!$D:$D,"S")+SUMIFS(MASUK!$E:$E,MASUK!$B:$B,"KUTUBARU",MASUK!$C:$C,"HITAM",MASUK!$D:$D,"S")++SO!B8 -> 0 | C8: =-SUMIFS(KELUAR!$E:$E,KELUAR!$B:$B,"KUTUBARU",KELUAR!$C:$C,"HITAM",KELUAR!$D:$D,"M")+SUMIFS(MASUK!$E:$E,MASUK!$B:$B,"KUTUBARU",MASUK!$C:$C,"HITAM",MASUK!$D:$D,"M")+SO!C8 -> 0 | D8: =-SUMIFS(KELUAR!$E:$E,KELUAR!$B:$B,"KUTUBARU",KELUAR!$C:$C,"HITAM",KELUAR!$D:$D,"L")+SUMIFS(MASUK!$E:$E,MASUK!$B:$B,"KUTUBARU",MASUK!$C:$C,"HITAM",MASUK!$D:$D,"L")+SO!D8 -> 0 | E8: =-SUMIFS(KELUAR!$E:$E,KELUAR!$B:$B,"KUTUBARU",KELUAR!$C:$C,"HITAM",KELUAR!$D:$D,"XL")+SUMIFS(MASUK!$E:$E,MASUK!$B:$B,"KUTUBARU",MASUK!$C:$C,"HITAM",MASUK!$D:$D,"XL")+SO!E8 -> 0 | F8: =SUM(B8:E8) -> 0 | I8: HITAM | J8: =-SUMIFS(KELUAR!$E:$E,KELUAR!$B:$B,"GOTIK",KELUAR!$C:$C,"HITAM",KELUAR!$D:$D,"4")+SUMIFS(MASUK!$E:$E,MASUK!$B:$B,"GOTIK",MASUK!$C:$C,"HITAM",MASUK!$D:$D,"4")+SO!J8 -> 0 | K8: =-SUMIFS(KELUAR!$E:$E,KELUAR!$B:$B,"GOTIK",KELUAR!$C:$C,"HITAM",KELUAR!$D:$D,"6")+SUMIFS(MASUK!$E:$E,MASUK!$B:$B,"GOTIK",MASUK!$C:$C,"HITAM",MASUK!$D:$D,"6")+SO!K8 -> 0 | L8: =-SUMIFS(KELUAR!$E:$E,KELUAR!$B:$B,"GOTIK",KELUAR!$C:$C,"HITAM",KELUAR!$D:$D,"8")+SUMIFS(MASUK!$E:$E,MASUK!$B:$B,"GOTIK",MASUK!$C:$C,"HITAM",MASUK!$D:$D,"8")+SO!L8 -> 0 | M8: =-SUMIFS(KELUAR!$E:$E,KELUAR!$B:$B,"GOTIK",KELUAR!$C:$C,"HITAM",KELUAR!$D:$D,"10")+SUMIFS(MASUK!$E:$E,MASUK!$B:$B,"GOTIK",MASUK!$C:$C,"HITAM",MASUK!$D:$D,"10")+SO!M8 -> 0 | N8: =-SUMIFS(KELUAR!$E:$E,KELUAR!$B:$B,"GOTIK",KELUAR!$C:$C,"HITAM",KELUAR!$D:$D,"12")+SUMIFS(MASUK!$E:$E,MASUK!$B:$B,"GOTIK",MASUK!$C:$C,"HITAM",MASUK!$D:$D,"12")+SO!N8 -> 0 | O8: =-SUMIFS(KELUAR!$E:$E,KELUAR!$B:$B,"GOTIK",KELUAR!$C:$C,"HITAM",KELUAR!$D:$D,"14")+SUMIFS(MASUK!$E:$E,MASUK!$B:$B,"GOTIK",MASUK!$C:$C,"HITAM",MASUK!$D:$D,"14")+SO!O8 -> 0 | P8: =SUM(J8:O8) -> 0
A9: DUSTY | B9: =-SUMIFS(KELUAR!$E:$E,KELUAR!$B:$B,"KUTUBARU",KELUAR!$C:$C,"DUSTY",KELUAR!$D:$D,"S")+SUMIFS(MASUK!$E:$E,MASUK!$B:$B,"KUTUBARU",MASUK!$C:$C,"DUSTY",MASUK!$D:$D,"S")++SO!B9 -> 0 | C9: =-SUMIFS(KELUAR!$E:$E,KELUAR!$B:$B,"KUTUBARU",KELUAR!$C:$C,"DUSTY",KELUAR!$D:$D,"M")+SUMIFS(MASUK!$E:$E,MASUK!$B:$B,"KUTUBARU",MASUK!$C:$C,"DUSTY",MASUK!$D:$D,"M")+SO!C9 -> 0 | D9: =-SUMIFS(KELUAR!$E:$E,KELUAR!$B:$B,"KUTUBARU",KELUAR!$C:$C,"DUSTY",KELUAR!$D:$D,"L")+SUMIFS(MASUK!$E:$E,MASUK!$B:$B,"KUTUBARU",MASUK!$C:$C,"DUSTY",MASUK!$D:$D,"L")+SO!D9 -> 0 | E9: =-SUMIFS(KELUAR!$E:$E,KELUAR!$B:$B,"KUTUBARU",KELUAR!$C:$C,"DUSTY",KELUAR!$D:$D,"XL")+SUMIFS(MASUK!$E:$E,MASUK!$B:$B,"KUTUBARU",MASUK!$C:$C,"DUSTY",MASUK!$D:$D,"XL")+SO!E9 -> 0 | F9: =SUM(B9:E9) -> 0 | I9: DUSTY | J9: =-SUMIFS(KELUAR!$E:$E,KELUAR!$B:$B,"GOTIK",KELUAR!$C:$C,"DUSTY",KELUAR!$D:$D,"4")+SUMIFS(MASUK!$E:$E,MASUK!$B:$B,"GOTIK",MASUK!$C:$C,"DUSTY",MASUK!$D:$D,"4")+SO!J9 -> 0 | K9: =-SUMIFS(KELUAR!$E:$E,KELUAR!$B:$B,"GOTIK",KELUAR!$C:$C,"DUSTY",KELUAR!$D:$D,"6")+SUMIFS(MASUK!$E:$E,MASUK!$B:$B,"GOTIK",MASUK!$C:$C,"DUSTY",MASUK!$D:$D,"6")+SO!K9 -> 0 | L9: =-SUMIFS(KELUAR!$E:$E,KELUAR!$B:$B,"GOTIK",KELUAR!$C:$C,"DUSTY",KELUAR!$D:$D,"8")+SUMIFS(MASUK!$E:$E,MASUK!$B:$B,"GOTIK",MASUK!$C:$C,"DUSTY",MASUK!$D:$D,"8")+SO!L9 -> 0 | M9: =-SUMIFS(KELUAR!$E:$E,KELUAR!$B:$B,"GOTIK",KELUAR!$C:$C,"DUSTY",KELUAR!$D:$D,"10")+SUMIFS(MASUK!$E:$E,MASUK!$B:$B,"GOTIK",MASUK!$C:$C,"DUSTY",MASUK!$D:$D,"10")+SO!M9 -> 0 | N9: =-SUMIFS(KELUAR!$E:$E,KELUAR!$B:$B,"GOTIK",KELUAR!$C:$C,"DUSTY",KELUAR!$D:$D,"12")+SUMIFS(MASUK!$E:$E,MASUK!$B:$B,"GOTIK",MASUK!$C:$C,"DUSTY",MASUK!$D:$D,"12")+SO!N9 -> 0 | O9: =-SUMIFS(KELUAR!$E:$E,KELUAR!$B:$B,"GOTIK",KELUAR!$C:$C,"DUSTY",KELUAR!$D:$D,"14")+SUMIFS(MASUK!$E:$E,MASUK!$B:$B,"GOTIK",MASUK!$C:$C,"DUSTY",MASUK!$D:$D,"14")+SO!O9 -> 0 | P9: =SUM(J9:O9) -> 0
A10: BABYBLUE | B10: =-SUMIFS(KELUAR!$E:$E,KELUAR!$B:$B,"KUTUBARU",KELUAR!$C:$C,"BABYBLUE",KELUAR!$D:$D,"S")+SUMIFS(MASUK!$E:$E,MASUK!$B:$B,"KUTUBARU",MASUK!$C:$C,"BABYBLUE",MASUK!$D:$D,"S")++SO!B10 -> 0 | C10: =-SUMIFS(KELUAR!$E:$E,KELUAR!$B:$B,"KUTUBARU",KELUAR!$C:$C,"BABYBLUE",KELUAR!$D:$D,"M")+SUMIFS(MASUK!$E:$E,MASUK!$B:$B,"KUTUBARU",MASUK!$C:$C,"BABYBLUE",MASUK!$D:$D,"M")+SO!C10 -> 0 | D10: =-SUMIFS(KELUAR!$E:$E,KELUAR!$B:$B,"KUTUBARU",KELUAR!$C:$C,"BABYBLUE",KELUAR!$D:$D,"L")+SUMIFS(MASUK!$E:$E,MASUK!$B:$B,"KUTUBARU",MASUK!$C:$C,"BABYBLUE",MASUK!$D:$D,"L")+SO!D10 -> 0 | E10: =-SUMIFS(KELUAR!$E:$E,KELUAR!$B:$B,"KUTUBARU",KELUAR!$C:$C,"BABYBLUE",KELUAR!$D:$D,"XL")+SUMIFS(MASUK!$E:$E,MASUK!$B:$B,"KUTUBARU",MASUK!$C:$C,"BABYBLUE",MASUK!$D:$D,"XL")+SO!E10 -> 0 | F10: =SUM(B10:E10) -> 0 | I10: BABYBLUE | J10: =-SUMIFS(KELUAR!$E:$E,KELUAR!$B:$B,"GOTIK",KELUAR!$C:$C,"BABYBLUE",KELUAR!$D:$D,"4")+SUMIFS(MASUK!$E:$E,MASUK!$B:$B,"GOTIK",MASUK!$C:$C,"BABYBLUE",MASUK!$D:$D,"4")+SO!J10 -> 0 | K10: =-SUMIFS(KELUAR!$E:$E,KELUAR!$B:$B,"GOTIK",KELUAR!$C:$C,"BABYBLUE",KELUAR!$D:$D,"6")+SUMIFS(MASUK!$E:$E,MASUK!$B:$B,"GOTIK",MASUK!$C:$C,"BABYBLUE",MASUK!$D:$D,"6")+SO!K10 -> 0 | L10: =-SUMIFS(KELUAR!$E:$E,KELUAR!$B:$B,"GOTIK",KELUAR!$C:$C,"BABYBLUE",KELUAR!$D:$D,"8")+SUMIFS(MASUK!$E:$E,MASUK!$B:$B,"GOTIK",MASUK!$C:$C,"BABYBLUE",MASUK!$D:$D,"8")+SO!L10 -> 0 | M10: =-SUMIFS(KELUAR!$E:$E,KELUAR!$B:$B,"GOTIK",KELUAR!$C:$C,"BABYBLUE",KELUAR!$D:$D,"10")+SUMIFS(MASUK!$E:$E,MASUK!$B:$B,"GOTIK",MASUK!$C:$C,"BABYBLUE",MASUK!$D:$D,"10")+SO!M10 -> 0 | N10: =-SUMIFS(KELUAR!$E:$E,KELUAR!$B:$B,"GOTIK",KELUAR!$C:$C,"BABYBLUE",KELUAR!$D:$D,"12")+SUMIFS(MASUK!$E:$E,MASUK!$B:$B,"GOTIK",MASUK!$C:$C,"BABYBLUE",MASUK!$D:$D,"12")+SO!N10 -> 0 | O10: =-SUMIFS(KELUAR!$E:$E,KELUAR!$B:$B,"GOTIK",KELUAR!$C:$C,"BABYBLUE",KELUAR!$D:$D,"14")+SUMIFS(MASUK!$E:$E,MASUK!$B:$B,"GOTIK",MASUK!$C:$C,"BABYBLUE",MASUK!$D:$D,"14")+SO!O10 -> 0 | P10: =SUM(J10:O10) -> 0
A11: MAROON | B11: =-SUMIFS(KELUAR!$E:$E,KELUAR!$B:$B,"KUTUBARU",KELUAR!$C:$C,"MAROON",KELUAR!$D:$D,"S")+SUMIFS(MASUK!$E:$E,MASUK!$B:$B,"KUTUBARU",MASUK!$C:$C,"MAROON",MASUK!$D:$D,"S")+SO!B11 -> 0 | C11: =-SUMIFS(KELUAR!$E:$E,KELUAR!$B:$B,"KUTUBARU",KELUAR!$C:$C,"MAROON",KELUAR!$D:$D,"M")+SUMIFS(MASUK!$E:$E,MASUK!$B:$B,"KUTUBARU",MASUK!$C:$C,"MAROON",MASUK!$D:$D,"M")+SO!C11 -> 0 | D11: =-SUMIFS(KELUAR!$E:$E,KELUAR!$B:$B,"KUTUBARU",KELUAR!$C:$C,"MAROON",KELUAR!$D:$D,"L")+SUMIFS(MASUK!$E:$E,MASUK!$B:$B,"KUTUBARU",MASUK!$C:$C,"MAROON",MASUK!$D:$D,"L")+SO!D11 -> 0 | E11: =-SUMIFS(KELUAR!$E:$E,KELUAR!$B:$B,"KUTUBARU",KELUAR!$C:$C,"MAROON",KELUAR!$D:$D,"XL")+SUMIFS(MASUK!$E:$E,MASUK!$B:$B,"KUTUBARU",MASUK!$C:$C,"MAROON",MASUK!$D:$D,"XL")+SO!E11 -> 0 | F11: =SUM(B11:E11) -> 0 | I11: MAROON | J11: =-SUMIFS(KELUAR!$E:$E,KELUAR!$B:$B,"GOTIK",KELUAR!$C:$C,"MAROON",KELUAR!$D:$D,"4")+SUMIFS(MASUK!$E:$E,MASUK!$B:$B,"GOTIK",MASUK!$C:$C,"MAROON",MASUK!$D:$D,"4")+SO!J11 -> 0 | K11: =-SUMIFS(KELUAR!$E:$E,KELUAR!$B:$B,"GOTIK",KELUAR!$C:$C,"MAROON",KELUAR!$D:$D,"6")+SUMIFS(MASUK!$E:$E,MASUK!$B:$B,"GOTIK",MASUK!$C:$C,"MAROON",MASUK!$D:$D,"6")+SO!K11 -> 0 | L11: =-SUMIFS(KELUAR!$E:$E,KELUAR!$B:$B,"GOTIK",KELUAR!$C:$C,"MAROON",KELUAR!$D:$D,"8")+SUMIFS(MASUK!$E:$E,MASUK!$B:$B,"GOTIK",MASUK!$C:$C,"MAROON",MASUK!$D:$D,"8")+SO!L11 -> 0 | M11: =-SUMIFS(KELUAR!$E:$E,KELUAR!$B:$B,"GOTIK",KELUAR!$C:$C,"MAROON",KELUAR!$D:$D,"10")+SUMIFS(MASUK!$E:$E,MASUK!$B:$B,"GOTIK",MASUK!$C:$C,"MAROON",MASUK!$D:$D,"10")+SO!M11 -> 0 | N11: =-SUMIFS(KELUAR!$E:$E,KELUAR!$B:$B,"GOTIK",KELUAR!$C:$C,"MAROON",KELUAR!$D:$D,"12")+SUMIFS(MASUK!$E:$E,MASUK!$B:$B,"GOTIK",MASUK!$C:$C,"MAROON",MASUK!$D:$D,"12")+SO!N11 -> 0 | O11: =-SUMIFS(KELUAR!$E:$E,KELUAR!$B:$B,"GOTIK",KELUAR!$C:$C,"MAROON",KELUAR!$D:$D,"14")+SUMIFS(MASUK!$E:$E,MASUK!$B:$B,"GOTIK",MASUK!$C:$C,"MAROON",MASUK!$D:$D,"14")+SO!O11 -> 0 | P11: =SUM(J11:O11) -> 0
A12: GOLD | B12: =-SUMIFS(KELUAR!$E:$E,KELUAR!$B:$B,"KUTUBARU",KELUAR!$C:$C,"GOLD",KELUAR!$D:$D,"S")+SUMIFS(MASUK!$E:$E,MASUK!$B:$B,"KUTUBARU",MASUK!$C:$C,"GOLD",MASUK!$D:$D,"S")++SO!B12 -> 0 | C12: =-SUMIFS(KELUAR!$E:$E,KELUAR!$B:$B,"KUTUBARU",KELUAR!$C:$C,"GOLD",KELUAR!$D:$D,"M")+SUMIFS(MASUK!$E:$E,MASUK!$B:$B,"KUTUBARU",MASUK!$C:$C,"GOLD",MASUK!$D:$D,"M")+SO!C12 -> 0 | D12: =-SUMIFS(KELUAR!$E:$E,KELUAR!$B:$B,"KUTUBARU",KELUAR!$C:$C,"GOLD",KELUAR!$D:$D,"L")+SUMIFS(MASUK!$E:$E,MASUK!$B:$B,"KUTUBARU",MASUK!$C:$C,"GOLD",MASUK!$D:$D,"L")+SO!D12 -> 0 | E12: =-SUMIFS(KELUAR!$E:$E,KELUAR!$B:$B,"KUTUBARU",KELUAR!$C:$C,"GOLD",KELUAR!$D:$D,"XL")+SUMIFS(MASUK!$E:$E,MASUK!$B:$B,"KUTUBARU",MASUK!$C:$C,"GOLD",MASUK!$D:$D,"XL")+SO!E12 -> 0 | F12: =SUM(B12:E12) -> 0 | I12: GOLD | J12: =-SUMIFS(KELUAR!$E:$E,KELUAR!$B:$B,"GOTIK",KELUAR!$C:$C,"GOLD",KELUAR!$D:$D,"4")+SUMIFS(MASUK!$E:$E,MASUK!$B:$B,"GOTIK",MASUK!$C:$C,"GOLD",MASUK!$D:$D,"4")+SO!J12 -> 0 | K12: =-SUMIFS(KELUAR!$E:$E,KELUAR!$B:$B,"GOTIK",KELUAR!$C:$C,"GOLD",KELUAR!$D:$D,"6")+SUMIFS(MASUK!$E:$E,MASUK!$B:$B,"GOTIK",MASUK!$C:$C,"GOLD",MASUK!$D:$D,"6")+SO!K12 -> 0 | L12: =-SUMIFS(KELUAR!$E:$E,KELUAR!$B:$B,"GOTIK",KELUAR!$C:$C,"GOLD",KELUAR!$D:$D,"8")+SUMIFS(MASUK!$E:$E,MASUK!$B:$B,"GOTIK",MASUK!$C:$C,"GOLD",MASUK!$D:$D,"8")+SO!L12 -> 0 | M12: =-SUMIFS(KELUAR!$E:$E,KELUAR!$B:$B,"GOTIK",KELUAR!$C:$C,"GOLD",KELUAR!$D:$D,"10")+SUMIFS(MASUK!$E:$E,MASUK!$B:$B,"GOTIK",MASUK!$C:$C,"GOLD",MASUK!$D:$D,"10")+SO!M12 -> 0 | N12: =-SUMIFS(KELUAR!$E:$E,KELUAR!$B:$B,"GOTIK",KELUAR!$C:$C,"GOLD",KELUAR!$D:$D,"12")+SUMIFS(MASUK!$E:$E,MASUK!$B:$B,"GOTIK",MASUK!$C:$C,"GOLD",MASUK!$D:$D,"12")+SO!N12 -> 0 | O12: =-SUMIFS(KELUAR!$E:$E,KELUAR!$B:$B,"GOTIK",KELUAR!$C:$C,"GOLD",KELUAR!$D:$D,"14")+SUMIFS(MASUK!$E:$E,MASUK!$B:$B,"GOTIK",MASUK!$C:$C,"GOLD",MASUK!$D:$D,"14")+SO!O12 -> 0 | P12: =SUM(J12:O12) -> 0
A13: SAGE | B13: =-SUMIFS(KELUAR!$E:$E,KELUAR!$B:$B,"KUTUBARU",KELUAR!$C:$C,"SAGE",KELUAR!$D:$D,"S")+SUMIFS(MASUK!$E:$E,MASUK!$B:$B,"KUTUBARU",MASUK!$C:$C,"SAGE",MASUK!$D:$D,"S")++SO!B13 -> 0 | C13: =-SUMIFS(KELUAR!$E:$E,KELUAR!$B:$B,"KUTUBARU",KELUAR!$C:$C,"SAGE",KELUAR!$D:$D,"M")+SUMIFS(MASUK!$E:$E,MASUK!$B:$B,"KUTUBARU",MASUK!$C:$C,"SAGE",MASUK!$D:$D,"M")+SO!C13 -> 0 | D13: =-SUMIFS(KELUAR!$E:$E,KELUAR!$B:$B,"KUTUBARU",KELUAR!$C:$C,"SAGE",KELUAR!$D:$D,"L")+SUMIFS(MASUK!$E:$E,MASUK!$B:$B,"KUTUBARU",MASUK!$C:$C,"SAGE",MASUK!$D:$D,"L")+SO!D13 -> 0 | E13: =-SUMIFS(KELUAR!$E:$E,KELUAR!$B:$B,"KUTUBARU",KELUAR!$C:$C,"SAGE",KELUAR!$D:$D,"XL")+SUMIFS(MASUK!$E:$E,MASUK!$B:$B,"KUTUBARU",MASUK!$C:$C,"SAGE",MASUK!$D:$D,"XL")+SO!E13 -> 0 | F13: =SUM(B13:E13) -> 0 | I13: SAGE | J13: =-SUMIFS(KELUAR!$E:$E,KELUAR!$B:$B,"GOTIK",KELUAR!$C:$C,"sage",KELUAR!$D:$D,"4")+SUMIFS(MASUK!$E:$E,MASUK!$B:$B,"GOTIK",MASUK!$C:$C,"sage",MASUK!$D:$D,"4")+SO!J13 -> 0 | K13: =-SUMIFS(KELUAR!$E:$E,KELUAR!$B:$B,"GOTIK",KELUAR!$C:$C,"sage",KELUAR!$D:$D,"6")+SUMIFS(MASUK!$E:$E,MASUK!$B:$B,"GOTIK",MASUK!$C:$C,"sage",MASUK!$D:$D,"6")+SO!K13 -> 0 | L13: =-SUMIFS(KELUAR!$E:$E,KELUAR!$B:$B,"GOTIK",KELUAR!$C:$C,"sage",KELUAR!$D:$D,"8")+SUMIFS(MASUK!$E:$E,MASUK!$B:$B,"GOTIK",MASUK!$C:$C,"sage",MASUK!$D:$D,"8")+SO!L13 -> 0 | M13: =-SUMIFS(KELUAR!$E:$E,KELUAR!$B:$B,"GOTIK",KELUAR!$C:$C,"sage",KELUAR!$D:$D,"10")+SUMIFS(MASUK!$E:$E,MASUK!$B:$B,"GOTIK",MASUK!$C:$C,"sage",MASUK!$D:$D,"10")+SO!M13 -> 0 | N13: =-SUMIFS(KELUAR!$E:$E,KELUAR!$B:$B,"GOTIK",KELUAR!$C:$C,"sage",KELUAR!$D:$D,"12")+SUMIFS(MASUK!$E:$E,MASUK!$B:$B,"GOTIK",MASUK!$C:$C,"sage",MASUK!$D:$D,"12")+SO!N13 -> 0 | O13: =-SUMIFS(KELUAR!$E:$E,KELUAR!$B:$B,"GOTIK",KELUAR!$C:$C,"sage",KELUAR!$D:$D,"14")+SUMIFS(MASUK!$E:$E,MASUK!$B:$B,"GOTIK",MASUK!$C:$C,"sage",MASUK!$D:$D,"14")+SO!O13 -> 0 | P13: =SUM(J13:O13) -> 0
A14: EMERALD GREEN | B14: =-SUMIFS(KELUAR!$E:$E,KELUAR!$B:$B,"KUTUBARU",KELUAR!$C:$C,"EMERALD GREEN",KELUAR!$D:$D,"S")+SUMIFS(MASUK!$E:$E,MASUK!$B:$B,"KUTUBARU",MASUK!$C:$C,"EMERALD GREEN",MASUK!$D:$D,"S")++SO!B14 -> 0 | C14: =-SUMIFS(KELUAR!$E:$E,KELUAR!$B:$B,"KUTUBARU",KELUAR!$C:$C,"EMERALD GREEN",KELUAR!$D:$D,"M")+SUMIFS(MASUK!$E:$E,MASUK!$B:$B,"KUTUBARU",MASUK!$C:$C,"EMERALD GREEN",MASUK!$D:$D,"M")+SO!C14 -> 0 | D14: =-SUMIFS(KELUAR!$E:$E,KELUAR!$B:$B,"KUTUBARU",KELUAR!$C:$C,"EMERALD GREEN",KELUAR!$D:$D,"L")+SUMIFS(MASUK!$E:$E,MASUK!$B:$B,"KUTUBARU",MASUK!$C:$C,"EMERALD GREEN",MASUK!$D:$D,"L")+SO!D14 -> 0 | E14: =-SUMIFS(KELUAR!$E:$E,KELUAR!$B:$B,"KUTUBARU",KELUAR!$C:$C,"EMERALD GREEN",KELUAR!$D:$D,"XL")+SUMIFS(MASUK!$E:$E,MASUK!$B:$B,"KUTUBARU",MASUK!$C:$C,"EMERALD GREEN",MASUK!$D:$D,"XL")+SO!E14 -> 0 | F14: =SUM(B14:E14) -> 0 | I14: EMERALD BLUE | J14: =-SUMIFS(KELUAR!$E:$E,KELUAR!$B:$B,"GOTIK",KELUAR!$C:$C,"emerald blue",KELUAR!$D:$D,"4")+SUMIFS(MASUK!$E:$E,MASUK!$B:$B,"GOTIK",MASUK!$C:$C,"emerald blue",MASUK!$D:$D,"4")+SO!J14 -> 0 | K14: =-SUMIFS(KELUAR!$E:$E,KELUAR!$B:$B,"GOTIK",KELUAR!$C:$C,"emerald blue",KELUAR!$D:$D,"6")+SUMIFS(MASUK!$E:$E,MASUK!$B:$B,"GOTIK",MASUK!$C:$C,"emerald blue",MASUK!$D:$D,"6")+SO!K14 -> 0 | L14: =-SUMIFS(KELUAR!$E:$E,KELUAR!$B:$B,"GOTIK",KELUAR!$C:$C,"emerald blue",KELUAR!$D:$D,"8")+SUMIFS(MASUK!$E:$E,MASUK!$B:$B,"GOTIK",MASUK!$C:$C,"emerald blue",MASUK!$D:$D,"8")+SO!L14 -> 0 | M14: =-SUMIFS(KELUAR!$E:$E,KELUAR!$B:$B,"GOTIK",KELUAR!$C:$C,"emerald blue",KELUAR!$D:$D,"10")+SUMIFS(MASUK!$E:$E,MASUK!$B:$B,"GOTIK",MASUK!$C:$C,"emerald blue",MASUK!$D:$D,"10")+SO!M14 -> 0 | N14: =-SUMIFS(KELUAR!$E:$E,KELUAR!$B:$B,"GOTIK",KELUAR!$C:$C,"emerald blue",KELUAR!$D:$D,"12")+SUMIFS(MASUK!$E:$E,MASUK!$B:$B,"GOTIK",MASUK!$C:$C,"emerald blue",MASUK!$D:$D,"12")+SO!N14 -> 0 | O14: =-SUMIFS(KELUAR!$E:$E,KELUAR!$B:$B,"GOTIK",KELUAR!$C:$C,"emerald blue",KELUAR!$D:$D,"14")+SUMIFS(MASUK!$E:$E,MASUK!$B:$B,"GOTIK",MASUK!$C:$C,"emerald blue",MASUK!$D:$D,"14")+SO!O14 -> 0 | P14: =SUM(J14:O14) -> 0
A15: FUCIA | B15: =-SUMIFS(KELUAR!$E:$E,KELUAR!$B:$B,"KUTUBARU",KELUAR!$C:$C,"FUCIA",KELUAR!$D:$D,"S")+SUMIFS(MASUK!$E:$E,MASUK!$B:$B,"KUTUBARU",MASUK!$C:$C,"FUCIA",MASUK!$D:$D,"S")++SO!B15 -> 0 | C15: =-SUMIFS(KELUAR!$E:$E,KELUAR!$B:$B,"KUTUBARU",KELUAR!$C:$C,"FUCIA",KELUAR!$D:$D,"M")+SUMIFS(MASUK!$E:$E,MASUK!$B:$B,"KUTUBARU",MASUK!$C:$C,"FUCIA",MASUK!$D:$D,"M")+SO!C15 -> 0 | D15: =-SUMIFS(KELUAR!$E:$E,KELUAR!$B:$B,"KUTUBARU",KELUAR!$C:$C,"FUCIA",KELUAR!$D:$D,"L")+SUMIFS(MASUK!$E:$E,MASUK!$B:$B,"KUTUBARU",MASUK!$C:$C,"FUCIA",MASUK!$D:$D,"L")+SO!D15 -> 0 | E15: =-SUMIFS(KELUAR!$E:$E,KELUAR!$B:$B,"KUTUBARU",KELUAR!$C:$C,"FUCIA",KELUAR!$D:$D,"XL")+SUMIFS(MASUK!$E:$E,MASUK!$B:$B,"KUTUBARU",MASUK!$C:$C,"FUCIA",MASUK!$D:$D,"XL")+SO!E15 -> 0 | F15: =SUM(B15:E15) -> 0 | I15: SILVER | J15: =-SUMIFS(KELUAR!$E:$E,KELUAR!$B:$B,"GOTIK",KELUAR!$C:$C,"silver",KELUAR!$D:$D,"4")+SUMIFS(MASUK!$E:$E,MASUK!$B:$B,"GOTIK",MASUK!$C:$C,"silver",MASUK!$D:$D,"4")+SO!J15 -> 0 | K15: =-SUMIFS(KELUAR!$E:$E,KELUAR!$B:$B,"GOTIK",KELUAR!$C:$C,"silver",KELUAR!$D:$D,"6")+SUMIFS(MASUK!$E:$E,MASUK!$B:$B,"GOTIK",MASUK!$C:$C,"silver",MASUK!$D:$D,"6")+SO!K15 -> 0 | L15: =-SUMIFS(KELUAR!$E:$E,KELUAR!$B:$B,"GOTIK",KELUAR!$C:$C,"silver",KELUAR!$D:$D,"8")+SUMIFS(MASUK!$E:$E,MASUK!$B:$B,"GOTIK",MASUK!$C:$C,"silver",MASUK!$D:$D,"8")+SO!L15 -> 0 | M15: =-SUMIFS(KELUAR!$E:$E,KELUAR!$B:$B,"GOTIK",KELUAR!$C:$C,"silver",KELUAR!$D:$D,"10")+SUMIFS(MASUK!$E:$E,MASUK!$B:$B,"GOTIK",MASUK!$C:$C,"silver",MASUK!$D:$D,"10")+SO!M15 -> 0 | N15: =-SUMIFS(KELUAR!$E:$E,KELUAR!$B:$B,"GOTIK",KELUAR!$C:$C,"silver",KELUAR!$D:$D,"12")+SUMIFS(MASUK!$E:$E,MASUK!$B:$B,"GOTIK",MASUK!$C:$C,"silver",MASUK!$D:$D,"12")+SO!N15 -> 0 | O15: =-SUMIFS(KELUAR!$E:$E,KELUAR!$B:$B,"GOTIK",KELUAR!$C:$C,"silver",KELUAR!$D:$D,"14")+SUMIFS(MASUK!$E:$E,MASUK!$B:$B,"GOTIK",MASUK!$C:$C,"silver",MASUK!$D:$D,"14")+SO!O15 -> 0 | P15: =SUM(J15:O15) -> 0
A16: SILVER | B16: =-SUMIFS(KELUAR!$E:$E,KELUAR!$B:$B,"KUTUBARU",KELUAR!$C:$C,"silver",KELUAR!$D:$D,"S")+SUMIFS(MASUK!$E:$E,MASUK!$B:$B,"KUTUBARU",MASUK!$C:$C,"silver",MASUK!$D:$D,"S")++SO!B16 -> 0 | C16: =-SUMIFS(KELUAR!$E:$E,KELUAR!$B:$B,"KUTUBARU",KELUAR!$C:$C,"silver",KELUAR!$D:$D,"M")+SUMIFS(MASUK!$E:$E,MASUK!$B:$B,"KUTUBARU",MASUK!$C:$C,"silver",MASUK!$D:$D,"M")+SO!C16 -> 0 | D16: =-SUMIFS(KELUAR!$E:$E,KELUAR!$B:$B,"KUTUBARU",KELUAR!$C:$C,"silver",KELUAR!$D:$D,"L")+SUMIFS(MASUK!$E:$E,MASUK!$B:$B,"KUTUBARU",MASUK!$C:$C,"silver",MASUK!$D:$D,"L")+SO!D16 -> 0 | E16: =-SUMIFS(KELUAR!$E:$E,KELUAR!$B:$B,"KUTUBARU",KELUAR!$C:$C,"silver",KELUAR!$D:$D,"XL")+SUMIFS(MASUK!$E:$E,MASUK!$B:$B,"KUTUBARU",MASUK!$C:$C,"silver",MASUK!$D:$D,"XL")+SO!E16 -> 0 | F16: =SUM(B16:E16) -> 0 | I16: BUTTER YELLOW | J16: =-SUMIFS(KELUAR!$E:$E,KELUAR!$B:$B,"GOTIK",KELUAR!$C:$C,"butter yellow",KELUAR!$D:$D,"4")+SUMIFS(MASUK!$E:$E,MASUK!$B:$B,"GOTIK",MASUK!$C:$C,"butter yellow",MASUK!$D:$D,"4")+SO!J16 -> 0 | K16: =-SUMIFS(KELUAR!$E:$E,KELUAR!$B:$B,"GOTIK",KELUAR!$C:$C,"butter yellow",KELUAR!$D:$D,"6")+SUMIFS(MASUK!$E:$E,MASUK!$B:$B,"GOTIK",MASUK!$C:$C,"butter yellow",MASUK!$D:$D,"6")+SO!K16 -> 0 | L16: =-SUMIFS(KELUAR!$E:$E,KELUAR!$B:$B,"GOTIK",KELUAR!$C:$C,"butter yellow",KELUAR!$D:$D,"8")+SUMIFS(MASUK!$E:$E,MASUK!$B:$B,"GOTIK",MASUK!$C:$C,"butter yellow",MASUK!$D:$D,"8")+SO!L16 -> 0 | M16: =-SUMIFS(KELUAR!$E:$E,KELUAR!$B:$B,"GOTIK",KELUAR!$C:$C,"butter yellow",KELUAR!$D:$D,"10")+SUMIFS(MASUK!$E:$E,MASUK!$B:$B,"GOTIK",MASUK!$C:$C,"butter yellow",MASUK!$D:$D,"10")+SO!M16 -> 0 | N16: =-SUMIFS(KELUAR!$E:$E,KELUAR!$B:$B,"GOTIK",KELUAR!$C:$C,"butter yellow",KELUAR!$D:$D,"12")+SUMIFS(MASUK!$E:$E,MASUK!$B:$B,"GOTIK",MASUK!$C:$C,"butter yellow",MASUK!$D:$D,"12")+SO!N16 -> 0 | O16: =-SUMIFS(KELUAR!$E:$E,KELUAR!$B:$B,"GOTIK",KELUAR!$C:$C,"butter yellow",KELUAR!$D:$D,"14")+SUMIFS(MASUK!$E:$E,MASUK!$B:$B,"GOTIK",MASUK!$C:$C,"butter yellow",MASUK!$D:$D,"14")+SO!O16 -> 0 | P16: =SUM(J16:O16) -> 0
A17: BUTTER YELLOW | B17: =-SUMIFS(KELUAR!$E:$E,KELUAR!$B:$B,"KUTUBARU",KELUAR!$C:$C,"Butter Yellow",KELUAR!$D:$D,"S")+SUMIFS(MASUK!$E:$E,MASUK!$B:$B,"KUTUBARU",MASUK!$C:$C,"Butter Yellow",MASUK!$D:$D,"S")++SO!B17 -> 0 | C17: =-SUMIFS(KELUAR!$E:$E,KELUAR!$B:$B,"KUTUBARU",KELUAR!$C:$C,"Butter Yellow",KELUAR!$D:$D,"M")+SUMIFS(MASUK!$E:$E,MASUK!$B:$B,"KUTUBARU",MASUK!$C:$C,"Butter Yellow",MASUK!$D:$D,"M")+SO!C17 -> 0 | D17: =-SUMIFS(KELUAR!$E:$E,KELUAR!$B:$B,"KUTUBARU",KELUAR!$C:$C,"Butter Yellow",KELUAR!$D:$D,"L")+SUMIFS(MASUK!$E:$E,MASUK!$B:$B,"KUTUBARU",MASUK!$C:$C,"Butter Yellow",MASUK!$D:$D,"L")+SO!D17 -> 0 | E17: =-SUMIFS(KELUAR!$E:$E,KELUAR!$B:$B,"KUTUBARU",KELUAR!$C:$C,"Butter Yellow",KELUAR!$D:$D,"XL")+SUMIFS(MASUK!$E:$E,MASUK!$B:$B,"KUTUBARU",MASUK!$C:$C,"Butter Yellow",MASUK!$D:$D,"XL")+SO!E17 -> 0 | F17: =SUM(B17:E17) -> 0 | J17: =-SUMIFS(KELUAR!$E:$E,KELUAR!$B:$B,"GOTIK",KELUAR!$C:$C,"GOLD",KELUAR!$D:$D,"4")+SUMIFS(MASUK!$E:$E,MASUK!$B:$B,"GOTIK",MASUK!$C:$C,"GOLD",MASUK!$D:$D,"4")+SO!J17 -> 0 | K17: =-SUMIFS(KELUAR!$E:$E,KELUAR!$B:$B,"GOTIK",KELUAR!$C:$C,"GOLD",KELUAR!$D:$D,"6")+SUMIFS(MASUK!$E:$E,MASUK!$B:$B,"GOTIK",MASUK!$C:$C,"GOLD",MASUK!$D:$D,"6")+SO!K17 -> 0 | L17: =-SUMIFS(KELUAR!$E:$E,KELUAR!$B:$B,"GOTIK",KELUAR!$C:$C,"GOLD",KELUAR!$D:$D,"8")+SUMIFS(MASUK!$E:$E,MASUK!$B:$B,"GOTIK",MASUK!$C:$C,"GOLD",MASUK!$D:$D,"8")+SO!L17 -> 0 | M17: =-SUMIFS(KELUAR!$E:$E,KELUAR!$B:$B,"GOTIK",KELUAR!$C:$C,"GOLD",KELUAR!$D:$D,"10")+SUMIFS(MASUK!$E:$E,MASUK!$B:$B,"GOTIK",MASUK!$C:$C,"GOLD",MASUK!$D:$D,"10")+SO!M17 -> 0 | N17: =-SUMIFS(KELUAR!$E:$E,KELUAR!$B:$B,"GOTIK",KELUAR!$C:$C,"GOLD",KELUAR!$D:$D,"12")+SUMIFS(MASUK!$E:$E,MASUK!$B:$B,"GOTIK",MASUK!$C:$C,"GOLD",MASUK!$D:$D,"12")+SO!N17 -> 0 | O17: =-SUMIFS(KELUAR!$E:$E,KELUAR!$B:$B,"GOTIK",KELUAR!$C:$C,"GOLD",KELUAR!$D:$D,"14")+SUMIFS(MASUK!$E:$E,MASUK!$B:$B,"GOTIK",MASUK!$C:$C,"GOLD",MASUK!$D:$D,"14")+SO!O17 -> 0 | P17: =SUM(J17:O17) -> 0
